Workbook

Sheet SUMMARY
A1: Date | B1: Day | C1: Day Oppning Balance | D1: 1st Lifting Balance | E1: 2nd Lifting Balamce | F1: Total Balance | G1: DO Transferred | H1: In Hand Balance
A2: 46204 | B2: Wednesday | C2: ='1'!A23 -> 815579 | D2: ='1'!C23 -> 700000 | E2: ='1'!D23 -> 630000 | F2: =SUM(C2:E2) -> 2145579 | G2: ='1'!G18 -> 1225897 | H2: =F2-G2 -> 919682.04 | J2: Month Total Upfront Commissions
A3: 46205 | B3: Thursday | C3: =H2 -> 919682.04 | D3: ='2'!C23 -> 0 | E3: ='2'!D23 -> 0 | F3: =SUM(C3:E3) -> 919682.04 | G3: ='2'!G18 -> 0 | H3: =F3-G3 -> 919682.04
A4: 46206 | B4: Friday | C4: =H3 -> 919682.04 | D4: ='3'!C23 -> 0 | E4: ='3'!D23 -> 0 | F4: =SUM(C4:E4) -> 919682.04 | G4: ='3'!G18 -> 0 | H4: =F4-G4 -> 919682.04 | J4: Commission 1 (2.4) | L4: ='1'!M25+'2'!M25+'3'!M25+'4'!M25+'5'!M25+'6'!M25+'7'!M25+'8'!M25+'9'!M25+'10'!M25+'11'!M25+'12'!M25+'13'!M25+'14'!M25+'15'!M25+'16'!M25+'17'!M25+'18'!M25+'19'!M25+'20'!M25+'21'!M25+'22'!M25+'23'!M25+'24'!M25+'25'!M25+'26'!M25+'27'!M25+'28'!M25+'29'!M25+'30'!M25+'31'!M25 -> 660.19104
A5: 46207 | B5: Saturday | C5: =H4 -> 919682.04 | D5: ='4'!C23 -> 0 | E5: ='4'!D23 -> 0 | F5: =SUM(C5:E5) -> 919682.04 | G5: ='4'!G18 -> 0 | H5: =F5-G5 -> 919682.04 | J5: Commission 2 (1.16) | L5: ='1'!M26+'2'!M26+'3'!M26+'4'!M26+'5'!M26+'6'!M26+'7'!M26+'8'!M26+'9'!M26+'10'!M26+'11'!M26+'12'!M26+'13'!M26+'14'!M26+'15'!M26+'16'!M26+'17'!M26+'18'!M26+'19'!M26+'20'!M26+'21'!M26+'22'!M26+'23'!M26+'24'!M26+'25'!M26+'26'!M26+'27'!M26+'28'!M26+'29'!M26+'30'!M26+'31'!M26 -> 13295.514
A6: 46208 | B6: Sunday | C6: =H5 -> 919682.04 | D6: ='5'!C23 -> 0 | E6: ='5'!D23 -> 0 | F6: =SUM(C6:E6) -> 919682.04 | G6: ='5'!G18 -> 0 | H6: =F6-G6 -> 919682.04 | J6: Total Day Commission | L6: =L5+L4 -> 13955.705
A7: 46209 | B7: Monday | C7: =H6 -> 919682.04 | D7: ='6'!C23 -> 0 | E7: ='6'!D23 -> 0 | F7: =SUM(C7:E7) -> 919682.04 | G7: ='6'!G18 -> 0 | H7: =F7-G7 -> 919682.04
A8: 46210 | B8: Tuesday | C8: =H7 -> 919682.04 | D8: ='7'!C23 -> 0 | E8: ='7'!D23 -> 0 | F8: =SUM(C8:E8) -> 919682.04 | G8: ='7'!G18 -> 0 | H8: =F8-G8 -> 919682.04
A9: 46211 | B9: Wednesday | C9: =H8 -> 919682.04 | D9: ='8'!C23 -> 0 | E9: ='8'!D23 -> 0 | F9: =SUM(C9:E9) -> 919682.04 | G9: ='8'!G18 -> 0 | H9: =F9-G9 -> 919682.04
A10: 46212 | B10: Thursday | C10: =H9 -> 919682.04 | D10: ='9'!C23 -> 0 | E10: ='8'!D24 -> 0 | F10: =SUM(C10:E10) -> 919682.04 | G10: ='9'!G18 -> 0 | H10: =F10-G10 -> 919682.04
A11: 46213 | B11: Friday | C11: =H10 -> 919682.04 | D11: ='10'!C23 -> 0 | E11: ='10'!D23 -> 0 | F11: =SUM(C11:E11) -> 919682.04 | G11: ='10'!G18 -> 0 | H11: =F11-G11 -> 919682.04
A12: 46214 | B12: Saturday | C12: =H11 -> 919682.04 | D12: ='11'!C23 -> 0 | E12: ='11'!D23 -> 0 | F12: =SUM(C12:E12) -> 919682.04 | G12: ='11'!G18 -> 0 | H12: =F12-G12 -> 919682.04
A13: 46215 | B13: Sunday | C13: =H12 -> 919682.04 | D13: ='12'!C23 -> 0 | E13: ='12'!D23 -> 0 | F13: =SUM(C13:E13) -> 919682.04 | G13: ='12'!G18 -> 0 | H13: =F13-G13 -> 919682.04
A14: 46216 | B14: Monday | C14: =H13 -> 919682.04 | D14: ='13'!C23 -> 0 | E14: ='13'!D23 -> 0 | F14: =SUM(C14:E14) -> 919682.04 | G14: ='13'!G18 -> 0 | H14: =F14-G14 -> 919682.04
A15: 46217 | B15: Tuesday | C15: =H14 -> 919682.04 | D15: ='14'!C23 -> 0 | E15: ='14'!D23 -> 0 | F15: =SUM(C15:E15) -> 919682.04 | G15: ='14'!G18 -> 0 | H15: =F15-G15 -> 919682.04
A16: 46218 | B16: Wednesday | C16: =H15 -> 919682.04 | D16: ='15'!C23 -> 0 | E16: ='15'!D23 -> 0 | F16: =SUM(C16:E16) -> 919682.04 | G16: ='15'!G18 -> 0 | H16: =F16-G16 -> 919682.04
A17: 46219 | B17: Thursday | C17: =H16 -> 919682.04 | D17: ='16'!C23 -> 0 | E17: ='16'!D23 -> 0 | F17: =SUM(C17:E17) -> 919682.04 | G17: ='16'!G18 -> 0 | H17: =F17-G17 -> 919682.04
A18: 46220 | B18: Friday | C18: =H17 -> 919682.04 | D18: ='17'!C23 -> 0 | E18: ='17'!D23 -> 0 | F18: =SUM(C18:E18) -> 919682.04 | G18: ='17'!G18 -> 0 | H18: =F18-G18 -> 919682.04
A19: 46221 | B19: Saturday | C19: =H18 -> 919682.04 | D19: ='18'!C23 -> 0 | E19: ='18'!D23 -> 0 | F19: =SUM(C19:E19) -> 919682.04 | G19: ='18'!G18 -> 0 | H19: =F19-G19 -> 919682.04
A20: 46222 | B20: Sunday | C20: =H19 -> 919682.04 | D20: ='19'!C23 -> 0 | E20: ='19'!D23 -> 0 | F20: =SUM(C20:E20) -> 919682.04 | G20: ='19'!G18 -> 0 | H20: =F20-G20 -> 919682.04
A21: 46223 | B21: Monday | C21: =H20 -> 919682.04 | D21: ='20'!C23 -> 0 | E21: ='20'!D23 -> 0 | F21: =SUM(C21:E21) -> 919682.04 | G21: ='20'!G18 -> 0 | H21: =F21-G21 -> 919682.04
A22: 46224 | B22: Tuesday | C22: =H21 -> 919682.04 | D22: ='21'!C23 -> 0 | E22: ='21'!D23 -> 0 | F22: =SUM(C22:E22) -> 919682.04 | G22: ='21'!G18 -> 0 | H22: =F22-G22 -> 919682.04
A23: 46225 | B23: Wednesday | C23: =H22 -> 919682.04 | D23: ='22'!C23 -> 0 | E23: ='22'!D23 -> 0 | F23: =SUM(C23:E23) -> 919682.04 | G23: ='22'!G18 -> 0 | H23: =F23-G23 -> 919682.04
A24: 46226 | B24: Thursday | C24: =H23 -> 919682.04 | D24: ='23'!C23 -> 0 | E24: ='23'!D23 -> 0 | F24: =SUM(C24:E24) -> 919682.04 | G24: ='23'!G18 -> 0 | H24: =F24-G24 -> 919682.04
A25: 46227 | B25: Friday | C25: =H24 -> 919682.04 | D25: ='24'!C23 -> 0 | E25: ='24'!D23 -> 0 | F25: =SUM(C25:E25) -> 919682.04 | G25: ='24'!G18 -> 0 | H25: =F25-G25 -> 919682.04
A26: 46228 | B26: Saturday | C26: =H25 -> 919682.04 | D26: ='25'!C23 -> 0 | E26: ='25'!D23 -> 0 | F26: =SUM(C26:E26) -> 919682.04 | G26: ='25'!G18 -> 0 | H26: =F26-G26 -> 919682.04
A27: 46229 | B27: Sunday | C27: =H26 -> 919682.04 | D27: ='26'!C23 -> 0 | E27: ='26'!D23 -> 0 | F27: =SUM(C27:E27) -> 919682.04 | G27: ='26'!G18 -> 0 | H27: =F27-G27 -> 919682.04
A28: 46230 | B28: Monday | C28: =H27 -> 919682.04 | D28: ='27'!C23 -> 0 | E28: ='27'!D23 -> 0 | F28: =SUM(C28:E28) -> 919682.04 | G28: ='27'!G18 -> 0 | H28: =F28-G28 -> 919682.04
A29: 46231 | B29: Tuesday | C29: =H28 -> 919682.04 | D29: ='28'!C23 -> 0 | E29: ='28'!D23 -> 0 | F29: =SUM(C29:E29) -> 919682.04 | G29: ='28'!G18 -> 0 | H29: =F29-G29 -> 919682.04
A30: 46232 | B30: Wednesday | C30: =H29 -> 919682.04 | D30: ='29'!C23 -> 0 | E30: ='29'!D23 -> 0 | F30: =SUM(C30:E30) -> 919682.04 | G30: ='29'!G18 -> 0 | H30: =F30-G30 -> 919682.04
A31: 46233 | B31: Thursday | C31: =H30 -> 919682.04 | D31: ='30'!C23 -> 0 | E31: ='30'!D23 -> 0 | F31: =SUM(C31:E31) -> 919682.04 | G31: ='30'!G18 -> 0 | H31: =F31-G31 -> 919682.04
A32: 46234 | B32: Friday | C32: =H31 -> 919682.04 | D32: ='31'!C23 -> 0 | E32: ='31'!D23 -> 0 | F32: =SUM(C32:E32) -> 919682.04 | G32: ='31'!G18 -> 0 | H32: =F32-G32 -> 919682.04

Sheet 1
D2: Opening Balance | F2: Today ML Issuance | H2: Day Total | J2: Payment Received | L2: CLOSING BALANCE
A3: S.No | B3: Do Name | C3: Do Line | D3: Amount | E3: ML | F3: Amount | G3: ML Issue | H3: Cash Receiveable | I3: ML | J3: Cash Received | K3: ML | L3: Cash Receiveable | M3: ML
A4: 1 | B4: RIZWAN | C4: 3017211475 | E4: =D4*2.4/100+D4 -> 0 | G4: =F4*2.4/100+F4 -> 0 | H4: =F4+D4 -> 0 | I4: =G4+E4 -> 0 | K4: =J4*2.4/100+J4 -> 0 | L4: =H4-J4 -> 0 | M4: =L4*2.4/100+L4 -> 0
A5: 2 | B5: MIRZA | C5: 3051639672 | E5: =D5*2.4/100+D5 -> 0 | F5: 50000 | G5: =F5*2.4/100+F5 -> 51200 | H5: =F5+D5 -> 50000 | I5: =G5+E5 -> 51200 | K5: =J5*2.4/100+J5 -> 0 | L5: =H5-J5 -> 50000 | M5: =L5*2.4/100+L5 -> 51200
A6: 3 | B6: ADNAN | C6: 3017211714 | E6: =D6*2.4/100+D6 -> 0 | F6: 66000 | G6: =F6*2.4/100+F6 -> 67584 | H6: =F6+D6 -> 66000 | I6: =G6+E6 -> 67584 | J6: 66000 | K6: =J6*2.4/100+J6 -> 67584 | L6: =H6-J6 -> 0 | M6: =L6*2.4/100+L6 -> 0
A7: 4 | B7: ARSLAN | C7: 3027100125 | E7: =D7*2.4/100+D7 -> 0 | F7: 89000 | G7: =F7*2.4/100+F7 -> 91136 | H7: =F7+D7 -> 89000 | I7: =G7+E7 -> 91136 | J7: 89000 | K7: =J7*2.4/100+J7 -> 91136 | L7: =H7-J7 -> 0 | M7: =L7*2.4/100+L7 -> 0
A8: 5 | B8: MUBASHAR | C8: 3027100126 | E8: =D8*2.4/100+D8 -> 0 | F8: 200000 | G8: =F8*2.4/100+F8 -> 204800 | H8: =F8+D8 -> 200000 | I8: =G8+E8 -> 204800 | J8: 200000 | K8: =J8*2.4/100+J8 -> 204800 | L8: =H8-J8 -> 0 | M8: =L8*2.4/100+L8 -> 0
A9: 6 | B9: IRFAN MIRZA | C9: 3027103467 | E9: =D9*2.4/100+D9 -> 0 | F9: 157000 | G9: =F9*2.4/100+F9 -> 160768 | H9: =F9+D9 -> 157000 | I9: =G9+E9 -> 160768 | J9: 157000 | K9: =J9*2.4/100+J9 -> 160768 | L9: =H9-J9 -> 0 | M9: =L9*2.4/100+L9 -> 0
A10: 7 | B10: HASSAN | C10: 3027103468 | E10: =D10*2.4/100+D10 -> 0 | F10: 201000 | G10: =F10*2.4/100+F10 -> 205824 | H10: =F10+D10 -> 201000 | I10: =G10+E10 -> 205824 | J10: 201000 | K10: =J10*2.4/100+J10 -> 205824 | L10: =H10-J10 -> 0 | M10: =L10*2.4/100+L10 -> 0
A11: 8 | B11: NAVEED | C11: 3030963707 | E11: =D11*2.4/100+D11 -> 0 | F11: 200000 | G11: =F11*2.4/100+F11 -> 204800 | H11: =F11+D11 -> 200000 | I11: =G11+E11 -> 204800 | J11: 199000 | K11: =J11*2.4/100+J11 -> 203776 | L11: =H11-J11 -> 1000 | M11: =L11*2.4/100+L11 -> 1024
A12: 9 | B12: IRFAN | C12: 3030964504 | E12: =D12*2.4/100+D12 -> 0 | F12: 70000 | G12: =F12*2.4/100+F12 -> 71680 | H12: =F12+D12 -> 70000 | I12: =G12+E12 -> 71680 | J12: 70000 | K12: =J12*2.4/100+J12 -> 71680 | L12: =H12-J12 -> 0 | M12: =L12*2.4/100+L12 -> 0
A13: 10 | B13: OFFICE | C13: 3027107343 | E13: =D13*2.4/100+D13 -> 0 | F13: 150000 | G13: =F13*2.4/100+F13 -> 153600 | H13: =F13+D13 -> 150000 | I13: =G13+E13 -> 153600 | J13: 150000 | K13: =J13*2.4/100+J13 -> 153600 | L13: =H13-J13 -> 0 | M13: =L13*2.4/100+L13 -> 0
A14: 11 | B14: ANNI | C14: 3087081311 | E14: =D14*2.4/100+D14 -> 0 | F14: 2165 | G14: =F14*2.4/100+F14 -> 2216.96 | H14: =F14+D14 -> 2165 | I14: =G14+E14 -> 2216.96 | J14: 2165 | K14: =J14*2.4/100+J14 -> 2216.96 | L14: =H14-J14 -> 0 | M14: =L14*2.4/100+L14 -> 0
A15: 12 | B15: HUSSAIN | C15: 3027108872 | E15: =D15*2.4/100+D15 -> 0 | F15: 12000 | G15: =F15*2.4/100+F15 -> 12288 | H15: =F15+D15 -> 12000 | I15: =G15+E15 -> 12288 | J15: 12000 | K15: =J15*2.4/100+J15 -> 12288 | L15: =H15-J15 -> 0 | M15: =L15*2.4/100+L15 -> 0
A16: 13 | B16: SARAM | C16: 3250919702 | E16: =D16*2.4/100+D16 -> 0 | G16: =F16*2.4/100+F16 -> 0 | H16: =F16+D16 -> 0 | I16: =G16+E16 -> 0 | K16: =J16*2.4/100+J16 -> 0 | L16: =H16-J16 -> 0 | M16: =L16*2.4/100+L16 -> 0
A17: 14 | B17: OFFICE | C17: 3027107343 | E17: =D17*2.4/100+D17 -> 0 | G17: =F17*2.4/100+F17 -> 0 | H17: =F17+D17 -> 0 | I17: =G17+E17 -> 0 | K17: =J17*2.4/100+J17 -> 0 | L17: =H17-J17 -> 0 | M17: =L17*2.4/100+L17 -> 0
A18: TOTAL | D18: =SUM(D4:D17) -> 0 | E18: =SUM(E4:E17) -> 0 | F18: =SUM(F4:F17) -> 1197165 | G18: =SUM(G4:G17) -> 1225897 | H18: =SUM(H4:H17) -> 1197165 | I18: =SUM(I4:I17) -> 1225897 | J18: =SUM(J4:J17) -> 1146165 | K18: =SUM(K4:K17) -> 1173673 | ... M18: =SUM(M4:M17) -> 52224 | N18: =K18*2.4/100 -> 28168.151 | O18: =K18-N18 -> 1145504.8 | P18: =J18-O18 -> 660.19104
A22: Opening Balance | C22: 1st ML Lifting | D22: 2nd ML Lifting | F22: Total Balance | H22: Today ML Issuance | J22: In Hand Balance
A23: 815579 | C23: 700000 | D23: 630000 | F23: =D23+C23+A23 -> 2145579 | H23: =G18 -> 1225897 | J23: =F23-H23 -> 919682.04 | L23: =J23 -> 919682.04
K25: Commission 1 (2.4) | M25: =P18 -> 660.19104
K26: Commission 2 (1.16) | M26: =J18*1.16/100 -> 13295.514
K27: Total Day Commission | M27: =M26+M25 -> 13955.705

Sheet 2
D2: Opening Balance | F2: Today ML Issuance | H2: Day Total | J2: Payment Received | L2: CLOSING BALANCE
A3: S.No | B3: Do Name | C3: Do Line | D3: Amount | E3: ML | F3: Amount | G3: ML Issue | H3: Cash Receiveable | I3: ML | J3: Cash Received | K3: ML | L3: Cash Receiveable | M3: ML
A4: 1 | B4: RIZWAN | C4: 3017211475 | D4: ='1'!L4 -> 0 | E4: =D4*2.4/100+D4 -> 0 | G4: =F4*2.4/100+F4 -> 0 | H4: =F4+D4 -> 0 | I4: =G4+E4 -> 0 | K4: =J4*2.4/100+J4 -> 0 | L4: =H4-J4 -> 0 | M4: =L4*2.4/100+L4 -> 0
A5: 2 | B5: MIRZA | C5: 3051639672 | D5: ='1'!L5 -> 50000 | E5: =D5*2.4/100+D5 -> 51200 | G5: =F5*2.4/100+F5 -> 0 | H5: =F5+D5 -> 50000 | I5: =G5+E5 -> 51200 | K5: =J5*2.4/100+J5 -> 0 | L5: =H5-J5 -> 50000 | M5: =L5*2.4/100+L5 -> 51200
A6: 3 | B6: ADNAN | C6: 3017211714 | D6: ='1'!L6 -> 0 | E6: =D6*2.4/100+D6 -> 0 | G6: =F6*2.4/100+F6 -> 0 | H6: =F6+D6 -> 0 | I6: =G6+E6 -> 0 | K6: =J6*2.4/100+J6 -> 0 | L6: =H6-J6 -> 0 | M6: =L6*2.4/100+L6 -> 0
A7: 4 | B7: ARSLAN | C7: 3027100125 | D7: ='1'!L7 -> 0 | E7: =D7*2.4/100+D7 -> 0 | G7: =F7*2.4/100+F7 -> 0 | H7: =F7+D7 -> 0 | I7: =G7+E7 -> 0 | K7: =J7*2.4/100+J7 -> 0 | L7: =H7-J7 -> 0 | M7: =L7*2.4/100+L7 -> 0
A8: 5 | B8: MUBASHAR | C8: 3027100126 | D8: ='1'!L8 -> 0 | E8: =D8*2.4/100+D8 -> 0 | G8: =F8*2.4/100+F8 -> 0 | H8: =F8+D8 -> 0 | I8: =G8+E8 -> 0 | K8: =J8*2.4/100+J8 -> 0 | L8: =H8-J8 -> 0 | M8: =L8*2.4/100+L8 -> 0
A9: 6 | B9: IRFAN MIRZA | C9: 3027103467 | D9: ='1'!L9 -> 0 | E9: =D9*2.4/100+D9 -> 0 | G9: =F9*2.4/100+F9 -> 0 | H9: =F9+D9 -> 0 | I9: =G9+E9 -> 0 | K9: =J9*2.4/100+J9 -> 0 | L9: =H9-J9 -> 0 | M9: =L9*2.4/100+L9 -> 0
A10: 7 | B10: HASSAN | C10: 3027103468 | D10: ='1'!L10 -> 0 | E10: =D10*2.4/100+D10 -> 0 | G10: =F10*2.4/100+F10 -> 0 | H10: =F10+D10 -> 0 | I10: =G10+E10 -> 0 | K10: =J10*2.4/100+J10 -> 0 | L10: =H10-J10 -> 0 | M10: =L10*2.4/100+L10 -> 0
A11: 8 | B11: NAVEED | C11: 3030963707 | D11: ='1'!L11 -> 1000 | E11: =D11*2.4/100+D11 -> 1024 | G11: =F11*2.4/100+F11 -> 0 | H11: =F11+D11 -> 1000 | I11: =G11+E11 -> 1024 | K11: =J11*2.4/100+J11 -> 0 | L11: =H11-J11 -> 1000 | M11: =L11*2.4/100+L11 -> 1024
A12: 9 | B12: IRFAN | C12: 3030964504 | D12: ='1'!L12 -> 0 | E12: =D12*2.4/100+D12 -> 0 | G12: =F12*2.4/100+F12 -> 0 | H12: =F12+D12 -> 0 | I12: =G12+E12 -> 0 | K12: =J12*2.4/100+J12 -> 0 | L12: =H12-J12 -> 0 | M12: =L12*2.4/100+L12 -> 0
A13: 10 | D13: ='1'!L13 -> 0 | E13: =D13*2.4/100+D13 -> 0 | G13: =F13*2.4/100+F13 -> 0 | H13: =F13+D13 -> 0 | I13: =G13+E13 -> 0 | K13: =J13*2.4/100+J13 -> 0 | L13: =H13-J13 -> 0 | M13: =L13*2.4/100+L13 -> 0
A14: 11 | D14: ='1'!L14 -> 0 | E14: =D14*2.4/100+D14 -> 0 | G14: =F14*2.4/100+F14 -> 0 | H14: =F14+D14 -> 0 | I14: =G14+E14 -> 0 | K14: =J14*2.4/100+J14 -> 0 | L14: =H14-J14 -> 0 | M14: =L14*2.4/100+L14 -> 0
A15: 12 | D15: ='1'!L15 -> 0 | E15: =D15*2.4/100+D15 -> 0 | G15: =F15*2.4/100+F15 -> 0 | H15: =F15+D15 -> 0 | I15: =G15+E15 -> 0 | K15: =J15*2.4/100+J15 -> 0 | L15: =H15-J15 -> 0 | M15: =L15*2.4/100+L15 -> 0
A16: 13 | D16: ='1'!L16 -> 0 | E16: =D16*2.4/100+D16 -> 0 | G16: =F16*2.4/100+F16 -> 0 | H16: =F16+D16 -> 0 | I16: =G16+E16 -> 0 | K16: =J16*2.4/100+J16 -> 0 | L16: =H16-J16 -> 0 | M16: =L16*2.4/100+L16 -> 0
A17: 14 | B17: OFFICE | C17: 3027107343 | D17: ='1'!L17 -> 0 | E17: =D17*2.4/100+D17 -> 0 | G17: =F17*2.4/100+F17 -> 0 | H17: =F17+D17 -> 0 | I17: =G17+E17 -> 0 | K17: =J17*2.4/100+J17 -> 0 | L17: =H17-J17 -> 0 | M17: =L17*2.4/100+L17 -> 0
A18: TOTAL | D18: =SUM(D4:D17) -> 51000 | E18: =SUM(E4:E17) -> 52224 | F18: =SUM(F4:F17) -> 0 | G18: =SUM(G4:G17) -> 0 | H18: =SUM(H4:H17) -> 51000 | I18: =SUM(I4:I17) -> 52224 | J18: =SUM(J4:J17) -> 0 | K18: =SUM(K4:K17) -> 0 | ... M18: =SUM(M4:M17) -> 52224 | N18: =K18*2.4/100 -> 0 | O18: =K18-N18 -> 0 | P18: =J18-O18 -> 0
A22: Opening Balance | C22: 1st ML Lifting | D22: 2nd ML Lifting | F22: Total Balance | H22: Today ML Issuance | J22: In Hand Balance
A23: ='1'!L23 -> 919682.04 | F23: =D23+C23+A23 -> 919682.04 | H23: =G18 -> 0 | J23: =F23-H23 -> 919682.04 | L23: =J23 -> 919682.04
K25: Commission 1 (2.4) | M25: =P18 -> 0
K26: Commission 2 (1.16) | M26: =J18*1.16/100 -> 0
K27: Total Day Commission | M27: =M26+M25 -> 0

Sheet 3
D2: Opening Balance | F2: Today ML Issuance | H2: Day Total | J2: Payment Received | L2: CLOSING BALANCE
A3: S.No | B3: Do Name | C3: Do Line | D3: Amount | E3: ML | F3: Amount | G3: ML Issue | H3: Cash Receiveable | I3: ML | J3: Cash Received | K3: ML | L3: Cash Receiveable | M3: ML
A4: 1 | B4: RIZWAN | C4: 3017211475 | D4: ='2'!L4 -> 0 | E4: =D4*2.4/100+D4 -> 0 | G4: =F4*2.4/100+F4 -> 0 | H4: =F4+D4 -> 0 | I4: =G4+E4 -> 0 | K4: =J4*2.4/100+J4 -> 0 | L4: =H4-J4 -> 0 | M4: =L4*2.4/100+L4 -> 0
A5: 2 | B5: MIRZA | C5: 3051639672 | D5: ='2'!L5 -> 50000 | E5: =D5*2.4/100+D5 -> 51200 | G5: =F5*2.4/100+F5 -> 0 | H5: =F5+D5 -> 50000 | I5: =G5+E5 -> 51200 | K5: =J5*2.4/100+J5 -> 0 | L5: =H5-J5 -> 50000 | M5: =L5*2.4/100+L5 -> 51200
A6: 3 | B6: ADNAN | C6: 3017211714 | D6: ='2'!L6 -> 0 | E6: =D6*2.4/100+D6 -> 0 | G6: =F6*2.4/100+F6 -> 0 | H6: =F6+D6 -> 0 | I6: =G6+E6 -> 0 | K6: =J6*2.4/100+J6 -> 0 | L6: =H6-J6 -> 0 | M6: =L6*2.4/100+L6 -> 0
A7: 4 | B7: ARSLAN | C7: 3027100125 | D7: ='2'!L7 -> 0 | E7: =D7*2.4/100+D7 -> 0 | G7: =F7*2.4/100+F7 -> 0 | H7: =F7+D7 -> 0 | I7: =G7+E7 -> 0 | K7: =J7*2.4/100+J7 -> 0 | L7: =H7-J7 -> 0 | M7: =L7*2.4/100+L7 -> 0
A8: 5 | B8: MUBASHAR | C8: 3027100126 | D8: ='2'!L8 -> 0 | E8: =D8*2.4/100+D8 -> 0 | G8: =F8*2.4/100+F8 -> 0 | H8: =F8+D8 -> 0 | I8: =G8+E8 -> 0 | K8: =J8*2.4/100+J8 -> 0 | L8: =H8-J8 -> 0 | M8: =L8*2.4/100+L8 -> 0
A9: 6 | B9: IRFAN MIRZA | C9: 3027103467 | D9: ='2'!L9 -> 0 | E9: =D9*2.4/100+D9 -> 0 | G9: =F9*2.4/100+F9 -> 0 | H9: =F9+D9 -> 0 | I9: =G9+E9 -> 0 | K9: =J9*2.4/100+J9 -> 0 | L9: =H9-J9 -> 0 | M9: =L9*2.4/100+L9 -> 0
A10: 7 | B10: HASSAN | C10: 3027103468 | D10: ='2'!L10 -> 0 | E10: =D10*2.4/100+D10 -> 0 | G10: =F10*2.4/100+F10 -> 0 | H10: =F10+D10 -> 0 | I10: =G10+E10 -> 0 | K10: =J10*2.4/100+J10 -> 0 | L10: =H10-J10 -> 0 | M10: =L10*2.4/100+L10 -> 0
A11: 8 | B11: NAVEED | C11: 3030963707 | D11: ='2'!L11 -> 1000 | E11: =D11*2.4/100+D11 -> 1024 | G11: =F11*2.4/100+F11 -> 0 | H11: =F11+D11 -> 1000 | I11: =G11+E11 -> 1024 | K11: =J11*2.4/100+J11 -> 0 | L11: =H11-J11 -> 1000 | M11: =L11*2.4/100+L11 -> 1024
A12: 9 | B12: IRFAN | C12: 3030964504 | D12: ='2'!L12 -> 0 | E12: =D12*2.4/100+D12 -> 0 | G12: =F12*2.4/100+F12 -> 0 | H12: =F12+D12 -> 0 | I12: =G12+E12 -> 0 | K12: =J12*2.4/100+J12 -> 0 | L12: =H12-J12 -> 0 | M12: =L12*2.4/100+L12 -> 0
A13: 10 | D13: ='2'!L13 -> 0 | E13: =D13*2.4/100+D13 -> 0 | G13: =F13*2.4/100+F13 -> 0 | H13: =F13+D13 -> 0 | I13: =G13+E13 -> 0 | K13: =J13*2.4/100+J13 -> 0 | L13: =H13-J13 -> 0 | M13: =L13*2.4/100+L13 -> 0
A14: 11 | D14: ='2'!L14 -> 0 | E14: =D14*2.4/100+D14 -> 0 | G14: =F14*2.4/100+F14 -> 0 | H14: =F14+D14 -> 0 | I14: =G14+E14 -> 0 | K14: =J14*2.4/100+J14 -> 0 | L14: =H14-J14 -> 0 | M14: =L14*2.4/100+L14 -> 0
A15: 12 | D15: ='2'!L15 -> 0 | E15: =D15*2.4/100+D15 -> 0 | G15: =F15*2.4/100+F15 -> 0 | H15: =F15+D15 -> 0 | I15: =G15+E15 -> 0 | K15: =J15*2.4/100+J15 -> 0 | L15: =H15-J15 -> 0 | M15: =L15*2.4/100+L15 -> 0
A16: 13 | D16: ='2'!L16 -> 0 | E16: =D16*2.4/100+D16 -> 0 | G16: =F16*2.4/100+F16 -> 0 | H16: =F16+D16 -> 0 | I16: =G16+E16 -> 0 | K16: =J16*2.4/100+J16 -> 0 | L16: =H16-J16 -> 0 | M16: =L16*2.4/100+L16 -> 0
A17: 14 | B17: OFFICE | C17: 3027107343 | D17: ='2'!L17 -> 0 | E17: =D17*2.4/100+D17 -> 0 | G17: =F17*2.4/100+F17 -> 0 | H17: =F17+D17 -> 0 | I17: =G17+E17 -> 0 | K17: =J17*2.4/100+J17 -> 0 | L17: =H17-J17 -> 0 | M17: =L17*2.4/100+L17 -> 0
A18: TOTAL | D18: =SUM(D4:D17) -> 51000 | E18: =SUM(E4:E17) -> 52224 | F18: =SUM(F4:F17) -> 0 | G18: =SUM(G4:G17) -> 0 | H18: =SUM(H4:H17) -> 51000 | I18: =SUM(I4:I17) -> 52224 | J18: =SUM(J4:J17) -> 0 | K18: =SUM(K4:K17) -> 0 | ... M18: =SUM(M4:M17) -> 52224 | N18: =K18*2.4/100 -> 0 | O18: =K18-N18 -> 0 | P18: =J18-O18 -> 0
A22: Opening Balance | C22: 1st ML Lifting | D22: 2nd ML Lifting | F22: Total Balance | H22: Today ML Issuance | J22: In Hand Balance
A23: ='2'!L23 -> 919682.04 | F23: =D23+C23+A23 -> 919682.04 | H23: =G18 -> 0 | J23: =F23-H23 -> 919682.04 | L23: =J23 -> 919682.04
K25: Commission 1 (2.6) | M25: =P18 -> 0
K26: Commission 2 (.96) | M26: =J18*1.16/100 -> 0
K27: Total Day Commission | M27: =M26+M25 -> 0

Sheet 4
D2: Opening Balance | F2: Today ML Issuance | H2: Day Total | J2: Payment Received | L2: CLOSING BALANCE
A3: S.No | B3: Do Name | C3: Do Line | D3: Amount | E3: ML | F3: Amount | G3: ML Issue | H3: Cash Receiveable | I3: ML | J3: Cash Received | K3: ML | L3: Cash Receiveable | M3: ML
A4: 1 | B4: RIZWAN | C4: 3017211475 | D4: ='3'!L4 -> 0 | E4: =D4*2.4/100+D4 -> 0 | G4: =F4*2.4/100+F4 -> 0 | H4: =F4+D4 -> 0 | I4: =G4+E4 -> 0 | K4: =J4*2.4/100+J4 -> 0 | L4: =H4-J4 -> 0 | M4: =L4*2.4/100+L4 -> 0
A5: 2 | B5: MIRZA | C5: 3051639672 | D5: ='3'!L5 -> 50000 | E5: =D5*2.4/100+D5 -> 51200 | G5: =F5*2.4/100+F5 -> 0 | H5: =F5+D5 -> 50000 | I5: =G5+E5 -> 51200 | K5: =J5*2.4/100+J5 -> 0 | L5: =H5-J5 -> 50000 | M5: =L5*2.4/100+L5 -> 51200
A6: 3 | B6: ADNAN | C6: 3017211714 | D6: ='3'!L6 -> 0 | E6: =D6*2.4/100+D6 -> 0 | G6: =F6*2.4/100+F6 -> 0 | H6: =F6+D6 -> 0 | I6: =G6+E6 -> 0 | K6: =J6*2.4/100+J6 -> 0 | L6: =H6-J6 -> 0 | M6: =L6*2.4/100+L6 -> 0
A7: 4 | B7: ARSLAN | C7: 3027100125 | D7: ='3'!L7 -> 0 | E7: =D7*2.4/100+D7 -> 0 | G7: =F7*2.4/100+F7 -> 0 | H7: =F7+D7 -> 0 | I7: =G7+E7 -> 0 | K7: =J7*2.4/100+J7 -> 0 | L7: =H7-J7 -> 0 | M7: =L7*2.4/100+L7 -> 0
A8: 5 | B8: MUBASHAR | C8: 3027100126 | D8: ='3'!L8 -> 0 | E8: =D8*2.4/100+D8 -> 0 | G8: =F8*2.4/100+F8 -> 0 | H8: =F8+D8 -> 0 | I8: =G8+E8 -> 0 | K8: =J8*2.4/100+J8 -> 0 | L8: =H8-J8 -> 0 | M8: =L8*2.4/100+L8 -> 0
A9: 6 | B9: IRFAN MIRZA | C9: 3027103467 | D9: ='3'!L9 -> 0 | E9: =D9*2.4/100+D9 -> 0 | G9: =F9*2.4/100+F9 -> 0 | H9: =F9+D9 -> 0 | I9: =G9+E9 -> 0 | K9: =J9*2.4/100+J9 -> 0 | L9: =H9-J9 -> 0 | M9: =L9*2.4/100+L9 -> 0
A10: 7 | B10: HASSAN | C10: 3027103468 | D10: ='3'!L10 -> 0 | E10: =D10*2.4/100+D10 -> 0 | G10: =F10*2.4/100+F10 -> 0 | H10: =F10+D10 -> 0 | I10: =G10+E10 -> 0 | K10: =J10*2.4/100+J10 -> 0 | L10: =H10-J10 -> 0 | M10: =L10*2.4/100+L10 -> 0
A11: 8 | B11: NAVEED | C11: 3030963707 | D11: ='3'!L11 -> 1000 | E11: =D11*2.4/100+D11 -> 1024 | G11: =F11*2.4/100+F11 -> 0 | H11: =F11+D11 -> 1000 | I11: =G11+E11 -> 1024 | K11: =J11*2.4/100+J11 -> 0 | L11: =H11-J11 -> 1000 | M11: =L11*2.4/100+L11 -> 1024
A12: 9 | B12: IRFAN | C12: 3030964504 | D12: ='3'!L12 -> 0 | E12: =D12*2.4/100+D12 -> 0 | G12: =F12*2.4/100+F12 -> 0 | H12: =F12+D12 -> 0 | I12: =G12+E12 -> 0 | K12: =J12*2.4/100+J12 -> 0 | L12: =H12-J12 -> 0 | M12: =L12*2.4/100+L12 -> 0
A13: 10 | D13: ='3'!L13 -> 0 | E13: =D13*2.4/100+D13 -> 0 | G13: =F13*2.4/100+F13 -> 0 | H13: =F13+D13 -> 0 | I13: =G13+E13 -> 0 | K13: =J13*2.4/100+J13 -> 0 | L13: =H13-J13 -> 0 | M13: =L13*2.4/100+L13 -> 0
A14: 11 | D14: ='3'!L14 -> 0 | E14: =D14*2.4/100+D14 -> 0 | G14: =F14*2.4/100+F14 -> 0 | H14: =F14+D14 -> 0 | I14: =G14+E14 -> 0 | K14: =J14*2.4/100+J14 -> 0 | L14: =H14-J14 -> 0 | M14: =L14*2.4/100+L14 -> 0
A15: 12 | D15: ='3'!L15 -> 0 | E15: =D15*2.4/100+D15 -> 0 | G15: =F15*2.4/100+F15 -> 0 | H15: =F15+D15 -> 0 | I15: =G15+E15 -> 0 | K15: =J15*2.4/100+J15 -> 0 | L15: =H15-J15 -> 0 | M15: =L15*2.4/100+L15 -> 0
A16: 13 | D16: ='3'!L16 -> 0 | E16: =D16*2.4/100+D16 -> 0 | G16: =F16*2.4/100+F16 -> 0 | H16: =F16+D16 -> 0 | I16: =G16+E16 -> 0 | K16: =J16*2.4/100+J16 -> 0 | L16: =H16-J16 -> 0 | M16: =L16*2.4/100+L16 -> 0
A17: 14 | B17: OFFICE | C17: 3027107343 | D17: ='3'!L17 -> 0 | E17: =D17*2.4/100+D17 -> 0 | G17: =F17*2.4/100+F17 -> 0 | H17: =F17+D17 -> 0 | I17: =G17+E17 -> 0 | K17: =J17*2.4/100+J17 -> 0 | L17: =H17-J17 -> 0 | M17: =L17*2.4/100+L17 -> 0
A18: TOTAL | D18: =SUM(D4:D17) -> 51000 | E18: =SUM(E4:E17) -> 52224 | F18: =SUM(F4:F17) -> 0 | G18: =SUM(G4:G17) -> 0 | H18: =SUM(H4:H17) -> 51000 | I18: =SUM(I4:I17) -> 52224 | J18: =SUM(J4:J17) -> 0 | K18: =SUM(K4:K17) -> 0 | ... M18: =SUM(M4:M17) -> 52224 | N18: =K18*2.4/100 -> 0 | O18: =K18-N18 -> 0 | P18: =J18-O18 -> 0
A22: Opening Balance | C22: 1st ML Lifting | D22: 2nd ML Lifting | F22: Total Balance | H22: Today ML Issuance | J22: In Hand Balance
A23: ='3'!L23 -> 919682.04 | F23: =D23+C23+A23 -> 919682.04 | H23: =G18 -> 0 | J23: =F23-H23 -> 919682.04 | L23: =J23 -> 919682.04
K25: Commission 1 (2.4) | M25: =P18 -> 0
K26: Commission 2 (1.16) | M26: =J18*1.16/100 -> 0
K27: Total Day Commission | M27: =M26+M25 -> 0

Sheet 5
D2: Opening Balance | F2: Today ML Issuance | H2: Day Total | J2: Payment Received | L2: CLOSING BALANCE
A3: S.No | B3: Do Name | C3: Do Line | D3: Amount | E3: ML | F3: Amount | G3: ML Issue | H3: Cash Receiveable | I3: ML | J3: Cash Received | K3: ML | L3: Cash Receiveable | M3: ML
A4: 1 | B4: RIZWAN | C4: 3017211475 | D4: ='4'!L4 -> 0 | E4: =D4*2.4/100+D4 -> 0 | G4: =F4*2.4/100+F4 -> 0 | H4: =F4+D4 -> 0 | I4: =G4+E4 -> 0 | K4: =J4*2.4/100+J4 -> 0 | L4: =H4-J4 -> 0 | M4: =L4*2.4/100+L4 -> 0
A5: 2 | B5: MIRZA | C5: 3051639672 | D5: ='4'!L5 -> 50000 | E5: =D5*2.4/100+D5 -> 51200 | G5: =F5*2.4/100+F5 -> 0 | H5: =F5+D5 -> 50000 | I5: =G5+E5 -> 51200 | K5: =J5*2.4/100+J5 -> 0 | L5: =H5-J5 -> 50000 | M5: =L5*2.4/100+L5 -> 51200
A6: 3 | B6: ADNAN | C6: 3017211714 | D6: ='4'!L6 -> 0 | E6: =D6*2.4/100+D6 -> 0 | G6: =F6*2.4/100+F6 -> 0 | H6: =F6+D6 -> 0 | I6: =G6+E6 -> 0 | K6: =J6*2.4/100+J6 -> 0 | L6: =H6-J6 -> 0 | M6: =L6*2.4/100+L6 -> 0
A7: 4 | B7: ARSLAN | C7: 3027100125 | D7: ='4'!L7 -> 0 | E7: =D7*2.4/100+D7 -> 0 | G7: =F7*2.4/100+F7 -> 0 | H7: =F7+D7 -> 0 | I7: =G7+E7 -> 0 | K7: =J7*2.4/100+J7 -> 0 | L7: =H7-J7 -> 0 | M7: =L7*2.4/100+L7 -> 0
A8: 5 | B8: MUBASHAR | C8: 3027100126 | D8: ='4'!L8 -> 0 | E8: =D8*2.4/100+D8 -> 0 | G8: =F8*2.4/100+F8 -> 0 | H8: =F8+D8 -> 0 | I8: =G8+E8 -> 0 | K8: =J8*2.4/100+J8 -> 0 | L8: =H8-J8 -> 0 | M8: =L8*2.4/100+L8 -> 0
A9: 6 | B9: IRFAN MIRZA | C9: 3027103467 | D9: ='4'!L9 -> 0 | E9: =D9*2.4/100+D9 -> 0 | G9: =F9*2.4/100+F9 -> 0 | H9: =F9+D9 -> 0 | I9: =G9+E9 -> 0 | K9: =J9*2.4/100+J9 -> 0 | L9: =H9-J9 -> 0 | M9: =L9*2.4/100+L9 -> 0
A10: 7 | B10: HASSAN | C10: 3027103468 | D10: ='4'!L10 -> 0 | E10: =D10*2.4/100+D10 -> 0 | G10: =F10*2.4/100+F10 -> 0 | H10: =F10+D10 -> 0 | I10: =G10+E10 -> 0 | K10: =J10*2.4/100+J10 -> 0 | L10: =H10-J10 -> 0 | M10: =L10*2.4/100+L10 -> 0
A11: 8 | B11: NAVEED | C11: 3030963707 | D11: ='4'!L11 -> 1000 | E11: =D11*2.4/100+D11 -> 1024 | G11: =F11*2.4/100+F11 -> 0 | H11: =F11+D11 -> 1000 | I11: =G11+E11 -> 1024 | K11: =J11*2.4/100+J11 -> 0 | L11: =H11-J11 -> 1000 | M11: =L11*2.4/100+L11 -> 1024
A12: 9 | B12: IRFAN | C12: 3030964504 | D12: ='4'!L12 -> 0 | E12: =D12*2.4/100+D12 -> 0 | G12: =F12*2.4/100+F12 -> 0 | H12: =F12+D12 -> 0 | I12: =G12+E12 -> 0 | K12: =J12*2.4/100+J12 -> 0 | L12: =H12-J12 -> 0 | M12: =L12*2.4/100+L12 -> 0
A13: 10 | D13: ='4'!L13 -> 0 | E13: =D13*2.4/100+D13 -> 0 | G13: =F13*2.4/100+F13 -> 0 | H13: =F13+D13 -> 0 | I13: =G13+E13 -> 0 | K13: =J13*2.4/100+J13 -> 0 | L13: =H13-J13 -> 0 | M13: =L13*2.4/100+L13 -> 0
A14: 11 | D14: ='4'!L14 -> 0 | E14: =D14*2.4/100+D14 -> 0 | G14: =F14*2.4/100+F14 -> 0 | H14: =F14+D14 -> 0 | I14: =G14+E14 -> 0 | K14: =J14*2.4/100+J14 -> 0 | L14: =H14-J14 -> 0 | M14: =L14*2.4/100+L14 -> 0
A15: 12 | D15: ='4'!L15 -> 0 | E15: =D15*2.4/100+D15 -> 0 | G15: =F15*2.4/100+F15 -> 0 | H15: =F15+D15 -> 0 | I15: =G15+E15 -> 0 | K15: =J15*2.4/100+J15 -> 0 | L15: =H15-J15 -> 0 | M15: =L15*2.4/100+L15 -> 0
A16: 13 | D16: ='4'!L16 -> 0 | E16: =D16*2.4/100+D16 -> 0 | G16: =F16*2.4/100+F16 -> 0 | H16: =F16+D16 -> 0 | I16: =G16+E16 -> 0 | K16: =J16*2.4/100+J16 -> 0 | L16: =H16-J16 -> 0 | M16: =L16*2.4/100+L16 -> 0
A17: 14 | B17: OFFICE | C17: 3027107343 | D17: ='4'!L17 -> 0 | E17: =D17*2.4/100+D17 -> 0 | G17: =F17*2.4/100+F17 -> 0 | H17: =F17+D17 -> 0 | I17: =G17+E17 -> 0 | K17: =J17*2.4/100+J17 -> 0 | L17: =H17-J17 -> 0 | M17: =L17*2.4/100+L17 -> 0
A18: TOTAL | D18: =SUM(D4:D17) -> 51000 | E18: =SUM(E4:E17) -> 52224 | F18: =SUM(F4:F17) -> 0 | G18: =SUM(G4:G17) -> 0 | H18: =SUM(H4:H17) -> 51000 | I18: =SUM(I4:I17) -> 52224 | J18: =SUM(J4:J17) -> 0 | K18: =SUM(K4:K17) -> 0 | ... M18: =SUM(M4:M17) -> 52224 | N18: =K18*2.4/100 -> 0 | O18: =K18-N18 -> 0 | P18: =J18-O18 -> 0
A22: Opening Balance | C22: 1st ML Lifting | D22: 2nd ML Lifting | F22: Total Balance | H22: Today ML Issuance | J22: In Hand Balance
A23: ='4'!L23 -> 919682.04 | F23: =D23+C23+A23 -> 919682.04 | H23: =G18 -> 0 | J23: =F23-H23 -> 919682.04 | L23: =J23 -> 919682.04
K25: Commission 1 (2.4) | M25: =P18 -> 0
K26: Commission 2 (1.16) | M26: =J18*1.16/100 -> 0
K27: Total Day Commission | M27: =M26+M25 -> 0

Sheet 6
D2: Opening Balance | F2: Today ML Issuance | H2: Day Total | J2: Payment Received | L2: CLOSING BALANCE
A3: S.No | B3: Do Name | C3: Do Line | D3: Amount | E3: ML | F3: Amount | G3: ML Issue | H3: Cash Receiveable | I3: ML | J3: Cash Received | K3: ML | L3: Cash Receiveable | M3: ML
A4: 1 | B4: RIZWAN | C4: 3017211475 | D4: ='5'!L4 -> 0 | E4: =D4*2.4/100+D4 -> 0 | G4: =F4*2.4/100+F4 -> 0 | H4: =F4+D4 -> 0 | I4: =G4+E4 -> 0 | K4: =J4*2.4/100+J4 -> 0 | L4: =H4-J4 -> 0 | M4: =L4*2.4/100+L4 -> 0
A5: 2 | B5: MIRZA | C5: 3051639672 | D5: ='5'!L5 -> 50000 | E5: =D5*2.4/100+D5 -> 51200 | G5: =F5*2.4/100+F5 -> 0 | H5: =F5+D5 -> 50000 | I5: =G5+E5 -> 51200 | K5: =J5*2.4/100+J5 -> 0 | L5: =H5-J5 -> 50000 | M5: =L5*2.4/100+L5 -> 51200
A6: 3 | B6: ADNAN | C6: 3017211714 | D6: ='5'!L6 -> 0 | E6: =D6*2.4/100+D6 -> 0 | G6: =F6*2.4/100+F6 -> 0 | H6: =F6+D6 -> 0 | I6: =G6+E6 -> 0 | K6: =J6*2.4/100+J6 -> 0 | L6: =H6-J6 -> 0 | M6: =L6*2.4/100+L6 -> 0
A7: 4 | B7: ARSLAN | C7: 3027100125 | D7: ='5'!L7 -> 0 | E7: =D7*2.4/100+D7 -> 0 | G7: =F7*2.4/100+F7 -> 0 | H7: =F7+D7 -> 0 | I7: =G7+E7 -> 0 | K7: =J7*2.4/100+J7 -> 0 | L7: =H7-J7 -> 0 | M7: =L7*2.4/100+L7 -> 0
A8: 5 | B8: MUBASHAR | C8: 3027100126 | D8: ='5'!L8 -> 0 | E8: =D8*2.4/100+D8 -> 0 | G8: =F8*2.4/100+F8 -> 0 | H8: =F8+D8 -> 0 | I8: =G8+E8 -> 0 | K8: =J8*2.4/100+J8 -> 0 | L8: =H8-J8 -> 0 | M8: =L8*2.4/100+L8 -> 0
A9: 6 | B9: IRFAN MIRZA | C9: 3027103467 | D9: ='5'!L9 -> 0 | E9: =D9*2.4/100+D9 -> 0 | G9: =F9*2.4/100+F9 -> 0 | H9: =F9+D9 -> 0 | I9: =G9+E9 -> 0 | K9: =J9*2.4/100+J9 -> 0 | L9: =H9-J9 -> 0 | M9: =L9*2.4/100+L9 -> 0
A10: 7 | B10: HASSAN | C10: 3027103468 | D10: ='5'!L10 -> 0 | E10: =D10*2.4/100+D10 -> 0 | G10: =F10*2.4/100+F10 -> 0 | H10: =F10+D10 -> 0 | I10: =G10+E10 -> 0 | K10: =J10*2.4/100+J10 -> 0 | L10: =H10-J10 -> 0 | M10: =L10*2.4/100+L10 -> 0
A11: 8 | B11: NAVEED | C11: 3030963707 | D11: ='5'!L11 -> 1000 | E11: =D11*2.4/100+D11 -> 1024 | G11: =F11*2.4/100+F11 -> 0 | H11: =F11+D11 -> 1000 | I11: =G11+E11 -> 1024 | K11: =J11*2.4/100+J11 -> 0 | L11: =H11-J11 -> 1000 | M11: =L11*2.4/100+L11 -> 1024
A12: 9 | B12: IRFAN | C12: 3030964504 | D12: ='5'!L12 -> 0 | E12: =D12*2.4/100+D12 -> 0 | G12: =F12*2.4/100+F12 -> 0 | H12: =F12+D12 -> 0 | I12: =G12+E12 -> 0 | K12: =J12*2.4/100+J12 -> 0 | L12: =H12-J12 -> 0 | M12: =L12*2.4/100+L12 -> 0
A13: 10 | D13: ='5'!L13 -> 0 | E13: =D13*2.4/100+D13 -> 0 | G13: =F13*2.4/100+F13 -> 0 | H13: =F13+D13 -> 0 | I13: =G13+E13 -> 0 | K13: =J13*2.4/100+J13 -> 0 | L13: =H13-J13 -> 0 | M13: =L13*2.4/100+L13 -> 0
A14: 11 | D14: ='5'!L14 -> 0 | E14: =D14*2.4/100+D14 -> 0 | G14: =F14*2.4/100+F14 -> 0 | H14: =F14+D14 -> 0 | I14: =G14+E14 -> 0 | K14: =J14*2.4/100+J14 -> 0 | L14: =H14-J14 -> 0 | M14: =L14*2.4/100+L14 -> 0
A15: 12 | D15: ='5'!L15 -> 0 | E15: =D15*2.4/100+D15 -> 0 | G15: =F15*2.4/100+F15 -> 0 | H15: =F15+D15 -> 0 | I15: =G15+E15 -> 0 | K15: =J15*2.4/100+J15 -> 0 | L15: =H15-J15 -> 0 | M15: =L15*2.4/100+L15 -> 0
A16: 13 | D16: ='5'!L16 -> 0 | E16: =D16*2.4/100+D16 -> 0 | G16: =F16*2.4/100+F16 -> 0 | H16: =F16+D16 -> 0 | I16: =G16+E16 -> 0 | K16: =J16*2.4/100+J16 -> 0 | L16: =H16-J16 -> 0 | M16: =L16*2.4/100+L16 -> 0
A17: 14 | B17: OFFICE | C17: 3027107343 | D17: ='5'!L17 -> 0 | E17: =D17*2.4/100+D17 -> 0 | G17: =F17*2.4/100+F17 -> 0 | H17: =F17+D17 -> 0 | I17: =G17+E17 -> 0 | K17: =J17*2.4/100+J17 -> 0 | L17: =H17-J17 -> 0 | M17: =L17*2.4/100+L17 -> 0
A18: TOTAL | D18: =SUM(D4:D17) -> 51000 | E18: =SUM(E4:E17) -> 52224 | F18: =SUM(F4:F17) -> 0 | G18: =SUM(G4:G17) -> 0 | H18: =SUM(H4:H17) -> 51000 | I18: =SUM(I4:I17) -> 52224 | J18: =SUM(J4:J17) -> 0 | K18: =SUM(K4:K17) -> 0 | ... M18: =SUM(M4:M17) -> 52224 | N18: =K18*2.4/100 -> 0 | O18: =K18-N18 -> 0 | P18: =J18-O18 -> 0
A22: Opening Balance | C22: 1st ML Lifting | D22: 2nd ML Lifting | F22: Total Balance | H22: Today ML Issuance | J22: In Hand Balance
A23: ='5'!L23 -> 919682.04 | F23: =D23+C23+A23 -> 919682.04 | H23: =G18 -> 0 | J23: =F23-H23 -> 919682.04 | L23: =J23 -> 919682.04
K25: Commission 1 (2.4) | M25: =P18 -> 0
K26: Commission 2 (1.16) | M26: =J18*1.16/100 -> 0
K27: Total Day Commission | M27: =M26+M25 -> 0

Sheet 7
D2: Opening Balance | F2: Today ML Issuance | H2: Day Total | J2: Payment Received | L2: CLOSING BALANCE
A3: S.No | B3: Do Name | C3: Do Line | D3: Amount | E3: ML | F3: Amount | G3: ML Issue | H3: Cash Receiveable | I3: ML | J3: Cash Received | K3: ML | L3: Cash Receiveable | M3: ML
A4: 1 | B4: RIZWAN | C4: 3017211475 | D4: ='6'!L4 -> 0 | E4: =D4*2.4/100+D4 -> 0 | G4: =F4*2.4/100+F4 -> 0 | H4: =F4+D4 -> 0 | I4: =G4+E4 -> 0 | K4: =J4*2.4/100+J4 -> 0 | L4: =H4-J4 -> 0 | M4: =L4*2.4/100+L4 -> 0
A5: 2 | B5: MIRZA | C5: 3051639672 | D5: ='6'!L5 -> 50000 | E5: =D5*2.4/100+D5 -> 51200 | G5: =F5*2.4/100+F5 -> 0 | H5: =F5+D5 -> 50000 | I5: =G5+E5 -> 51200 | K5: =J5*2.4/100+J5 -> 0 | L5: =H5-J5 -> 50000 | M5: =L5*2.4/100+L5 -> 51200
A6: 3 | B6: ADNAN | C6: 3017211714 | D6: ='6'!L6 -> 0 | E6: =D6*2.4/100+D6 -> 0 | G6: =F6*2.4/100+F6 -> 0 | H6: =F6+D6 -> 0 | I6: =G6+E6 -> 0 | K6: =J6*2.4/100+J6 -> 0 | L6: =H6-J6 -> 0 | M6: =L6*2.4/100+L6 -> 0
A7: 4 | B7: ARSLAN | C7: 3027100125 | D7: ='6'!L7 -> 0 | E7: =D7*2.4/100+D7 -> 0 | G7: =F7*2.4/100+F7 -> 0 | H7: =F7+D7 -> 0 | I7: =G7+E7 -> 0 | K7: =J7*2.4/100+J7 -> 0 | L7: =H7-J7 -> 0 | M7: =L7*2.4/100+L7 -> 0
A8: 5 | B8: MUBASHAR | C8: 3027100126 | D8: ='6'!L8 -> 0 | E8: =D8*2.4/100+D8 -> 0 | G8: =F8*2.4/100+F8 -> 0 | H8: =F8+D8 -> 0 | I8: =G8+E8 -> 0 | K8: =J8*2.4/100+J8 -> 0 | L8: =H8-J8 -> 0 | M8: =L8*2.4/100+L8 -> 0
A9: 6 | B9: IRFAN MIRZA | C9: 3027103467 | D9: ='6'!L9 -> 0 | E9: =D9*2.4/100+D9 -> 0 | G9: =F9*2.4/100+F9 -> 0 | H9: =F9+D9 -> 0 | I9: =G9+E9 -> 0 | K9: =J9*2.4/100+J9 -> 0 | L9: =H9-J9 -> 0 | M9: =L9*2.4/100+L9 -> 0
A10: 7 | B10: HASSAN | C10: 3027103468 | D10: ='6'!L10 -> 0 | E10: =D10*2.4/100+D10 -> 0 | G10: =F10*2.4/100+F10 -> 0 | H10: =F10+D10 -> 0 | I10: =G10+E10 -> 0 | K10: =J10*2.4/100+J10 -> 0 | L10: =H10-J10 -> 0 | M10: =L10*2.4/100+L10 -> 0
A11: 8 | B11: NAVEED | C11: 3030963707 | D11: ='6'!L11 -> 1000 | E11: =D11*2.4/100+D11 -> 1024 | G11: =F11*2.4/100+F11 -> 0 | H11: =F11+D11 -> 1000 | I11: =G11+E11 -> 1024 | K11: =J11*2.4/100+J11 -> 0 | L11: =H11-J11 -> 1000 | M11: =L11*2.4/100+L11 -> 1024
A12: 9 | B12: IRFAN | C12: 3030964504 | D12: ='6'!L12 -> 0 | E12: =D12*2.4/100+D12 -> 0 | G12: =F12*2.4/100+F12 -> 0 | H12: =F12+D12 -> 0 | I12: =G12+E12 -> 0 | K12: =J12*2.4/100+J12 -> 0 | L12: =H12-J12 -> 0 | M12: =L12*2.4/100+L12 -> 0
A13: 10 | D13: ='6'!L13 -> 0 | E13: =D13*2.4/100+D13 -> 0 | G13: =F13*2.4/100+F13 -> 0 | H13: =F13+D13 -> 0 | I13: =G13+E13 -> 0 | K13: =J13*2.4/100+J13 -> 0 | L13: =H13-J13 -> 0 | M13: =L13*2.4/100+L13 -> 0
A14: 11 | D14: ='6'!L14 -> 0 | E14: =D14*2.4/100+D14 -> 0 | G14: =F14*2.4/100+F14 -> 0 | H14: =F14+D14 -> 0 | I14: =G14+E14 -> 0 | K14: =J14*2.4/100+J14 -> 0 | L14: =H14-J14 -> 0 | M14: =L14*2.4/100+L14 -> 0
A15: 12 | D15: ='6'!L15 -> 0 | E15: =D15*2.4/100+D15 -> 0 | G15: =F15*2.4/100+F15 -> 0 | H15: =F15+D15 -> 0 | I15: =G15+E15 -> 0 | K15: =J15*2.4/100+J15 -> 0 | L15: =H15-J15 -> 0 | M15: =L15*2.4/100+L15 -> 0
A16: 13 | D16: ='6'!L16 -> 0 | E16: =D16*2.4/100+D16 -> 0 | G16: =F16*2.4/100+F16 -> 0 | H16: =F16+D16 -> 0 | I16: =G16+E16 -> 0 | K16: =J16*2.4/100+J16 -> 0 | L16: =H16-J16 -> 0 | M16: =L16*2.4/100+L16 -> 0
A17: 14 | B17: OFFICE | C17: 3027107343 | D17: ='6'!L17 -> 0 | E17: =D17*2.4/100+D17 -> 0 | G17: =F17*2.4/100+F17 -> 0 | H17: =F17+D17 -> 0 | I17: =G17+E17 -> 0 | K17: =J17*2.4/100+J17 -> 0 | L17: =H17-J17 -> 0 | M17: =L17*2.4/100+L17 -> 0
A18: TOTAL | D18: =SUM(D4:D17) -> 51000 | E18: =SUM(E4:E17) -> 52224 | F18: =SUM(F4:F17) -> 0 | G18: =SUM(G4:G17) -> 0 | H18: =SUM(H4:H17) -> 51000 | I18: =SUM(I4:I17) -> 52224 | J18: =SUM(J4:J17) -> 0 | K18: =SUM(K4:K17) -> 0 | ... M18: =SUM(M4:M17) -> 52224 | N18: =K18*2.4/100 -> 0 | O18: =K18-N18 -> 0 | P18: =J18-O18 -> 0
A22: Opening Balance | C22: 1st ML Lifting | D22: 2nd ML Lifting | F22: Total Balance | H22: Today ML Issuance | J22: In Hand Balance
A23: ='6'!L23 -> 919682.04 | F23: =D23+C23+A23 -> 919682.04 | H23: =G18 -> 0 | J23: =F23-H23 -> 919682.04 | L23: =J23 -> 919682.04
K25: Commission 1 (2.6) | M25: =P18 -> 0
K26: Commission 2 (1.16) | M26: =J18*1.16/100 -> 0
K27: Total Day Commission | M27: =M26+M25 -> 0

Sheet 8
D2: Opening Balance | F2: Today ML Issuance | H2: Day Total | J2: Payment Received | L2: CLOSING BALANCE
A3: S.No | B3: Do Name | C3: Do Line | D3: Amount | E3: ML | F3: Amount | G3: ML Issue | H3: Cash Receiveable | I3: ML | J3: Cash Received | K3: ML | L3: Cash Receiveable | M3: ML
A4: 1 | B4: RIZWAN | C4: 3017211475 | D4: ='7'!L4 -> 0 | E4: =D4*2.4/100+D4 -> 0 | G4: =F4*2.4/100+F4 -> 0 | H4: =F4+D4 -> 0 | I4: =G4+E4 -> 0 | K4: =J4*2.4/100+J4 -> 0 | L4: =H4-J4 -> 0 | M4: =L4*2.4/100+L4 -> 0
A5: 2 | B5: MIRZA | C5: 3051639672 | D5: ='7'!L5 -> 50000 | E5: =D5*2.4/100+D5 -> 51200 | G5: =F5*2.4/100+F5 -> 0 | H5: =F5+D5 -> 50000 | I5: =G5+E5 -> 51200 | K5: =J5*2.4/100+J5 -> 0 | L5: =H5-J5 -> 50000 | M5: =L5*2.4/100+L5 -> 51200
A6: 3 | B6: ADNAN | C6: 3017211714 | D6: ='7'!L6 -> 0 | E6: =D6*2.4/100+D6 -> 0 | G6: =F6*2.4/100+F6 -> 0 | H6: =F6+D6 -> 0 | I6: =G6+E6 -> 0 | K6: =J6*2.4/100+J6 -> 0 | L6: =H6-J6 -> 0 | M6: =L6*2.4/100+L6 -> 0
A7: 4 | B7: ARSLAN | C7: 3027100125 | D7: ='7'!L7 -> 0 | E7: =D7*2.4/100+D7 -> 0 | G7: =F7*2.4/100+F7 -> 0 | H7: =F7+D7 -> 0 | I7: =G7+E7 -> 0 | K7: =J7*2.4/100+J7 -> 0 | L7: =H7-J7 -> 0 | M7: =L7*2.4/100+L7 -> 0
A8: 5 | B8: MUBASHAR | C8: 3027100126 | D8: ='7'!L8 -> 0 | E8: =D8*2.4/100+D8 -> 0 | G8: =F8*2.4/100+F8 -> 0 | H8: =F8+D8 -> 0 | I8: =G8+E8 -> 0 | K8: =J8*2.4/100+J8 -> 0 | L8: =H8-J8 -> 0 | M8: =L8*2.4/100+L8 -> 0
A9: 6 | B9: IRFAN MIRZA | C9: 3027103467 | D9: ='7'!L9 -> 0 | E9: =D9*2.4/100+D9 -> 0 | G9: =F9*2.4/100+F9 -> 0 | H9: =F9+D9 -> 0 | I9: =G9+E9 -> 0 | K9: =J9*2.4/100+J9 -> 0 | L9: =H9-J9 -> 0 | M9: =L9*2.4/100+L9 -> 0
A10: 7 | B10: HASSAN | C10: 3027103468 | D10: ='7'!L10 -> 0 | E10: =D10*2.4/100+D10 -> 0 | G10: =F10*2.4/100+F10 -> 0 | H10: =F10+D10 -> 0 | I10: =G10+E10 -> 0 | K10: =J10*2.4/100+J10 -> 0 | L10: =H10-J10 -> 0 | M10: =L10*2.4/100+L10 -> 0
A11: 8 | B11: NAVEED | C11: 3030963707 | D11: ='7'!L11 -> 1000 | E11: =D11*2.4/100+D11 -> 1024 | G11: =F11*2.4/100+F11 -> 0 | H11: =F11+D11 -> 1000 | I11: =G11+E11 -> 1024 | K11: =J11*2.4/100+J11 -> 0 | L11: =H11-J11 -> 1000 | M11: =L11*2.4/100+L11 -> 1024
A12: 9 | B12: IRFAN | C12: 3030964504 | D12: ='7'!L12 -> 0 | E12: =D12*2.4/100+D12 -> 0 | G12: =F12*2.4/100+F12 -> 0 | H12: =F12+D12 -> 0 | I12: =G12+E12 -> 0 | K12: =J12*2.4/100+J12 -> 0 | L12: =H12-J12 -> 0 | M12: =L12*2.4/100+L12 -> 0
A13: 10 | D13: ='7'!L13 -> 0 | E13: =D13*2.4/100+D13 -> 0 | G13: =F13*2.4/100+F13 -> 0 | H13: =F13+D13 -> 0 | I13: =G13+E13 -> 0 | K13: =J13*2.4/100+J13 -> 0 | L13: =H13-J13 -> 0 | M13: =L13*2.4/100+L13 -> 0
A14: 11 | D14: ='7'!L14 -> 0 | E14: =D14*2.4/100+D14 -> 0 | G14: =F14*2.4/100+F14 -> 0 | H14: =F14+D14 -> 0 | I14: =G14+E14 -> 0 | K14: =J14*2.4/100+J14 -> 0 | L14: =H14-J14 -> 0 | M14: =L14*2.4/100+L14 -> 0
A15: 12 | D15: ='7'!L15 -> 0 | E15: =D15*2.4/100+D15 -> 0 | G15: =F15*2.4/100+F15 -> 0 | H15: =F15+D15 -> 0 | I15: =G15+E15 -> 0 | K15: =J15*2.4/100+J15 -> 0 | L15: =H15-J15 -> 0 | M15: =L15*2.4/100+L15 -> 0
A16: 13 | D16: ='7'!L16 -> 0 | E16: =D16*2.4/100+D16 -> 0 | G16: =F16*2.4/100+F16 -> 0 | H16: =F16+D16 -> 0 | I16: =G16+E16 -> 0 | K16: =J16*2.4/100+J16 -> 0 | L16: =H16-J16 -> 0 | M16: =L16*2.4/100+L16 -> 0
A17: 14 | B17: OFFICE | C17: 3027107343 | D17: ='7'!L17 -> 0 | E17: =D17*2.4/100+D17 -> 0 | G17: =F17*2.4/100+F17 -> 0 | H17: =F17+D17 -> 0 | I17: =G17+E17 -> 0 | K17: =J17*2.4/100+J17 -> 0 | L17: =H17-J17 -> 0 | M17: =L17*2.4/100+L17 -> 0
A18: TOTAL | D18: =SUM(D4:D17) -> 51000 | E18: =SUM(E4:E17) -> 52224 | F18: =SUM(F4:F17) -> 0 | G18: =SUM(G4:G17) -> 0 | H18: =SUM(H4:H17) -> 51000 | I18: =SUM(I4:I17) -> 52224 | J18: =SUM(J4:J17) -> 0 | K18: =SUM(K4:K17) -> 0 | ... M18: =SUM(M4:M17) -> 52224 | N18: =K18*2.4/100 -> 0 | O18: =K18-N18 -> 0 | P18: =J18-O18 -> 0
A22: Opening Balance | C22: 1st ML Lifting | D22: 2nd ML Lifting | F22: Total Balance | H22: Today ML Issuance | J22: In Hand Balance
A23: ='7'!L23 -> 919682.04 | F23: =D23+C23+A23 -> 919682.04 | H23: =G18 -> 0 | J23: =F23-H23 -> 919682.04 | L23: =J23 -> 919682.04
K25: Commission 1 (2.4) | M25: =P18 -> 0
K26: Commission 2 (1.16) | M26: =J18*1.16/100 -> 0
K27: Total Day Commission | M27: =M26+M25 -> 0

Sheet 9
D2: Opening Balance | F2: Today ML Issuance | H2: Day Total | J2: Payment Received | L2: CLOSING BALANCE
A3: S.No | B3: Do Name | C3: Do Line | D3: Amount | E3: ML | F3: Amount | G3: ML Issue | H3: Cash Receiveable | I3: ML | J3: Cash Received | K3: ML | L3: Cash Receiveable | M3: ML
A4: 1 | B4: RIZWAN | C4: 3017211475 | D4: ='8'!L4 -> 0 | E4: =D4*2.4/100+D4 -> 0 | G4: =F4*2.4/100+F4 -> 0 | H4: =F4+D4 -> 0 | I4: =G4+E4 -> 0 | K4: =J4*2.4/100+J4 -> 0 | L4: =H4-J4 -> 0 | M4: =L4*2.4/100+L4 -> 0
A5: 2 | B5: MIRZA | C5: 3051639672 | D5: ='8'!L5 -> 50000 | E5: =D5*2.4/100+D5 -> 51200 | G5: =F5*2.4/100+F5 -> 0 | H5: =F5+D5 -> 50000 | I5: =G5+E5 -> 51200 | K5: =J5*2.4/100+J5 -> 0 | L5: =H5-J5 -> 50000 | M5: =L5*2.4/100+L5 -> 51200
A6: 3 | B6: ADNAN | C6: 3017211714 | D6: ='8'!L6 -> 0 | E6: =D6*2.4/100+D6 -> 0 | G6: =F6*2.4/100+F6 -> 0 | H6: =F6+D6 -> 0 | I6: =G6+E6 -> 0 | K6: =J6*2.4/100+J6 -> 0 | L6: =H6-J6 -> 0 | M6: =L6*2.4/100+L6 -> 0
A7: 4 | B7: ARSLAN | C7: 3027100125 | D7: ='8'!L7 -> 0 | E7: =D7*2.4/100+D7 -> 0 | G7: =F7*2.4/100+F7 -> 0 | H7: =F7+D7 -> 0 | I7: =G7+E7 -> 0 | K7: =J7*2.4/100+J7 -> 0 | L7: =H7-J7 -> 0 | M7: =L7*2.4/100+L7 -> 0
A8: 5 | B8: MUBASHAR | C8: 3027100126 | D8: ='8'!L8 -> 0 | E8: =D8*2.4/100+D8 -> 0 | G8: =F8*2.4/100+F8 -> 0 | H8: =F8+D8 -> 0 | I8: =G8+E8 -> 0 | K8: =J8*2.4/100+J8 -> 0 | L8: =H8-J8 -> 0 | M8: =L8*2.4/100+L8 -> 0
A9: 6 | B9: IRFAN MIRZA | C9: 3027103467 | D9: ='8'!L9 -> 0 | E9: =D9*2.4/100+D9 -> 0 | G9: =F9*2.4/100+F9 -> 0 | H9: =F9+D9 -> 0 | I9: =G9+E9 -> 0 | K9: =J9*2.4/100+J9 -> 0 | L9: =H9-J9 -> 0 | M9: =L9*2.4/100+L9 -> 0
A10: 7 | B10: HASSAN | C10: 3027103468 | D10: ='8'!L10 -> 0 | E10: =D10*2.4/100+D10 -> 0 | G10: =F10*2.4/100+F10 -> 0 | H10: =F10+D10 -> 0 | I10: =G10+E10 -> 0 | K10: =J10*2.4/100+J10 -> 0 | L10: =H10-J10 -> 0 | M10: =L10*2.4/100+L10 -> 0
A11: 8 | B11: NAVEED | C11: 3030963707 | D11: ='8'!L11 -> 1000 | E11: =D11*2.4/100+D11 -> 1024 | G11: =F11*2.4/100+F11 -> 0 | H11: =F11+D11 -> 1000 | I11: =G11+E11 -> 1024 | K11: =J11*2.4/100+J11 -> 0 | L11: =H11-J11 -> 1000 | M11: =L11*2.4/100+L11 -> 1024
A12: 9 | B12: IRFAN | C12: 3030964504 | D12: ='8'!L12 -> 0 | E12: =D12*2.4/100+D12 -> 0 | G12: =F12*2.4/100+F12 -> 0 | H12: =F12+D12 -> 0 | I12: =G12+E12 -> 0 | K12: =J12*2.4/100+J12 -> 0 | L12: =H12-J12 -> 0 | M12: =L12*2.4/100+L12 -> 0
A13: 10 | D13: ='8'!L13 -> 0 | E13: =D13*2.4/100+D13 -> 0 | G13: =F13*2.4/100+F13 -> 0 | H13: =F13+D13 -> 0 | I13: =G13+E13 -> 0 | K13: =J13*2.4/100+J13 -> 0 | L13: =H13-J13 -> 0 | M13: =L13*2.4/100+L13 -> 0
A14: 11 | D14: ='8'!L14 -> 0 | E14: =D14*2.4/100+D14 -> 0 | G14: =F14*2.4/100+F14 -> 0 | H14: =F14+D14 -> 0 | I14: =G14+E14 -> 0 | K14: =J14*2.4/100+J14 -> 0 | L14: =H14-J14 -> 0 | M14: =L14*2.4/100+L14 -> 0
A15: 12 | D15: ='8'!L15 -> 0 | E15: =D15*2.4/100+D15 -> 0 | G15: =F15*2.4/100+F15 -> 0 | H15: =F15+D15 -> 0 | I15: =G15+E15 -> 0 | K15: =J15*2.4/100+J15 -> 0 | L15: =H15-J15 -> 0 | M15: =L15*2.4/100+L15 -> 0
A16: 13 | D16: ='8'!L16 -> 0 | E16: =D16*2.4/100+D16 -> 0 | G16: =F16*2.4/100+F16 -> 0 | H16: =F16+D16 -> 0 | I16: =G16+E16 -> 0 | K16: =J16*2.4/100+J16 -> 0 | L16: =H16-J16 -> 0 | M16: =L16*2.4/100+L16 -> 0
A17: 14 | B17: OFFICE | C17: 3027107343 | D17: ='8'!L17 -> 0 | E17: =D17*2.4/100+D17 -> 0 | G17: =F17*2.4/100+F17 -> 0 | H17: =F17+D17 -> 0 | I17: =G17+E17 -> 0 | K17: =J17*2.4/100+J17 -> 0 | L17: =H17-J17 -> 0 | M17: =L17*2.4/100+L17 -> 0
A18: TOTAL | D18: =SUM(D4:D17) -> 51000 | E18: =SUM(E4:E17) -> 52224 | F18: =SUM(F4:F17) -> 0 | G18: =SUM(G4:G17) -> 0 | H18: =SUM(H4:H17) -> 51000 | I18: =SUM(I4:I17) -> 52224 | J18: =SUM(J4:J17) -> 0 | K18: =SUM(K4:K17) -> 0 | ... M18: =SUM(M4:M17) -> 52224 | N18: =K18*2.4/100 -> 0 | O18: =K18-N18 -> 0 | P18: =J18-O18 -> 0
A22: Opening Balance | C22: 1st ML Lifting | D22: 2nd ML Lifting | F22: Total Balance | H22: Today ML Issuance | J22: In Hand Balance
A23: ='8'!L23 -> 919682.04 | F23: =D23+C23+A23 -> 919682.04 | H23: =G18 -> 0 | J23: =F23-H23 -> 919682.04 | L23: =J23 -> 919682.04
K25: Commission 1 (2.4) | M25: =P18 -> 0
K26: Commission 2 (1.16) | M26: =J18*1.16/100 -> 0
K27: Total Day Commission | M27: =M26+M25 -> 0

Sheet 10
D2: Opening Balance | F2: Today ML Issuance | H2: Day Total | J2: Payment Received | L2: CLOSING BALANCE
A3: S.No | B3: Do Name | C3: Do Line | D3: Amount | E3: ML | F3: Amount | G3: ML Issue | H3: Cash Receiveable | I3: ML | J3: Cash Received | K3: ML | L3: Cash Receiveable | M3: ML
A4: 1 | B4: RIZWAN | C4: 3017211475 | D4: ='9'!L4 -> 0 | E4: =D4*2.4/100+D4 -> 0 | G4: =F4*2.4/100+F4 -> 0 | H4: =F4+D4 -> 0 | I4: =G4+E4 -> 0 | K4: =J4*2.4/100+J4 -> 0 | L4: =H4-J4 -> 0 | M4: =L4*2.4/100+L4 -> 0
A5: 2 | B5: MIRZA | C5: 3051639672 | D5: ='9'!L5 -> 50000 | E5: =D5*2.4/100+D5 -> 51200 | G5: =F5*2.4/100+F5 -> 0 | H5: =F5+D5 -> 50000 | I5: =G5+E5 -> 51200 | K5: =J5*2.4/100+J5 -> 0 | L5: =H5-J5 -> 50000 | M5: =L5*2.4/100+L5 -> 51200
A6: 3 | B6: ADNAN | C6: 3017211714 | D6: ='9'!L6 -> 0 | E6: =D6*2.4/100+D6 -> 0 | G6: =F6*2.4/100+F6 -> 0 | H6: =F6+D6 -> 0 | I6: =G6+E6 -> 0 | K6: =J6*2.4/100+J6 -> 0 | L6: =H6-J6 -> 0 | M6: =L6*2.4/100+L6 -> 0
A7: 4 | B7: ARSLAN | C7: 3027100125 | D7: ='9'!L7 -> 0 | E7: =D7*2.4/100+D7 -> 0 | G7: =F7*2.4/100+F7 -> 0 | H7: =F7+D7 -> 0 | I7: =G7+E7 -> 0 | K7: =J7*2.4/100+J7 -> 0 | L7: =H7-J7 -> 0 | M7: =L7*2.4/100+L7 -> 0
A8: 5 | B8: MUBASHAR | C8: 3027100126 | D8: ='9'!L8 -> 0 | E8: =D8*2.4/100+D8 -> 0 | G8: =F8*2.4/100+F8 -> 0 | H8: =F8+D8 -> 0 | I8: =G8+E8 -> 0 | K8: =J8*2.4/100+J8 -> 0 | L8: =H8-J8 -> 0 | M8: =L8*2.4/100+L8 -> 0
A9: 6 | B9: IRFAN MIRZA | C9: 3027103467 | D9: ='9'!L9 -> 0 | E9: =D9*2.4/100+D9 -> 0 | G9: =F9*2.4/100+F9 -> 0 | H9: =F9+D9 -> 0 | I9: =G9+E9 -> 0 | K9: =J9*2.4/100+J9 -> 0 | L9: =H9-J9 -> 0 | M9: =L9*2.4/100+L9 -> 0
A10: 7 | B10: HASSAN | C10: 3027103468 | D10: ='9'!L10 -> 0 | E10: =D10*2.4/100+D10 -> 0 | G10: =F10*2.4/100+F10 -> 0 | H10: =F10+D10 -> 0 | I10: =G10+E10 -> 0 | K10: =J10*2.4/100+J10 -> 0 | L10: =H10-J10 -> 0 | M10: =L10*2.4/100+L10 -> 0
A11: 8 | B11: NAVEED | C11: 3030963707 | D11: ='9'!L11 -> 1000 | E11: =D11*2.4/100+D11 -> 1024 | G11: =F11*2.4/100+F11 -> 0 | H11: =F11+D11 -> 1000 | I11: =G11+E11 -> 1024 | K11: =J11*2.4/100+J11 -> 0 | L11: =H11-J11 -> 1000 | M11: =L11*2.4/100+L11 -> 1024
A12: 9 | B12: IRFAN | C12: 3030964504 | D12: ='9'!L12 -> 0 | E12: =D12*2.4/100+D12 -> 0 | G12: =F12*2.4/100+F12 -> 0 | H12: =F12+D12 -> 0 | I12: =G12+E12 -> 0 | K12: =J12*2.4/100+J12 -> 0 | L12: =H12-J12 -> 0 | M12: =L12*2.4/100+L12 -> 0
A13: 10 | D13: ='9'!L13 -> 0 | E13: =D13*2.4/100+D13 -> 0 | G13: =F13*2.4/100+F13 -> 0 | H13: =F13+D13 -> 0 | I13: =G13+E13 -> 0 | K13: =J13*2.4/100+J13 -> 0 | L13: =H13-J13 -> 0 | M13: =L13*2.4/100+L13 -> 0
A14: 11 | D14: ='9'!L14 -> 0 | E14: =D14*2.4/100+D14 -> 0 | G14: =F14*2.4/100+F14 -> 0 | H14: =F14+D14 -> 0 | I14: =G14+E14 -> 0 | K14: =J14*2.4/100+J14 -> 0 | L14: =H14-J14 -> 0 | M14: =L14*2.4/100+L14 -> 0
A15: 12 | D15: ='9'!L15 -> 0 | E15: =D15*2.4/100+D15 -> 0 | G15: =F15*2.4/100+F15 -> 0 | H15: =F15+D15 -> 0 | I15: =G15+E15 -> 0 | K15: =J15*2.4/100+J15 -> 0 | L15: =H15-J15 -> 0 | M15: =L15*2.4/100+L15 -> 0
A16: 13 | D16: ='9'!L16 -> 0 | E16: =D16*2.4/100+D16 -> 0 | G16: =F16*2.4/100+F16 -> 0 | H16: =F16+D16 -> 0 | I16: =G16+E16 -> 0 | K16: =J16*2.4/100+J16 -> 0 | L16: =H16-J16 -> 0 | M16: =L16*2.4/100+L16 -> 0
A17: 14 | B17: OFFICE | C17: 3027107343 | D17: ='9'!L17 -> 0 | E17: =D17*2.4/100+D17 -> 0 | G17: =F17*2.4/100+F17 -> 0 | H17: =F17+D17 -> 0 | I17: =G17+E17 -> 0 | K17: =J17*2.4/100+J17 -> 0 | L17: =H17-J17 -> 0 | M17: =L17*2.4/100+L17 -> 0
A18: TOTAL | D18: =SUM(D4:D17) -> 51000 | E18: =SUM(E4:E17) -> 52224 | F18: =SUM(F4:F17) -> 0 | G18: =SUM(G4:G17) -> 0 | H18: =SUM(H4:H17) -> 51000 | I18: =SUM(I4:I17) -> 52224 | J18: =SUM(J4:J17) -> 0 | K18: =SUM(K4:K17) -> 0 | ... M18: =SUM(M4:M17) -> 52224 | N18: =K18*2.4/100 -> 0 | O18: =K18-N18 -> 0 | P18: =J18-O18 -> 0
A22: Opening Balance | C22: 1st ML Lifting | D22: 2nd ML Lifting | F22: Total Balance | H22: Today ML Issuance | J22: In Hand Balance
A23: ='9'!L23 -> 919682.04 | F23: =D23+C23+A23 -> 919682.04 | H23: =G18 -> 0 | J23: =F23-H23 -> 919682.04 | L23: =J23 -> 919682.04
K25: Commission 1 (2.4) | M25: =P18 -> 0
K26: Commission 2 (1.16) | M26: =J18*1.16/100 -> 0
K27: Total Day Commission | M27: =M26+M25 -> 0

Sheet 11
D2: Opening Balance | F2: Today ML Issuance | H2: Day Total | J2: Payment Received | L2: CLOSING BALANCE
A3: S.No | B3: Do Name | C3: Do Line | D3: Amount | E3: ML | F3: Amount | G3: ML Issue | H3: Cash Receiveable | I3: ML | J3: Cash Received | K3: ML | L3: Cash Receiveable | M3: ML
A4: 1 | B4: RIZWAN | C4: 3017211475 | D4: ='10'!L4 -> 0 | E4: =D4*2.4/100+D4 -> 0 | G4: =F4*2.4/100+F4 -> 0 | H4: =F4+D4 -> 0 | I4: =G4+E4 -> 0 | K4: =J4*2.4/100+J4 -> 0 | L4: =H4-J4 -> 0 | M4: =L4*2.4/100+L4 -> 0
A5: 2 | B5: MIRZA | C5: 3051639672 | D5: ='10'!L5 -> 50000 | E5: =D5*2.4/100+D5 -> 51200 | G5: =F5*2.4/100+F5 -> 0 | H5: =F5+D5 -> 50000 | I5: =G5+E5 -> 51200 | K5: =J5*2.4/100+J5 -> 0 | L5: =H5-J5 -> 50000 | M5: =L5*2.4/100+L5 -> 51200
A6: 3 | B6: ADNAN | C6: 3017211714 | D6: ='10'!L6 -> 0 | E6: =D6*2.4/100+D6 -> 0 | G6: =F6*2.4/100+F6 -> 0 | H6: =F6+D6 -> 0 | I6: =G6+E6 -> 0 | K6: =J6*2.4/100+J6 -> 0 | L6: =H6-J6 -> 0 | M6: =L6*2.4/100+L6 -> 0
A7: 4 | B7: ARSLAN | C7: 3027100125 | D7: ='10'!L7 -> 0 | E7: =D7*2.4/100+D7 -> 0 | G7: =F7*2.4/100+F7 -> 0 | H7: =F7+D7 -> 0 | I7: =G7+E7 -> 0 | K7: =J7*2.4/100+J7 -> 0 | L7: =H7-J7 -> 0 | M7: =L7*2.4/100+L7 -> 0
A8: 5 | B8: MUBASHAR | C8: 3027100126 | D8: ='10'!L8 -> 0 | E8: =D8*2.4/100+D8 -> 0 | G8: =F8*2.4/100+F8 -> 0 | H8: =F8+D8 -> 0 | I8: =G8+E8 -> 0 | K8: =J8*2.4/100+J8 -> 0 | L8: =H8-J8 -> 0 | M8: =L8*2.4/100+L8 -> 0
A9: 6 | B9: IRFAN MIRZA | C9: 3027103467 | D9: ='10'!L9 -> 0 | E9: =D9*2.4/100+D9 -> 0 | G9: =F9*2.4/100+F9 -> 0 | H9: =F9+D9 -> 0 | I9: =G9+E9 -> 0 | K9: =J9*2.4/100+J9 -> 0 | L9: =H9-J9 -> 0 | M9: =L9*2.4/100+L9 -> 0
A10: 7 | B10: HASSAN | C10: 3027103468 | D10: ='10'!L10 -> 0 | E10: =D10*2.4/100+D10 -> 0 | G10: =F10*2.4/100+F10 -> 0 | H10: =F10+D10 -> 0 | I10: =G10+E10 -> 0 | K10: =J10*2.4/100+J10 -> 0 | L10: =H10-J10 -> 0 | M10: =L10*2.4/100+L10 -> 0
A11: 8 | B11: NAVEED | C11: 3030963707 | D11: ='10'!L11 -> 1000 | E11: =D11*2.4/100+D11 -> 1024 | G11: =F11*2.4/100+F11 -> 0 | H11: =F11+D11 -> 1000 | I11: =G11+E11 -> 1024 | K11: =J11*2.4/100+J11 -> 0 | L11: =H11-J11 -> 1000 | M11: =L11*2.4/100+L11 -> 1024
A12: 9 | B12: IRFAN | C12: 3030964504 | D12: ='10'!L12 -> 0 | E12: =D12*2.4/100+D12 -> 0 | G12: =F12*2.4/100+F12 -> 0 | H12: =F12+D12 -> 0 | I12: =G12+E12 -> 0 | K12: =J12*2.4/100+J12 -> 0 | L12: =H12-J12 -> 0 | M12: =L12*2.4/100+L12 -> 0
A13: 10 | D13: ='10'!L13 -> 0 | E13: =D13*2.4/100+D13 -> 0 | G13: =F13*2.4/100+F13 -> 0 | H13: =F13+D13 -> 0 | I13: =G13+E13 -> 0 | K13: =J13*2.4/100+J13 -> 0 | L13: =H13-J13 -> 0 | M13: =L13*2.4/100+L13 -> 0
A14: 11 | D14: ='10'!L14 -> 0 | E14: =D14*2.4/100+D14 -> 0 | G14: =F14*2.4/100+F14 -> 0 | H14: =F14+D14 -> 0 | I14: =G14+E14 -> 0 | K14: =J14*2.4/100+J14 -> 0 | L14: =H14-J14 -> 0 | M14: =L14*2.4/100+L14 -> 0
A15: 12 | D15: ='10'!L15 -> 0 | E15: =D15*2.4/100+D15 -> 0 | G15: =F15*2.4/100+F15 -> 0 | H15: =F15+D15 -> 0 | I15: =G15+E15 -> 0 | K15: =J15*2.4/100+J15 -> 0 | L15: =H15-J15 -> 0 | M15: =L15*2.4/100+L15 -> 0
A16: 13 | D16: ='10'!L16 -> 0 | E16: =D16*2.4/100+D16 -> 0 | G16: =F16*2.4/100+F16 -> 0 | H16: =F16+D16 -> 0 | I16: =G16+E16 -> 0 | K16: =J16*2.4/100+J16 -> 0 | L16: =H16-J16 -> 0 | M16: =L16*2.4/100+L16 -> 0
A17: 14 | B17: OFFICE | C17: 3027107343 | D17: ='10'!L17 -> 0 | E17: =D17*2.4/100+D17 -> 0 | G17: =F17*2.4/100+F17 -> 0 | H17: =F17+D17 -> 0 | I17: =G17+E17 -> 0 | K17: =J17*2.4/100+J17 -> 0 | L17: =H17-J17 -> 0 | M17: =L17*2.4/100+L17 -> 0
A18: TOTAL | D18: =SUM(D4:D17) -> 51000 | E18: =SUM(E4:E17) -> 52224 | F18: =SUM(F4:F17) -> 0 | G18: =SUM(G4:G17) -> 0 | H18: =SUM(H4:H17) -> 51000 | I18: =SUM(I4:I17) -> 52224 | J18: =SUM(J4:J17) -> 0 | K18: =SUM(K4:K17) -> 0 | ... M18: =SUM(M4:M17) -> 52224 | N18: =K18*2.4/100 -> 0 | O18: =K18-N18 -> 0 | P18: =J18-O18 -> 0
A22: Opening Balance | C22: 1st ML Lifting | D22: 2nd ML Lifting | F22: Total Balance | H22: Today ML Issuance | J22: In Hand Balance
A23: ='10'!L23 -> 919682.04 | F23: =D23+C23+A23 -> 919682.04 | H23: =G18 -> 0 | J23: =F23-H23 -> 919682.04 | L23: =J23 -> 919682.04
K25: Commission 1 (2.4) | M25: =P18 -> 0
K26: Commission 2 (1.196) | M26: =J18*1.16/100 -> 0
K27: Total Day Commission | M27: =M26+M25 -> 0

Sheet 12
D2: Opening Balance | F2: Today ML Issuance | H2: Day Total | J2: Payment Received | L2: CLOSING BALANCE
A3: S.No | B3: Do Name | C3: Do Line | D3: Amount | E3: ML | F3: Amount | G3: ML Issue | H3: Cash Receiveable | I3: ML | J3: Cash Received | K3: ML | L3: Cash Receiveable | M3: ML
A4: 1 | B4: RIZWAN | C4: 3017211475 | D4: ='11'!L4 -> 0 | E4: =D4*2.4/100+D4 -> 0 | G4: =F4*2.4/100+F4 -> 0 | H4: =F4+D4 -> 0 | I4: =G4+E4 -> 0 | K4: =J4*2.4/100+J4 -> 0 | L4: =H4-J4 -> 0 | M4: =L4*2.4/100+L4 -> 0
A5: 2 | B5: MIRZA | C5: 3051639672 | D5: ='11'!L5 -> 50000 | E5: =D5*2.4/100+D5 -> 51200 | G5: =F5*2.4/100+F5 -> 0 | H5: =F5+D5 -> 50000 | I5: =G5+E5 -> 51200 | K5: =J5*2.4/100+J5 -> 0 | L5: =H5-J5 -> 50000 | M5: =L5*2.4/100+L5 -> 51200
A6: 3 | B6: ADNAN | C6: 3017211714 | D6: ='11'!L6 -> 0 | E6: =D6*2.4/100+D6 -> 0 | G6: =F6*2.4/100+F6 -> 0 | H6: =F6+D6 -> 0 | I6: =G6+E6 -> 0 | K6: =J6*2.4/100+J6 -> 0 | L6: =H6-J6 -> 0 | M6: =L6*2.4/100+L6 -> 0
A7: 4 | B7: ARSLAN | C7: 3027100125 | D7: ='11'!L7 -> 0 | E7: =D7*2.4/100+D7 -> 0 | G7: =F7*2.4/100+F7 -> 0 | H7: =F7+D7 -> 0 | I7: =G7+E7 -> 0 | K7: =J7*2.4/100+J7 -> 0 | L7: =H7-J7 -> 0 | M7: =L7*2.4/100+L7 -> 0
A8: 5 | B8: MUBASHAR | C8: 3027100126 | D8: ='11'!L8 -> 0 | E8: =D8*2.4/100+D8 -> 0 | G8: =F8*2.4/100+F8 -> 0 | H8: =F8+D8 -> 0 | I8: =G8+E8 -> 0 | K8: =J8*2.4/100+J8 -> 0 | L8: =H8-J8 -> 0 | M8: =L8*2.4/100+L8 -> 0
A9: 6 | B9: IRFAN MIRZA | C9: 3027103467 | D9: ='11'!L9 -> 0 | E9: =D9*2.4/100+D9 -> 0 | G9: =F9*2.4/100+F9 -> 0 | H9: =F9+D9 -> 0 | I9: =G9+E9 -> 0 | K9: =J9*2.4/100+J9 -> 0 | L9: =H9-J9 -> 0 | M9: =L9*2.4/100+L9 -> 0
A10: 7 | B10: HASSAN | C10: 3027103468 | D10: ='11'!L10 -> 0 | E10: =D10*2.4/100+D10 -> 0 | G10: =F10*2.4/100+F10 -> 0 | H10: =F10+D10 -> 0 | I10: =G10+E10 -> 0 | K10: =J10*2.4/100+J10 -> 0 | L10: =H10-J10 -> 0 | M10: =L10*2.4/100+L10 -> 0
A11: 8 | B11: NAVEED | C11: 3030963707 | D11: ='11'!L11 -> 1000 | E11: =D11*2.4/100+D11 -> 1024 | G11: =F11*2.4/100+F11 -> 0 | H11: =F11+D11 -> 1000 | I11: =G11+E11 -> 1024 | K11: =J11*2.4/100+J11 -> 0 | L11: =H11-J11 -> 1000 | M11: =L11*2.4/100+L11 -> 1024
A12: 9 | B12: IRFAN | C12: 3030964504 | D12: ='11'!L12 -> 0 | E12: =D12*2.4/100+D12 -> 0 | G12: =F12*2.4/100+F12 -> 0 | H12: =F12+D12 -> 0 | I12: =G12+E12 -> 0 | K12: =J12*2.4/100+J12 -> 0 | L12: =H12-J12 -> 0 | M12: =L12*2.4/100+L12 -> 0
A13: 10 | D13: ='11'!L13 -> 0 | E13: =D13*2.4/100+D13 -> 0 | G13: =F13*2.4/100+F13 -> 0 | H13: =F13+D13 -> 0 | I13: =G13+E13 -> 0 | K13: =J13*2.4/100+J13 -> 0 | L13: =H13-J13 -> 0 | M13: =L13*2.4/100+L13 -> 0
A14: 11 | D14: ='11'!L14 -> 0 | E14: =D14*2.4/100+D14 -> 0 | G14: =F14*2.4/100+F14 -> 0 | H14: =F14+D14 -> 0 | I14: =G14+E14 -> 0 | K14: =J14*2.4/100+J14 -> 0 | L14: =H14-J14 -> 0 | M14: =L14*2.4/100+L14 -> 0
A15: 12 | D15: ='11'!L15 -> 0 | E15: =D15*2.4/100+D15 -> 0 | G15: =F15*2.4/100+F15 -> 0 | H15: =F15+D15 -> 0 | I15: =G15+E15 -> 0 | K15: =J15*2.4/100+J15 -> 0 | L15: =H15-J15 -> 0 | M15: =L15*2.4/100+L15 -> 0
A16: 13 | D16: ='11'!L16 -> 0 | E16: =D16*2.4/100+D16 -> 0 | G16: =F16*2.4/100+F16 -> 0 | H16: =F16+D16 -> 0 | I16: =G16+E16 -> 0 | K16: =J16*2.4/100+J16 -> 0 | L16: =H16-J16 -> 0 | M16: =L16*2.4/100+L16 -> 0
A17: 14 | B17: OFFICE | C17: 3027107343 | D17: ='11'!L17 -> 0 | E17: =D17*2.4/100+D17 -> 0 | G17: =F17*2.4/100+F17 -> 0 | H17: =F17+D17 -> 0 | I17: =G17+E17 -> 0 | K17: =J17*2.4/100+J17 -> 0 | L17: =H17-J17 -> 0 | M17: =L17*2.4/100+L17 -> 0
A18: TOTAL | D18: =SUM(D4:D17) -> 51000 | E18: =SUM(E4:E17) -> 52224 | F18: =SUM(F4:F17) -> 0 | G18: =SUM(G4:G17) -> 0 | H18: =SUM(H4:H17) -> 51000 | I18: =SUM(I4:I17) -> 52224 | J18: =SUM(J4:J17) -> 0 | K18: =SUM(K4:K17) -> 0 | ... M18: =SUM(M4:M17) -> 52224 | N18: =K18*2.4/100 -> 0 | O18: =K18-N18 -> 0 | P18: =J18-O18 -> 0
A22: Opening Balance | C22: 1st ML Lifting | D22: 2nd ML Lifting | F22: Total Balance | H22: Today ML Issuance | J22: In Hand Balance
A23: ='11'!L23 -> 919682.04 | F23: =D23+C23+A23 -> 919682.04 | H23: =G18 -> 0 | J23: =F23-H23 -> 919682.04 | L23: =J23 -> 919682.04
K25: Commission 1 (2.4) | M25: =P18 -> 0
K26: Commission 2 (1.16) | M26: =J18*1.16/100 -> 0
K27: Total Day Commission | M27: =M26+M25 -> 0

Sheet 13
D2: Opening Balance | F2: Today ML Issuance | H2: Day Total | J2: Payment Received | L2: CLOSING BALANCE
A3: S.No | B3: Do Name | C3: Do Line | D3: Amount | E3: ML | F3: Amount | G3: ML Issue | H3: Cash Receiveable | I3: ML | J3: Cash Received | K3: ML | L3: Cash Receiveable | M3: ML
A4: 1 | B4: RIZWAN | C4: 3017211475 | D4: ='12'!L4 -> 0 | E4: =D4*2.4/100+D4 -> 0 | G4: =F4*2.4/100+F4 -> 0 | H4: =F4+D4 -> 0 | I4: =G4+E4 -> 0 | K4: =J4*2.4/100+J4 -> 0 | L4: =H4-J4 -> 0 | M4: =L4*2.4/100+L4 -> 0
A5: 2 | B5: MIRZA | C5: 3051639672 | D5: ='12'!L5 -> 50000 | E5: =D5*2.4/100+D5 -> 51200 | G5: =F5*2.4/100+F5 -> 0 | H5: =F5+D5 -> 50000 | I5: =G5+E5 -> 51200 | K5: =J5*2.4/100+J5 -> 0 | L5: =H5-J5 -> 50000 | M5: =L5*2.4/100+L5 -> 51200
A6: 3 | B6: ADNAN | C6: 3017211714 | D6: ='12'!L6 -> 0 | E6: =D6*2.4/100+D6 -> 0 | G6: =F6*2.4/100+F6 -> 0 | H6: =F6+D6 -> 0 | I6: =G6+E6 -> 0 | K6: =J6*2.4/100+J6 -> 0 | L6: =H6-J6 -> 0 | M6: =L6*2.4/100+L6 -> 0
A7: 4 | B7: ARSLAN | C7: 3027100125 | D7: ='12'!L7 -> 0 | E7: =D7*2.4/100+D7 -> 0 | G7: =F7*2.4/100+F7 -> 0 | H7: =F7+D7 -> 0 | I7: =G7+E7 -> 0 | K7: =J7*2.4/100+J7 -> 0 | L7: =H7-J7 -> 0 | M7: =L7*2.4/100+L7 -> 0
A8: 5 | B8: MUBASHAR | C8: 3027100126 | D8: ='12'!L8 -> 0 | E8: =D8*2.4/100+D8 -> 0 | G8: =F8*2.4/100+F8 -> 0 | H8: =F8+D8 -> 0 | I8: =G8+E8 -> 0 | K8: =J8*2.4/100+J8 -> 0 | L8: =H8-J8 -> 0 | M8: =L8*2.4/100+L8 -> 0
A9: 6 | B9: IRFAN MIRZA | C9: 3027103467 | D9: ='12'!L9 -> 0 | E9: =D9*2.4/100+D9 -> 0 | G9: =F9*2.4/100+F9 -> 0 | H9: =F9+D9 -> 0 | I9: =G9+E9 -> 0 | K9: =J9*2.4/100+J9 -> 0 | L9: =H9-J9 -> 0 | M9: =L9*2.4/100+L9 -> 0
A10: 7 | B10: HASSAN | C10: 3027103468 | D10: ='12'!L10 -> 0 | E10: =D10*2.4/100+D10 -> 0 | G10: =F10*2.4/100+F10 -> 0 | H10: =F10+D10 -> 0 | I10: =G10+E10 -> 0 | K10: =J10*2.4/100+J10 -> 0 | L10: =H10-J10 -> 0 | M10: =L10*2.4/100+L10 -> 0
A11: 8 | B11: NAVEED | C11: 3030963707 | D11: ='12'!L11 -> 1000 | E11: =D11*2.4/100+D11 -> 1024 | G11: =F11*2.4/100+F11 -> 0 | H11: =F11+D11 -> 1000 | I11: =G11+E11 -> 1024 | K11: =J11*2.4/100+J11 -> 0 | L11: =H11-J11 -> 1000 | M11: =L11*2.4/100+L11 -> 1024
A12: 9 | B12: IRFAN | C12: 3030964504 | D12: ='12'!L12 -> 0 | E12: =D12*2.4/100+D12 -> 0 | G12: =F12*2.4/100+F12 -> 0 | H12: =F12+D12 -> 0 | I12: =G12+E12 -> 0 | K12: =J12*2.4/100+J12 -> 0 | L12: =H12-J12 -> 0 | M12: =L12*2.4/100+L12 -> 0
A13: 10 | D13: ='12'!L13 -> 0 | E13: =D13*2.4/100+D13 -> 0 | G13: =F13*2.4/100+F13 -> 0 | H13: =F13+D13 -> 0 | I13: =G13+E13 -> 0 | K13: =J13*2.4/100+J13 -> 0 | L13: =H13-J13 -> 0 | M13: =L13*2.4/100+L13 -> 0
A14: 11 | D14: ='12'!L14 -> 0 | E14: =D14*2.4/100+D14 -> 0 | G14: =F14*2.4/100+F14 -> 0 | H14: =F14+D14 -> 0 | I14: =G14+E14 -> 0 | K14: =J14*2.4/100+J14 -> 0 | L14: =H14-J14 -> 0 | M14: =L14*2.4/100+L14 -> 0
A15: 12 | D15: ='12'!L15 -> 0 | E15: =D15*2.4/100+D15 -> 0 | G15: =F15*2.4/100+F15 -> 0 | H15: =F15+D15 -> 0 | I15: =G15+E15 -> 0 | K15: =J15*2.4/100+J15 -> 0 | L15: =H15-J15 -> 0 | M15: =L15*2.4/100+L15 -> 0
A16: 13 | D16: ='12'!L16 -> 0 | E16: =D16*2.4/100+D16 -> 0 | G16: =F16*2.4/100+F16 -> 0 | H16: =F16+D16 -> 0 | I16: =G16+E16 -> 0 | K16: =J16*2.4/100+J16 -> 0 | L16: =H16-J16 -> 0 | M16: =L16*2.4/100+L16 -> 0
A17: 14 | B17: OFFICE | C17: 3027107343 | D17: ='12'!L17 -> 0 | E17: =D17*2.4/100+D17 -> 0 | G17: =F17*2.4/100+F17 -> 0 | H17: =F17+D17 -> 0 | I17: =G17+E17 -> 0 | K17: =J17*2.4/100+J17 -> 0 | L17: =H17-J17 -> 0 | M17: =L17*2.4/100+L17 -> 0
