Workbook

Sheet Summary
A1: ACCOUNT SUMMARY | B1: STOCK ISSUANCE | M1: Account Summary
B2: 280 | C2: 350 | D2: 1000 | E2: 500 | F2: 2000 | G2: 7400 | H2: 5350 | I2: 2100 | J2: 390 | K2: 280 | L2: 390 | M2: Total Qty | N2: Total Amount | O2: Payment Received | P2: Due Balance
B3: RETAILER | C3: FRANCHISE | D3: LOAD SIM | E3: MBB SIM | F3: E SIM | G3: Shine Mobile | H3: MOBILE | I3: WINGLE | J3: Gold Number | K3: RETAIL IMZI | L3: CS IMZI
A4: DO RIZWAN | B4: ='NAVEED BANGLA '!B25 -> 0 | C4: ='NAVEED BANGLA '!C25 -> 0 | D4: ='NAVEED BANGLA '!D25 -> 0 | E4: ='NAVEED BANGLA '!E25 -> 0 | F4: ='NAVEED BANGLA '!F25 -> 0 | G4: ='NAVEED BANGLA '!G25 -> 0 | H4: ='NAVEED BANGLA '!H25 -> 0 | I4: ='NAVEED BANGLA '!I25 -> 0 | ... L4: ='NAVEED BANGLA '!L25 -> 0 | M4: =SUM(B4:L4) -> 0 | N4: =L4*L2+K4*K2+J4*J2+I4*I2+H4*H2+G4*G2+F4*F2+E4*E2+D4*D2+C4*C2+B4*B2 -> 0 | O4: ='NAVEED BANGLA '!V25 -> 0 | P4: ='NAVEED BANGLA '!W25 -> 0
A5: DO MIRZA | B5: =MIRZA!B25 -> 0 | C5: =MIRZA!C25 -> 0 | D5: =MIRZA!D25 -> 0 | E5: =MIRZA!E25 -> 0 | F5: =MIRZA!F25 -> 0 | G5: =MIRZA!G25 -> 0 | H5: =MIRZA!H25 -> 0 | I5: =MIRZA!I25 -> 0 | ... L5: =MIRZA!L25 -> 0 | M5: =SUM(B5:L5) -> 0 | N5: =L5*L2+K5*K2+J5*J2+I5*I2+H5*H2+G5*G2+F5*F2+E5*E2+D5*D2+C5*C2+B5*B2 -> 0 | O5: =MIRZA!V25 -> 0 | P5: =MIRZA!W25 -> 56592
A6: DO ADNAN | B6: =ADNAN!B25 -> 0 | C6: =ADNAN!C25 -> 0 | D6: =ADNAN!D25 -> 0 | E6: =ADNAN!E25 -> 0 | F6: =ADNAN!F25 -> 0 | G6: =ADNAN!G25 -> 0 | H6: =ADNAN!H25 -> 0 | I6: =ADNAN!I25 -> 0 | ... L6: =ADNAN!L25 -> 0 | M6: =SUM(B6:L6) -> 0 | N6: =L6*L2+K6*K2+J6*J2+I6*I2+H6*H2+G6*G2+F6*F2+E6*E2+D6*D2+C6*C2+B6*B2 -> 0 | O6: =ADNAN!V25 -> 0 | P6: =ADNAN!W25 -> 0
A7: DO ARSLAN | B7: =ARSLAN!B25 -> 0 | C7: =ARSLAN!C25 -> 0 | D7: =ARSLAN!D25 -> 0 | E7: =ARSLAN!E25 -> 0 | F7: =ARSLAN!F25 -> 0 | G7: =ARSLAN!G25 -> 0 | H7: =ARSLAN!H25 -> 0 | I7: =ARSLAN!I25 -> 0 | ... L7: =ARSLAN!L25 -> 0 | M7: =SUM(B7:L7) -> 100 | N7: =L7*L2+K7*K2+J7*J2+I7*I2+H7*H2+G7*G2+F7*F2+E7*E2+D7*D2+C7*C2+B7*B2 -> 28000 | O7: =ARSLAN!V25 -> 0 | P7: =ARSLAN!W25 -> 87015
A8: DO MUBASHAR | B8: ='Mubashar '!B25 -> 100 | C8: ='Mubashar '!C25 -> 0 | D8: ='Mubashar '!D25 -> 0 | E8: ='Mubashar '!E25 -> 0 | F8: ='Mubashar '!F25 -> 0 | G8: ='Mubashar '!G25 -> 0 | H8: ='Mubashar '!H25 -> 0 | I8: ='Mubashar '!I25 -> 0 | ... L8: ='Mubashar '!L25 -> 0 | M8: =SUM(B8:L8) -> 100 | N8: =L8*L2+K8*K2+J8*J2+I8*I2+H8*H2+G8*G2+F8*F2+E8*E2+D8*D2+C8*C2+B8*B2 -> 28000 | O8: ='Mubashar '!V25 -> 0 | P8: ='Mubashar '!W25 -> 86240
A9: Do Mirza irfan | B9: ='NEW IRFAN '!B25 -> 40 | C9: ='NEW IRFAN '!C25 -> 0 | D9: ='NEW IRFAN '!D25 -> 0 | E9: ='NEW IRFAN '!E25 -> 0 | F9: ='NEW IRFAN '!F25 -> 0 | G9: ='NEW IRFAN '!G25 -> 0 | H9: ='NEW IRFAN '!H25 -> 0 | I9: ='NEW IRFAN '!I25 -> 0 | ... L9: ='NEW IRFAN '!L25 -> 0 | M9: =SUM(B9:L9) -> 60 | N9: =L9*L2+K9*K2+J9*J2+I9*I2+H9*H2+G9*G2+F9*F2+E9*E2+D9*D2+C9*C2+B9*B2 -> 16800 | O9: ='NEW IRFAN '!V25 -> 0 | P9: ='NEW IRFAN '!W25 -> 53760
A10: DO HASSAN | B10: =HASSAN!B25 -> 0 | C10: =NAVEED!C25 -> 0 | D10: =NAVEED!D25 -> 0 | E10: =NAVEED!E25 -> 0 | F10: =NAVEED!F25 -> 0 | G10: =NAVEED!G25 -> 0 | H10: =NAVEED!H25 -> 0 | I10: =NAVEED!I25 -> 0 | J10: =NAVEED!J25 -> 0 | K10: =HASSAN!K25 -> 0 | L10: =NAVEED!L25 -> 0 | M10: =SUM(B10:L10) -> 0 | N10: =L10*L2+K10*K2+J10*J2+I10*I2+H10*H2+G10*G2+F10*F2+E10*E2+D10*D2+C10*C2+B10*B2 -> 0 | O10: ='NEW IRFAN '!V26 -> 0 | P10: =HASSAN!W25 -> 21000
A11: DO NAVEED | B11: =NAVEED!B25 -> 100 | C11: =HASSAN!C25 -> 0 | D11: =HASSAN!D25 -> 0 | E11: =HASSAN!E25 -> 0 | F11: =HASSAN!F25 -> 0 | G11: =HASSAN!G25 -> 0 | H11: =HASSAN!H25 -> 0 | I11: =HASSAN!I25 -> 0 | J11: =HASSAN!J25 -> 0 | K11: =NAVEED!K25 -> 100 | L11: =HASSAN!L25 -> 0 | M11: =SUM(B11:L11) -> 200 | N11: =L11*L2+K11*K2+J11*J2+I11*I2+H11*H2+G11*G2+F11*F2+E11*E2+D11*D2+C11*C2+B11*B2 -> 56000 | O11: =HASSAN!V25 -> 0 | P11: =NAVEED!W25 -> 171670
A12: DO IRFAN | B12: =IRFAN!B25 -> 0 | C12: =IRFAN!C25 -> 0 | D12: =IRFAN!D25 -> 0 | E12: =IRFAN!E25 -> 0 | F12: =IRFAN!F25 -> 0 | G12: =IRFAN!G25 -> 0 | H12: =IRFAN!H25 -> 0 | I12: =IRFAN!I25 -> 0 | ... L12: =IRFAN!L25 -> 0 | M12: =SUM(B12:L12) -> 0 | N12: =L12*L2+K12*K2+J12*J2+I12*I2+H12*H2+G12*G2+F12*F2+E12*E2+D12*D2+C12*C2+B12*B2 -> 0 | O12: =IRFAN!V25 -> 0 | P12: =IRFAN!W25 -> 40560
A13: DSO | B13: ='DSO NADEEM '!B25 -> 0 | C13: ='DSO NADEEM '!C25 -> 0 | D13: ='DSO NADEEM '!D25 -> 0 | E13: ='DSO NADEEM '!E25 -> 0 | F13: ='DSO NADEEM '!F25 -> 0 | G13: ='DSO NADEEM '!G25 -> 0 | H13: ='DSO NADEEM '!H25 -> 0 | I13: ='DSO NADEEM '!I25 -> 0 | ... L13: ='DSO NADEEM '!L25 -> 0 | M13: =SUM(B13:L13) -> 0 | N13: =L13*L2+K13*K2+J13*J2+I13*I2+H13*H2+G13*G2+F13*F2+E13*E2+D13*D2+C13*C2+B13*B2 -> 0 | O13: ='DSO NADEEM '!V25 -> 0 | P13: ='DSO NADEEM '!W25 -> 0
A14: DSO HASAN | B14: ='DSO HASAN'!B25 -> 40 | C14: ='DSO HASAN'!C25 -> 0 | D14: ='DSO HASAN'!D25 -> 0 | E14: ='DSO HASAN'!E25 -> 0 | F14: ='DSO HASAN'!F25 -> 0 | G14: ='DSO HASAN'!G25 -> 0 | H14: ='DSO HASAN'!H25 -> 0 | I14: ='DSO HASAN'!I25 -> 0 | ... L14: ='DSO HASAN'!L25 -> 0 | M14: =SUM(B14:L14) -> 60 | N14: =L14*L2+K14*K2+J14*J2+I14*I2+H14*H2+G14*G2+F14*F2+E14*E2+D14*D2+C14*C2+B14*B2 -> 16800 | O14: ='DSO HASAN'!V25 -> 0 | P14: ='DSO HASAN'!W25 -> 129920
A15: DSO | B15: ='DSO 2 '!B25 -> 0 | C15: ='DSO 2 '!C25 -> 0 | D15: ='DSO 2 '!D25 -> 0 | E15: ='DSO 2 '!E25 -> 0 | F15: ='DSO 2 '!F25 -> 0 | G15: ='DSO 2 '!G25 -> 0 | H15: ='DSO 2 '!H25 -> 0 | I15: ='DSO 2 '!I25 -> 0 | ... L15: ='DSO 2 '!L25 -> 0 | M15: =SUM(B15:L15) -> 0 | N15: =L15*L2+K15*K2+J15*J2+I15*I2+H15*H2+G15*G2+F15*F2+E15*E2+D15*D2+C15*C2+B15*B2 -> 0 | O15: ='DSO 2 '!V25 -> 0 | P15: ='DSO 2 '!W25 -> 0
A16: FREE SIM CCR | B16: ='SIM FREE '!B35 -> 0 | C16: ='SIM FREE '!C35 -> 0 | D16: ='SIM FREE '!D35 -> 0 | E16: ='SIM FREE '!E35 -> 0 | F16: ='SIM FREE '!F35 -> 0 | G16: ='SIM FREE '!G35 -> 0 | H16: ='SIM FREE '!H35 -> 0 | I16: ='SIM FREE '!I35 -> 0 | ... L16: ='SIM FREE '!L35 -> 0 | M16: =SUM(B16:L16) -> 0 | N16: =L16*L2+K16*K2+J16*J2+I16*I2+H16*H2+G16*G2+F16*F2+E16*E2+D16*D2+C16*C2+B16*B2 -> 0 | O16: ='SIM FREE '!V35 -> 0 | P16: ='SIM FREE '!W35 -> 29400
A17: HUSSAIN CCR | B17: ='CCR HUSSAIN'!B35 -> 0 | C17: ='CCR HUSSAIN'!C35 -> 0 | D17: ='CCR HUSSAIN'!D35 -> 0 | E17: ='CCR HUSSAIN'!E35 -> 0 | F17: ='CCR HUSSAIN'!F35 -> 0 | G17: ='CCR HUSSAIN'!G35 -> 0 | H17: ='CCR HUSSAIN'!H35 -> 0 | I17: ='CCR HUSSAIN'!I35 -> 0 | ... L17: ='CCR HUSSAIN'!L35 -> 13 | M17: =SUM(B17:L17) -> 14 | N17: =L17*L2+K17*K2+J17*J2+I17*I2+H17*H2+G17*G2+F17*F2+E17*E2+D17*D2+C17*C2+B17*B2 -> 5460 | O17: ='CCR HUSSAIN'!V35 -> 5460 | P17: ='CCR HUSSAIN'!W35 -> 22800
A18: SARAM CCR | B18: ='SARAM CS'!B35 -> 0 | C18: ='SARAM CS'!C35 -> 0 | D18: ='SARAM CS'!D35 -> 0 | E18: ='SARAM CS'!E35 -> 0 | F18: ='SARAM CS'!F35 -> 0 | G18: ='SARAM CS'!G35 -> 0 | H18: ='SARAM CS'!H35 -> 0 | I18: ='SARAM CS'!I35 -> 0 | ... L18: ='SARAM CS'!L35 -> 0 | M18: =SUM(B18:L18) -> 0 | N18: =L18*L2+K18*K2+J18*J2+I18*I2+H18*H2+G18*G2+F18*F2+E18*E2+D18*D2+C18*C2+B18*B2 -> 0 | O18: ='SARAM CS'!V35 -> 0 | P18: ='SARAM CS'!W35 -> 12800
A19: ANNI CCR | B19: ='ANNIE CCR'!B34 -> 0 | C19: ='ANNIE CCR'!C34 -> 19 | D19: ='ANNIE CCR'!D34 -> 0 | E19: ='ANNIE CCR'!E34 -> 0 | F19: ='ANNIE CCR'!F34 -> 0 | G19: ='ANNIE CCR'!G34 -> 0 | H19: ='ANNIE CCR'!H34 -> 0 | I19: ='ANNIE CCR'!I34 -> 0 | ... L19: ='ANNIE CCR'!L34 -> 1 | M19: =SUM(B19:L19) -> 21 | N19: =L19*L2+K19*K2+J19*J2+I19*I2+H19*H2+G19*G2+F19*F2+E19*E2+D19*D2+C19*C2+B19*B2 -> 7430 | O19: ='ANNIE CCR'!V34 -> 7430 | P19: ='ANNIE CCR'!W34 -> 41800
A20: WASEEM GUJJAR | B20: ='WASEEM GUJJAR'!B25 -> 0 | C20: ='WASEEM GUJJAR'!C25 -> 0 | D20: ='WASEEM GUJJAR'!D25 -> 0 | E20: ='WASEEM GUJJAR'!E25 -> 0 | F20: ='WASEEM GUJJAR'!F25 -> 0 | G20: ='WASEEM GUJJAR'!G25 -> 0 | H20: ='WASEEM GUJJAR'!H25 -> 0 | I20: ='WASEEM GUJJAR'!I25 -> 0 | ... L20: ='WASEEM GUJJAR'!L25 -> 0 | M20: =SUM(B20:L20) -> 0 | N20: =L20*L2+K20*K2+J20*J2+I20*I2+H20*H2+G20*G2+F20*F2+E20*E2+D20*D2+C20*C2+B20*B2 -> 0 | O20: ='WASEEM GUJJAR'!V25 -> 0 | P20: ='WASEEM GUJJAR'!W25 -> 3080
A21: DSO Abdullah | B21: ='ABDULLAH DSO '!B25 -> 0 | C21: ='ABDULLAH DSO '!C25 -> 0 | D21: ='ABDULLAH DSO '!D25 -> 0 | E21: ='ABDULLAH DSO '!E25 -> 0 | F21: ='ABDULLAH DSO '!F25 -> 0 | G21: ='ABDULLAH DSO '!G25 -> 0 | H21: ='ABDULLAH DSO '!H25 -> 0 | I21: ='ABDULLAH DSO '!I25 -> 0 | ... L21: ='ABDULLAH DSO '!L25 -> 0 | M21: =SUM(B21:L21) -> 0 | N21: =L21*L2+K21*K2+J21*J2+I21*I2+H21*H2+G21*G2+F21*F2+E21*E2+D21*D2+C21*C2+B21*B2 -> 0 | O21: ='ABDULLAH DSO '!V25 -> 0 | P21: ='ABDULLAH DSO '!W25 -> 20640
A22: DSO 4 | B22: ='DSO 1 '!B25 -> 0 | C22: ='DSO 1 '!C25 -> 0 | D22: ='DSO 1 '!D25 -> 0 | E22: ='DSO 1 '!E25 -> 0 | F22: ='DSO 1 '!F25 -> 0 | G22: ='DSO 1 '!G25 -> 0 | H22: ='DSO 1 '!H25 -> 0 | I22: ='DSO 1 '!I25 -> 0 | ... L22: ='DSO 1 '!L25 -> 0 | M22: =SUM(B22:L22) -> 0 | N22: =L22*L2+K22*K2+J22*J2+I22*I2+H22*H2+G22*G2+F22*F2+E22*E2+D22*D2+C22*C2+B22*B2 -> 0 | O22: ='DSO 1 '!V25 -> 0 | P22: ='DSO 1 '!W25 -> 0
A23: NET STOCK | B23: ='NET STOCK '!B25 -> 0 | C23: ='NET STOCK '!C25 -> 0 | D23: ='NET STOCK '!D25 -> 1 | E23: ='NET STOCK '!E25 -> 0 | F23: ='NET STOCK '!F25 -> 0 | G23: ='NET STOCK '!G25 -> 0 | H23: ='NET STOCK '!H25 -> 0 | I23: ='NET STOCK '!I25 -> 0 | ... L23: ='NET STOCK '!L25 -> 0 | M23: =SUM(B23:L23) -> 101 | N23: =L23*L2+K23*K2+J23*J2+I23*I2+H23*H2+G23*G2+F23*F2+E23*E2+D23*D2+C23*C2+B23*B2 -> 29000 | O23: ='NET STOCK '!V25 -> 1000 | P23: ='NET STOCK '!W25 -> 28000
A24: MOBILE STOCK | B24: ='MOBILE STOCK'!B25 -> 0 | C24: ='MOBILE STOCK'!C25 -> 0 | D24: ='MOBILE STOCK'!D25 -> 0 | E24: ='MOBILE STOCK'!E25 -> 0 | F24: ='MOBILE STOCK'!F25 -> 0 | G24: ='MOBILE STOCK'!G25 -> 0 | H24: ='MOBILE STOCK'!H25 -> 0 | I24: ='MOBILE STOCK'!I25 -> 0 | ... L24: ='MOBILE STOCK'!L25 -> 0 | M24: =SUM(B24:L24) -> 0 | N24: =L24*L2+K24*K2+J24*J2+I24*I2+H24*H2+G24*G2+F24*F2+E24*E2+D24*D2+C24*C2+B24*B2 -> 0 | O24: ='MOBILE STOCK'!V25 -> 0 | P24: ='MOBILE STOCK'!W25 -> 0
A25: DSO | B25: =DSO!B24 -> 0 | C25: ='MOBILE STOCK'!C26 -> 0 | D25: ='MOBILE STOCK'!D26 -> 0 | E25: ='MOBILE STOCK'!E26 -> 0 | F25: ='MOBILE STOCK'!F26 -> 0 | G25: ='MOBILE STOCK'!G26 -> 0 | H25: ='MOBILE STOCK'!H26 -> 0 | I25: ='MOBILE STOCK'!I26 -> 0 | J25: ='MOBILE STOCK'!J26 -> 0 | K25: =DSO!K24 -> 0 | L25: =DSO!L24 -> 0 | M25: =SUM(B25:L25) -> 0 | N25: =DSO!U24 -> 0 | O25: ='MOBILE STOCK'!V26 -> 0 | P25: =DSO!W24 -> 0
A26: G TOTAL | B26: =SUM(B4:B25) -> 280 | C26: =SUM(C4:C25) -> 19 | D26: =SUM(D4:D24) -> 1 | E26: =SUM(E4:E24) -> 0 | F26: =SUM(F4:F24) -> 0 | G26: =SUM(G4:G24) -> 0 | H26: =SUM(H4:H24) -> 0 | I26: =SUM(I4:I24) -> 0 | J26: =SUM(J4:J24) -> 2 | K26: =SUM(K4:K25) -> 340 | L26: =SUM(L4:L25) -> 14 | M26: =SUM(M4:M24) -> 656 | N26: =SUM(N4:N24) -> 187490 | O26: =SUM(O4:O24) -> 13890 | P26: =SUM(P4:P25) -> 805277
A28: DATE | B28: MONTHLY STOCK POSITION & VALUE
B29: 280 | C29: 350 | D29: 1000 | E29: 500 | F29: 2000 | G29: 7400 | H29: 5350 | I29: 2100 | J29: 390 | K29: 280 | L29: 390 | M29: TOTAL
B30: RETAILER | C30: FRANCHISE | D30: LOAD SIM | E30: MBB SIM | F30: E SIM | G30: Shine Mobile | H30: MOBILE | I30: WINGLE | J30: Gold Number | K30: RETAIL IMZI | L30: CS IMZI
A31: OPENING | B31: 1727 | C31: 466 | D31: 5 | F31: 16 | J31: 20 | K31: 1010 | L31: 210 | M31: =SUM(B31:L31) -> 3454
M32: =SUM(B32:L32) -> 0
M33: =SUM(B33:L33) -> 0
M34: =SUM(B34:L34) -> 0
M35: =SUM(B35:L35) -> 0
M36: =SUM(B36:L36) -> 0
M37: =SUM(B37:L37) -> 0
M38: =SUM(B38:L38) -> 0
M39: =SUM(B39:L39) -> 0
M40: =SUM(B40:L40) -> 0
M41: =SUM(B41:L41) -> 0
...

Sheet NAVEED BANGLA 
A1: Month January
A2: DO NAME | B2: STOCK ISSUANCE | O2: PAYMENT RECEIVED | U2: ACCOUNT BALANCE
A3: Date | B3: 280 | C3: 350 | D3: 1000 | E3: 500 | F3: 5000 | G3: 7400 | H3: 5350 | I3: 2100 | J3: 7000 | K3: 280 | L3: 390 | M3: Total Qty | N3: Total Amount | O3: Date | P3: PAYMENT RECEIVED | T3: Total Received | U3: Carry Forward
B4: RETAILER | C4: FRANCHISE | D4: LOAD SIM | E4: MBB SIM | F4: E SIM | G4: Shine Mobile | H4: MOBILE | I4: WINGLE | J4: DONGLE | K4: RETAIL IMZI | L4: CS IMZI | P4: SIM | Q4: IMZI | R4: DEVICES | S4: MOBILE | U4: Total Amount | V4: Payment | W4: Due Balance
M5: =SUM(B5:L5) -> 0 | N5: =L5*L3+K5*K3+J5*J3+I5*I3+H5*H3+G5*G3+F5*F3+E5*E3+D5*D3+C5*C3+B5*B3 -> 0 | T5: =P5+Q5+R5+S5 -> 0 | U5: =N5 -> 0 | V5: =T5 -> 0 | W5: =U5-V5 -> 0
M6: =SUM(B6:L6) -> 0 | N6: =L6*L3+K6*K3+J6*J3+I6*I3+H6*H3+G6*G3+F6*F3+E6*E3+D6*D3+C6*C3+B6*B3 -> 0 | T6: =P6+Q6+R6+S6 -> 0 | U6: =N6 -> 0 | V6: =T6 -> 0 | W6: =U6-V6 -> 0
M7: =SUM(B7:L7) -> 0 | N7: =L7*L3+K7*K3+J7*J3+I7*I3+H7*H3+G7*G3+F7*F3+E7*E3+D7*D3+C7*C3+B7*B3 -> 0 | T7: =P7+Q7+R7+S7 -> 0 | U7: =N7 -> 0 | V7: =T7 -> 0 | W7: =U7-V7 -> 0
M8: =SUM(B8:L8) -> 0 | N8: =L8*L3+K8*K3+J8*J3+I8*I3+H8*H3+G8*G3+F8*F3+E8*E3+D8*D3+C8*C3+B8*B3 -> 0 | T8: =P8+Q8+R8+S8 -> 0 | U8: =N8 -> 0 | V8: =T8 -> 0 | W8: =U8-V8 -> 0
M9: =SUM(B9:L9) -> 0 | N9: =L9*L3+K9*K3+J9*J3+I9*I3+H9*H3+G9*G3+F9*F3+E9*E3+D9*D3+C9*C3+B9*B3 -> 0 | T9: =P9+Q9+R9+S9 -> 0 | U9: =N9 -> 0 | V9: =T9 -> 0 | W9: =U9-V9 -> 0
M10: =SUM(B10:L10) -> 0 | N10: =L10*L3+K10*K3+J10*J3+I10*I3+H10*H3+G10*G3+F10*F3+E10*E3+D10*D3+C10*C3+B10*B3 -> 0 | T10: =P10+Q10+R10+S10 -> 0 | U10: =N10 -> 0 | V10: =T10 -> 0 | W10: =U10-V10 -> 0
M11: =SUM(B11:L11) -> 0 | N11: =L11*L3+K11*K3+J11*J3+I11*I3+H11*H3+G11*G3+F11*F3+E11*E3+D11*D3+C11*C3+B11*B3 -> 0 | T11: =P11+Q11+R11+S11 -> 0 | U11: =N11 -> 0 | V11: =T11 -> 0 | W11: =U11-V11 -> 0
M12: =SUM(B12:L12) -> 0 | N12: =L12*L3+K12*K3+J12*J3+I12*I3+H12*H3+G12*G3+F12*F3+E12*E3+D12*D3+C12*C3+B12*B3 -> 0 | T12: =P12+Q12+R12+S12 -> 0 | U12: =N12 -> 0 | V12: =T12 -> 0 | W12: =U12-V12 -> 0
M13: =SUM(B13:L13) -> 0 | N13: =L13*L3+K13*K3+J13*J3+I13*I3+H13*H3+G13*G3+F13*F3+E13*E3+D13*D3+C13*C3+B13*B3 -> 0 | T13: =P13+Q13+R13+S13 -> 0 | U13: =N13 -> 0 | V13: =T13 -> 0 | W13: =U13-V13 -> 0
M14: =SUM(B14:L14) -> 0 | N14: =L14*L3+K14*K3+J14*J3+I14*I3+H14*H3+G14*G3+F14*F3+E14*E3+D14*D3+C14*C3+B14*B3 -> 0 | T14: =P14+Q14+R14+S14 -> 0 | U14: =N14 -> 0 | V14: =T14 -> 0 | W14: =U14-V14 -> 0
M15: =SUM(B15:L15) -> 0 | N15: =L15*L3+K15*K3+J15*J3+I15*I3+H15*H3+G15*G3+F15*F3+E15*E3+D15*D3+C15*C3+B15*B3 -> 0 | T15: =P15+Q15+R15+S15 -> 0 | U15: =N15 -> 0 | V15: =T15 -> 0 | W15: =U15-V15 -> 0
M16: =SUM(B16:L16) -> 0 | N16: =L16*L3+K16*K3+J16*J3+I16*I3+H16*H3+G16*G3+F16*F3+E16*E3+D16*D3+C16*C3+B16*B3 -> 0 | T16: =P16+Q16+R16+S16 -> 0 | U16: =N16 -> 0 | V16: =T16 -> 0 | W16: =U16-V16 -> 0
M17: =SUM(B17:L17) -> 0 | N17: =L17*L3+K17*K3+J17*J3+I17*I3+H17*H3+G17*G3+F17*F3+E17*E3+D17*D3+C17*C3+B17*B3 -> 0 | T17: =P17+Q17+R17+S17 -> 0 | U17: =N17 -> 0 | V17: =T17 -> 0 | W17: =U17-V17 -> 0
M18: =SUM(B18:L18) -> 0 | N18: =L18*L3+K18*K3+J18*J3+I18*I3+H18*H3+G18*G3+F18*F3+E18*E3+D18*D3+C18*C3+B18*B3 -> 0 | T18: =P18+Q18+R18+S18 -> 0 | U18: =N18 -> 0 | V18: =T18 -> 0 | W18: =U18-V18 -> 0
M19: =SUM(B19:L19) -> 0 | N19: =L19*L3+K19*K3+J19*J3+I19*I3+H19*H3+G19*G3+F19*F3+E19*E3+D19*D3+C19*C3+B19*B3 -> 0 | T19: =P19+Q19+R19+S19 -> 0 | U19: =N19 -> 0 | V19: =T19 -> 0 | W19: =U19-V19 -> 0
M20: =SUM(B20:L20) -> 0 | N20: =L20*L3+K20*K3+J20*J3+I20*I3+H20*H3+G20*G3+F20*F3+E20*E3+D20*D3+C20*C3+B20*B3 -> 0 | T20: =P20+Q20+R20+S20 -> 0 | U20: =N20 -> 0 | V20: =T20 -> 0 | W20: =U20-V20 -> 0
M21: =SUM(B21:L21) -> 0 | N21: =L21*L3+K21*K3+J21*J3+I21*I3+H21*H3+G21*G3+F21*F3+E21*E3+D21*D3+C21*C3+B21*B3 -> 0 | T21: =P21+Q21+R21+S21 -> 0 | U21: =N21 -> 0 | V21: =T21 -> 0 | W21: =U21-V21 -> 0
M22: =SUM(B22:L22) -> 0 | N22: =L22*L3+K22*K3+J22*J3+I22*I3+H22*H3+G22*G3+F22*F3+E22*E3+D22*D3+C22*C3+B22*B3 -> 0 | T22: =P22+Q22+R22+S22 -> 0 | U22: =N22 -> 0 | V22: =T22 -> 0 | W22: =U22-V22 -> 0
M23: =SUM(B23:L23) -> 0 | N23: =L23*L3+K23*K3+J23*J3+I23*I3+H23*H3+G23*G3+F23*F3+E23*E3+D23*D3+C23*C3+B23*B3 -> 0 | T23: =P23+Q23+R23+S23 -> 0 | U23: =N23 -> 0 | V23: =T23 -> 0 | W23: =U23-V23 -> 0
M24: =SUM(B24:L24) -> 0 | N24: =L24*L3+K24*K3+J24*J3+I24*I3+H24*H3+G24*G3+F24*F3+E24*E3+D24*D3+C24*C3+B24*B3 -> 0 | T24: =P24+Q24+R24+S24 -> 0 | U24: =N24 -> 0 | V24: =T24 -> 0 | W24: =U24-V24 -> 0
A25: G TOTAL | B25: =SUM(B5:B24) -> 0 | C25: =SUM(C5:C24) -> 0 | D25: =SUM(D5:D24) -> 0 | E25: =SUM(E5:E24) -> 0 | F25: =SUM(F5:F24) -> 0 | G25: =SUM(G5:G24) -> 0 | H25: =SUM(H5:H24) -> 0 | I25: =SUM(I5:I24) -> 0 | ... N25: =SUM(N5:N24) -> 0 | P25: =SUM(P5:P24) -> 0 | Q25: =SUM(Q5:Q24) -> 0 | R25: =SUM(R5:R24) -> 0 | S25: =SUM(S5:S24) -> 0 | T25: =SUM(T5:T24) -> 0 | U25: =SUM(U5:U24) -> 0 | V25: =SUM(V5:V24) -> 0 | W25: =SUM(W3:W24) -> 0

Sheet MIRZA
A1: Month January
A2: DO NAME | B2: STOCK ISSUANCE | O2: PAYMENT RECEIVED | U2: ACCOUNT BALANCE
A3: Date | B3: 280 | C3: 350 | D3: 1000 | E3: 500 | F3: 5000 | G3: 7400 | H3: 5350 | I3: 2100 | J3: 7000 | K3: 280 | L3: 390 | M3: Total Qty | N3: Total Amount | O3: Date | P3: PAYMENT RECEIVED | T3: Total Received | U3: Carry Forward | W3: 56592
B4: RETAILER | C4: FRANCHISE | D4: LOAD SIM | E4: MBB SIM | F4: E SIM | G4: Shine Mobile | H4: MOBILE | I4: WINGLE | J4: DONGLE | K4: RETAIL IMZI | L4: CS IMZI | P4: SIM | Q4: IMZI | R4: DEVICES | S4: MOBILE | U4: Total Amount | V4: Payment | W4: Due Balance
M5: =SUM(B5:L5) -> 0 | N5: =L5*L3+K5*K3+J5*J3+I5*I3+H5*H3+G5*G3+F5*F3+E5*E3+D5*D3+C5*C3+B5*B3 -> 0 | T5: =P5+Q5+R5+S5 -> 0 | U5: =N5 -> 0 | V5: =T5 -> 0 | W5: =U5-V5 -> 0
M6: =SUM(B6:L6) -> 0 | N6: =L6*L3+K6*K3+J6*J3+I6*I3+H6*H3+G6*G3+F6*F3+E6*E3+D6*D3+C6*C3+B6*B3 -> 0 | T6: =P6+Q6+R6+S6 -> 0 | U6: =N6 -> 0 | V6: =T6 -> 0 | W6: =U6-V6 -> 0
M7: =SUM(B7:L7) -> 0 | N7: =L7*L3+K7*K3+J7*J3+I7*I3+H7*H3+G7*G3+F7*F3+E7*E3+D7*D3+C7*C3+B7*B3 -> 0 | T7: =P7+Q7+R7+S7 -> 0 | U7: =N7 -> 0 | V7: =T7 -> 0 | W7: =U7-V7 -> 0
M8: =SUM(B8:L8) -> 0 | N8: =L8*L3+K8*K3+J8*J3+I8*I3+H8*H3+G8*G3+F8*F3+E8*E3+D8*D3+C8*C3+B8*B3 -> 0 | T8: =P8+Q8+R8+S8 -> 0 | U8: =N8 -> 0 | V8: =T8 -> 0 | W8: =U8-V8 -> 0
M9: =SUM(B9:L9) -> 0 | N9: =L9*L3+K9*K3+J9*J3+I9*I3+H9*H3+G9*G3+F9*F3+E9*E3+D9*D3+C9*C3+B9*B3 -> 0 | T9: =P9+Q9+R9+S9 -> 0 | U9: =N9 -> 0 | V9: =T9 -> 0 | W9: =U9-V9 -> 0
M10: =SUM(B10:L10) -> 0 | N10: =L10*L3+K10*K3+J10*J3+I10*I3+H10*H3+G10*G3+F10*F3+E10*E3+D10*D3+C10*C3+B10*B3 -> 0 | T10: =P10+Q10+R10+S10 -> 0 | U10: =N10 -> 0 | V10: =T10 -> 0 | W10: =U10-V10 -> 0
M11: =SUM(B11:L11) -> 0 | N11: =L11*L3+K11*K3+J11*J3+I11*I3+H11*H3+G11*G3+F11*F3+E11*E3+D11*D3+C11*C3+B11*B3 -> 0 | T11: =P11+Q11+R11+S11 -> 0 | U11: =N11 -> 0 | V11: =T11 -> 0 | W11: =U11-V11 -> 0
M12: =SUM(B12:L12) -> 0 | N12: =L12*L3+K12*K3+J12*J3+I12*I3+H12*H3+G12*G3+F12*F3+E12*E3+D12*D3+C12*C3+B12*B3 -> 0 | T12: =P12+Q12+R12+S12 -> 0 | U12: =N12 -> 0 | V12: =T12 -> 0 | W12: =U12-V12 -> 0
M13: =SUM(B13:L13) -> 0 | N13: =L13*L3+K13*K3+J13*J3+I13*I3+H13*H3+G13*G3+F13*F3+E13*E3+D13*D3+C13*C3+B13*B3 -> 0 | T13: =P13+Q13+R13+S13 -> 0 | U13: =N13 -> 0 | V13: =T13 -> 0 | W13: =U13-V13 -> 0
M14: =SUM(B14:L14) -> 0 | N14: =L14*L3+K14*K3+J14*J3+I14*I3+H14*H3+G14*G3+F14*F3+E14*E3+D14*D3+C14*C3+B14*B3 -> 0 | T14: =P14+Q14+R14+S14 -> 0 | U14: =N14 -> 0 | V14: =T14 -> 0 | W14: =U14-V14 -> 0
M15: =SUM(B15:L15) -> 0 | N15: =L15*L3+K15*K3+J15*J3+I15*I3+H15*H3+G15*G3+F15*F3+E15*E3+D15*D3+C15*C3+B15*B3 -> 0 | T15: =P15+Q15+R15+S15 -> 0 | U15: =N15 -> 0 | V15: =T15 -> 0 | W15: =U15-V15 -> 0
M16: =SUM(B16:L16) -> 0 | N16: =L16*L3+K16*K3+J16*J3+I16*I3+H16*H3+G16*G3+F16*F3+E16*E3+D16*D3+C16*C3+B16*B3 -> 0 | T16: =P16+Q16+R16+S16 -> 0 | U16: =N16 -> 0 | V16: =T16 -> 0 | W16: =U16-V16 -> 0
M17: =SUM(B17:L17) -> 0 | N17: =L17*L3+K17*K3+J17*J3+I17*I3+H17*H3+G17*G3+F17*F3+E17*E3+D17*D3+C17*C3+B17*B3 -> 0 | T17: =P17+Q17+R17+S17 -> 0 | U17: =N17 -> 0 | V17: =T17 -> 0 | W17: =U17-V17 -> 0
M18: =SUM(B18:L18) -> 0 | N18: =L18*L3+K18*K3+J18*J3+I18*I3+H18*H3+G18*G3+F18*F3+E18*E3+D18*D3+C18*C3+B18*B3 -> 0 | T18: =P18+Q18+R18+S18 -> 0 | U18: =N18 -> 0 | V18: =T18 -> 0 | W18: =U18-V18 -> 0
M19: =SUM(B19:L19) -> 0 | N19: =L19*L3+K19*K3+J19*J3+I19*I3+H19*H3+G19*G3+F19*F3+E19*E3+D19*D3+C19*C3+B19*B3 -> 0 | T19: =P19+Q19+R19+S19 -> 0 | U19: =N19 -> 0 | V19: =T19 -> 0 | W19: =U19-V19 -> 0
M20: =SUM(B20:L20) -> 0 | N20: =L20*L3+K20*K3+J20*J3+I20*I3+H20*H3+G20*G3+F20*F3+E20*E3+D20*D3+C20*C3+B20*B3 -> 0 | T20: =P20+Q20+R20+S20 -> 0 | U20: =N20 -> 0 | V20: =T20 -> 0 | W20: =U20-V20 -> 0
M21: =SUM(B21:L21) -> 0 | N21: =L21*L3+K21*K3+J21*J3+I21*I3+H21*H3+G21*G3+F21*F3+E21*E3+D21*D3+C21*C3+B21*B3 -> 0 | T21: =P21+Q21+R21+S21 -> 0 | U21: =N21 -> 0 | V21: =T21 -> 0 | W21: =U21-V21 -> 0
M22: =SUM(B22:L22) -> 0 | N22: =L22*L3+K22*K3+J22*J3+I22*I3+H22*H3+G22*G3+F22*F3+E22*E3+D22*D3+C22*C3+B22*B3 -> 0 | T22: =P22+Q22+R22+S22 -> 0 | U22: =N22 -> 0 | V22: =T22 -> 0 | W22: =U22-V22 -> 0
M23: =SUM(B23:L23) -> 0 | N23: =L23*L3+K23*K3+J23*J3+I23*I3+H23*H3+G23*G3+F23*F3+E23*E3+D23*D3+C23*C3+B23*B3 -> 0 | T23: =P23+Q23+R23+S23 -> 0 | U23: =N23 -> 0 | V23: =T23 -> 0 | W23: =U23-V23 -> 0
M24: =SUM(B24:L24) -> 0 | N24: =L24*L3+K24*K3+J24*J3+I24*I3+H24*H3+G24*G3+F24*F3+E24*E3+D24*D3+C24*C3+B24*B3 -> 0 | T24: =P24+Q24+R24+S24 -> 0 | U24: =N24 -> 0 | V24: =T24 -> 0 | W24: =U24-V24 -> 0
A25: G TOTAL | B25: =SUM(B5:B24) -> 0 | C25: =SUM(C5:C24) -> 0 | D25: =SUM(D5:D24) -> 0 | E25: =SUM(E5:E24) -> 0 | F25: =SUM(F5:F24) -> 0 | G25: =SUM(G5:G24) -> 0 | H25: =SUM(H5:H24) -> 0 | I25: =SUM(I5:I24) -> 0 | ... N25: =SUM(N5:N24) -> 0 | P25: =SUM(P5:P24) -> 0 | Q25: =SUM(Q5:Q24) -> 0 | R25: =SUM(R5:R24) -> 0 | S25: =SUM(S5:S24) -> 0 | T25: =SUM(T5:T24) -> 0 | U25: =SUM(U5:U24) -> 0 | V25: =SUM(V5:V24) -> 0 | W25: =SUM(W3:W24) -> 56592

Sheet ADNAN
A1: Month January
A2: DO NAME | B2: STOCK ISSUANCE | O2: PAYMENT RECEIVED | U2: ACCOUNT BALANCE
A3: Date | B3: 280 | C3: 350 | D3: 1000 | E3: 500 | F3: 5000 | G3: 7400 | H3: 5350 | I3: 2100 | J3: 7000 | K3: 230 | L3: 390 | M3: Total Qty | N3: Total Amount | O3: Date | P3: PAYMENT RECEIVED | T3: Total Received | U3: Carry Forward | W3: 0
B4: RETAILER | C4: FRANCHISE | D4: LOAD SIM | E4: MBB SIM | F4: E SIM | G4: Shine Mobile | H4: MOBILE | I4: WINGLE | J4: DONGLE | K4: RETAIL IMZI | L4: CS IMZI | P4: SIM | Q4: IMZI | R4: DEVICES | S4: MOBILE | U4: Total Amount | V4: Payment | W4: Due Balance
M5: =SUM(B5:L5) -> 0 | N5: =L5*L3+K5*K3+J5*J3+I5*I3+H5*H3+G5*G3+F5*F3+E5*E3+D5*D3+C5*C3+B5*B3 -> 0 | T5: =P5+Q5+R5+S5 -> 0 | U5: =N5 -> 0 | V5: =T5 -> 0 | W5: =U5-V5 -> 0
M6: =SUM(B6:L6) -> 0 | N6: =L6*L3+K6*K3+J6*J3+I6*I3+H6*H3+G6*G3+F6*F3+E6*E3+D6*D3+C6*C3+B6*B3 -> 0 | T6: =P6+Q6+R6+S6 -> 0 | U6: =N6 -> 0 | V6: =T6 -> 0 | W6: =U6-V6 -> 0
M7: =SUM(B7:L7) -> 0 | N7: =L7*L3+K7*K3+J7*J3+I7*I3+H7*H3+G7*G3+F7*F3+E7*E3+D7*D3+C7*C3+B7*B3 -> 0 | T7: =P7+Q7+R7+S7 -> 0 | U7: =N7 -> 0 | V7: =T7 -> 0 | W7: =U7-V7 -> 0
M8: =SUM(B8:L8) -> 0 | N8: =L8*L3+K8*K3+J8*J3+I8*I3+H8*H3+G8*G3+F8*F3+E8*E3+D8*D3+C8*C3+B8*B3 -> 0 | T8: =P8+Q8+R8+S8 -> 0 | U8: =N8 -> 0 | V8: =T8 -> 0 | W8: =U8-V8 -> 0
M9: =SUM(B9:L9) -> 0 | N9: =L9*L3+K9*K3+J9*J3+I9*I3+H9*H3+G9*G3+F9*F3+E9*E3+D9*D3+C9*C3+B9*B3 -> 0 | T9: =P9+Q9+R9+S9 -> 0 | U9: =N9 -> 0 | V9: =T9 -> 0 | W9: =U9-V9 -> 0
M10: =SUM(B10:L10) -> 0 | N10: =L10*L3+K10*K3+J10*J3+I10*I3+H10*H3+G10*G3+F10*F3+E10*E3+D10*D3+C10*C3+B10*B3 -> 0 | T10: =P10+Q10+R10+S10 -> 0 | U10: =N10 -> 0 | V10: =T10 -> 0 | W10: =U10-V10 -> 0
M11: =SUM(B11:L11) -> 0 | N11: =L11*L3+K11*K3+J11*J3+I11*I3+H11*H3+G11*G3+F11*F3+E11*E3+D11*D3+C11*C3+B11*B3 -> 0 | T11: =P11+Q11+R11+S11 -> 0 | U11: =N11 -> 0 | V11: =T11 -> 0 | W11: =U11-V11 -> 0
M12: =SUM(B12:L12) -> 0 | N12: =L12*L3+K12*K3+J12*J3+I12*I3+H12*H3+G12*G3+F12*F3+E12*E3+D12*D3+C12*C3+B12*B3 -> 0 | T12: =P12+Q12+R12+S12 -> 0 | U12: =N12 -> 0 | V12: =T12 -> 0 | W12: =U12-V12 -> 0
M13: =SUM(B13:L13) -> 0 | N13: =L13*L3+K13*K3+J13*J3+I13*I3+H13*H3+G13*G3+F13*F3+E13*E3+D13*D3+C13*C3+B13*B3 -> 0 | T13: =P13+Q13+R13+S13 -> 0 | U13: =N13 -> 0 | V13: =T13 -> 0 | W13: =U13-V13 -> 0
M14: =SUM(B14:L14) -> 0 | N14: =L14*L3+K14*K3+J14*J3+I14*I3+H14*H3+G14*G3+F14*F3+E14*E3+D14*D3+C14*C3+B14*B3 -> 0 | T14: =P14+Q14+R14+S14 -> 0 | U14: =N14 -> 0 | V14: =T14 -> 0 | W14: =U14-V14 -> 0
M15: =SUM(B15:L15) -> 0 | N15: =L15*L3+K15*K3+J15*J3+I15*I3+H15*H3+G15*G3+F15*F3+E15*E3+D15*D3+C15*C3+B15*B3 -> 0 | T15: =P15+Q15+R15+S15 -> 0 | U15: =N15 -> 0 | V15: =T15 -> 0 | W15: =U15-V15 -> 0
M16: =SUM(B16:L16) -> 0 | N16: =L16*L3+K16*K3+J16*J3+I16*I3+H16*H3+G16*G3+F16*F3+E16*E3+D16*D3+C16*C3+B16*B3 -> 0 | T16: =P16+Q16+R16+S16 -> 0 | U16: =N16 -> 0 | V16: =T16 -> 0 | W16: =U16-V16 -> 0
M17: =SUM(B17:L17) -> 0 | N17: =L17*L3+K17*K3+J17*J3+I17*I3+H17*H3+G17*G3+F17*F3+E17*E3+D17*D3+C17*C3+B17*B3 -> 0 | T17: =P17+Q17+R17+S17 -> 0 | U17: =N17 -> 0 | V17: =T17 -> 0 | W17: =U17-V17 -> 0
M18: =SUM(B18:L18) -> 0 | N18: =L18*L3+K18*K3+J18*J3+I18*I3+H18*H3+G18*G3+F18*F3+E18*E3+D18*D3+C18*C3+B18*B3 -> 0 | T18: =P18+Q18+R18+S18 -> 0 | U18: =N18 -> 0 | V18: =T18 -> 0 | W18: =U18-V18 -> 0
M19: =SUM(B19:L19) -> 0 | N19: =L19*L3+K19*K3+J19*J3+I19*I3+H19*H3+G19*G3+F19*F3+E19*E3+D19*D3+C19*C3+B19*B3 -> 0 | T19: =P19+Q19+R19+S19 -> 0 | U19: =N19 -> 0 | V19: =T19 -> 0 | W19: =U19-V19 -> 0
M20: =SUM(B20:L20) -> 0 | N20: =L20*L3+K20*K3+J20*J3+I20*I3+H20*H3+G20*G3+F20*F3+E20*E3+D20*D3+C20*C3+B20*B3 -> 0 | T20: =P20+Q20+R20+S20 -> 0 | U20: =N20 -> 0 | V20: =T20 -> 0 | W20: =U20-V20 -> 0
M21: =SUM(B21:L21) -> 0 | N21: =L21*L3+K21*K3+J21*J3+I21*I3+H21*H3+G21*G3+F21*F3+E21*E3+D21*D3+C21*C3+B21*B3 -> 0 | T21: =P21+Q21+R21+S21 -> 0 | U21: =N21 -> 0 | V21: =T21 -> 0 | W21: =U21-V21 -> 0
M22: =SUM(B22:L22) -> 0 | N22: =L22*L3+K22*K3+J22*J3+I22*I3+H22*H3+G22*G3+F22*F3+E22*E3+D22*D3+C22*C3+B22*B3 -> 0 | T22: =P22+Q22+R22+S22 -> 0 | U22: =N22 -> 0 | V22: =T22 -> 0 | W22: =U22-V22 -> 0
M23: =SUM(B23:L23) -> 0 | N23: =L23*L3+K23*K3+J23*J3+I23*I3+H23*H3+G23*G3+F23*F3+E23*E3+D23*D3+C23*C3+B23*B3 -> 0 | T23: =P23+Q23+R23+S23 -> 0 | U23: =N23 -> 0 | V23: =T23 -> 0 | W23: =U23-V23 -> 0
M24: =SUM(B24:L24) -> 0 | N24: =L24*L3+K24*K3+J24*J3+I24*I3+H24*H3+G24*G3+F24*F3+E24*E3+D24*D3+C24*C3+B24*B3 -> 0 | T24: =P24+Q24+R24+S24 -> 0 | U24: =N24 -> 0 | V24: =T24 -> 0 | W24: =U24-V24 -> 0
A25: G TOTAL | B25: =SUM(B5:B24) -> 0 | C25: =SUM(C5:C24) -> 0 | D25: =SUM(D5:D24) -> 0 | E25: =SUM(E5:E24) -> 0 | F25: =SUM(F5:F24) -> 0 | G25: =SUM(G5:G24) -> 0 | H25: =SUM(H5:H24) -> 0 | I25: =SUM(I5:I24) -> 0 | ... N25: =SUM(N5:N24) -> 0 | P25: =SUM(P5:P24) -> 0 | Q25: =SUM(Q5:Q24) -> 0 | R25: =SUM(R5:R24) -> 0 | S25: =SUM(S5:S24) -> 0 | T25: =SUM(T5:T24) -> 0 | U25: =SUM(U5:U24) -> 0 | V25: =SUM(V5:V24) -> 0 | W25: =SUM(W3:W24) -> 0

Sheet ARSLAN
A1: Month January
A2: DO NAME | B2: STOCK ISSUANCE | O2: PAYMENT RECEIVED | U2: ACCOUNT BALANCE
A3: Date | B3: 280 | C3: 350 | D3: 1000 | E3: 500 | F3: 5000 | G3: 7400 | H3: 5350 | I3: 2100 | J3: 7000 | K3: 280 | L3: 390 | M3: Total Qty | N3: Total Amount | O3: Date | P3: PAYMENT RECEIVED | T3: Total Received | U3: Carry Forward | W3: 59015
B4: RETAILER | C4: FRANCHISE | D4: LOAD SIM | E4: MBB SIM | F4: E SIM | G4: Shine Mobile | H4: MOBILE | I4: WINGLE | J4: DONGLE | K4: RETAIL IMZI | L4: CS IMZI | P4: SIM | Q4: IMZI | R4: DEVICES | S4: MOBILE | U4: Total Amount | V4: Payment | W4: Due Balance
A5: 46266 | K5: 100 | M5: =SUM(B5:L5) -> 100 | N5: =L5*L3+K5*K3+J5*J3+I5*I3+H5*H3+G5*G3+F5*F3+E5*E3+D5*D3+C5*C3+B5*B3 -> 28000 | T5: =P5+Q5+R5+S5 -> 0 | U5: =N5 -> 28000 | V5: =T5 -> 0 | W5: =U5-V5 -> 28000
M6: =SUM(B6:L6) -> 0 | N6: =L6*L3+K6*K3+J6*J3+I6*I3+H6*H3+G6*G3+F6*F3+E6*E3+D6*D3+C6*C3+B6*B3 -> 0 | T6: =P6+Q6+R6+S6 -> 0 | U6: =N6 -> 0 | V6: =T6 -> 0 | W6: =U6-V6 -> 0
M7: =SUM(B7:L7) -> 0 | N7: =L7*L3+K7*K3+J7*J3+I7*I3+H7*H3+G7*G3+F7*F3+E7*E3+D7*D3+C7*C3+B7*B3 -> 0 | T7: =P7+Q7+R7+S7 -> 0 | U7: =N7 -> 0 | V7: =T7 -> 0 | W7: =U7-V7 -> 0
M8: =SUM(B8:L8) -> 0 | N8: =L8*L3+K8*K3+J8*J3+I8*I3+H8*H3+G8*G3+F8*F3+E8*E3+D8*D3+C8*C3+B8*B3 -> 0 | T8: =P8+Q8+R8+S8 -> 0 | U8: =N8 -> 0 | V8: =T8 -> 0 | W8: =U8-V8 -> 0
M9: =SUM(B9:L9) -> 0 | N9: =L9*L3+K9*K3+J9*J3+I9*I3+H9*H3+G9*G3+F9*F3+E9*E3+D9*D3+C9*C3+B9*B3 -> 0 | T9: =P9+Q9+R9+S9 -> 0 | U9: =N9 -> 0 | V9: =T9 -> 0 | W9: =U9-V9 -> 0
M10: =SUM(B10:L10) -> 0 | N10: =L10*L3+K10*K3+J10*J3+I10*I3+H10*H3+G10*G3+F10*F3+E10*E3+D10*D3+C10*C3+B10*B3 -> 0 | T10: =P10+Q10+R10+S10 -> 0 | U10: =N10 -> 0 | V10: =T10 -> 0 | W10: =U10-V10 -> 0
M11: =SUM(B11:L11) -> 0 | N11: =L11*L3+K11*K3+J11*J3+I11*I3+H11*H3+G11*G3+F11*F3+E11*E3+D11*D3+C11*C3+B11*B3 -> 0 | T11: =P11+Q11+R11+S11 -> 0 | U11: =N11 -> 0 | V11: =T11 -> 0 | W11: =U11-V11 -> 0
M12: =SUM(B12:L12) -> 0 | N12: =L12*L3+K12*K3+J12*J3+I12*I3+H12*H3+G12*G3+F12*F3+E12*E3+D12*D3+C12*C3+B12*B3 -> 0 | T12: =P12+Q12+R12+S12 -> 0 | U12: =N12 -> 0 | V12: =T12 -> 0 | W12: =U12-V12 -> 0
M13: =SUM(B13:L13) -> 0 | N13: =L13*L3+K13*K3+J13*J3+I13*I3+H13*H3+G13*G3+F13*F3+E13*E3+D13*D3+C13*C3+B13*B3 -> 0 | T13: =P13+Q13+R13+S13 -> 0 | U13: =N13 -> 0 | V13: =T13 -> 0 | W13: =U13-V13 -> 0
M14: =SUM(B14:L14) -> 0 | N14: =L14*L3+K14*K3+J14*J3+I14*I3+H14*H3+G14*G3+F14*F3+E14*E3+D14*D3+C14*C3+B14*B3 -> 0 | T14: =P14+Q14+R14+S14 -> 0 | U14: =N14 -> 0 | V14: =T14 -> 0 | W14: =U14-V14 -> 0
M15: =SUM(B15:L15) -> 0 | N15: =L15*L3+K15*K3+J15*J3+I15*I3+H15*H3+G15*G3+F15*F3+E15*E3+D15*D3+C15*C3+B15*B3 -> 0 | T15: =P15+Q15+R15+S15 -> 0 | U15: =N15 -> 0 | V15: =T15 -> 0 | W15: =U15-V15 -> 0
M16: =SUM(B16:L16) -> 0 | N16: =L16*L3+K16*K3+J16*J3+I16*I3+H16*H3+G16*G3+F16*F3+E16*E3+D16*D3+C16*C3+B16*B3 -> 0 | T16: =P16+Q16+R16+S16 -> 0 | U16: =N16 -> 0 | V16: =T16 -> 0 | W16: =U16-V16 -> 0
M17: =SUM(B17:L17) -> 0 | N17: =L17*L3+K17*K3+J17*J3+I17*I3+H17*H3+G17*G3+F17*F3+E17*E3+D17*D3+C17*C3+B17*B3 -> 0 | T17: =P17+Q17+R17+S17 -> 0 | U17: =N17 -> 0 | V17: =T17 -> 0 | W17: =U17-V17 -> 0
M18: =SUM(B18:L18) -> 0 | N18: =L18*L3+K18*K3+J18*J3+I18*I3+H18*H3+G18*G3+F18*F3+E18*E3+D18*D3+C18*C3+B18*B3 -> 0 | T18: =P18+Q18+R18+S18 -> 0 | U18: =N18 -> 0 | V18: =T18 -> 0 | W18: =U18-V18 -> 0
M19: =SUM(B19:L19) -> 0 | N19: =L19*L3+K19*K3+J19*J3+I19*I3+H19*H3+G19*G3+F19*F3+E19*E3+D19*D3+C19*C3+B19*B3 -> 0 | T19: =P19+Q19+R19+S19 -> 0 | U19: =N19 -> 0 | V19: =T19 -> 0 | W19: =U19-V19 -> 0
M20: =SUM(B20:L20) -> 0 | N20: =L20*L3+K20*K3+J20*J3+I20*I3+H20*H3+G20*G3+F20*F3+E20*E3+D20*D3+C20*C3+B20*B3 -> 0 | T20: =P20+Q20+R20+S20 -> 0 | U20: =N20 -> 0 | V20: =T20 -> 0 | W20: =U20-V20 -> 0
M21: =SUM(B21:L21) -> 0 | N21: =L21*L3+K21*K3+J21*J3+I21*I3+H21*H3+G21*G3+F21*F3+E21*E3+D21*D3+C21*C3+B21*B3 -> 0 | T21: =P21+Q21+R21+S21 -> 0 | U21: =N21 -> 0 | V21: =T21 -> 0 | W21: =U21-V21 -> 0
M22: =SUM(B22:L22) -> 0 | N22: =L22*L3+K22*K3+J22*J3+I22*I3+H22*H3+G22*G3+F22*F3+E22*E3+D22*D3+C22*C3+B22*B3 -> 0 | T22: =P22+Q22+R22+S22 -> 0 | U22: =N22 -> 0 | V22: =T22 -> 0 | W22: =U22-V22 -> 0
M23: =SUM(B23:L23) -> 0 | N23: =L23*L3+K23*K3+J23*J3+I23*I3+H23*H3+G23*G3+F23*F3+E23*E3+D23*D3+C23*C3+B23*B3 -> 0 | T23: =P23+Q23+R23+S23 -> 0 | U23: =N23 -> 0 | V23: =T23 -> 0 | W23: =U23-V23 -> 0
M24: =SUM(B24:L24) -> 0 | N24: =L24*L3+K24*K3+J24*J3+I24*I3+H24*H3+G24*G3+F24*F3+E24*E3+D24*D3+C24*C3+B24*B3 -> 0 | T24: =P24+Q24+R24+S24 -> 0 | U24: =N24 -> 0 | V24: =T24 -> 0 | W24: =U24-V24 -> 0
A25: G TOTAL | B25: =SUM(B5:B24) -> 0 | C25: =SUM(C5:C24) -> 0 | D25: =SUM(D5:D24) -> 0 | E25: =SUM(E5:E24) -> 0 | F25: =SUM(F5:F24) -> 0 | G25: =SUM(G5:G24) -> 0 | H25: =SUM(H5:H24) -> 0 | I25: =SUM(I5:I24) -> 0 | ... N25: =SUM(N5:N24) -> 28000 | P25: =SUM(P5:P24) -> 0 | Q25: =SUM(Q5:Q24) -> 0 | R25: =SUM(R5:R24) -> 0 | S25: =SUM(S5:S24) -> 0 | T25: =SUM(T5:T24) -> 0 | U25: =SUM(U5:U24) -> 28000 | V25: =SUM(V5:V24) -> 0 | W25: =SUM(W3:W24) -> 87015

Sheet Mubashar 
A1: Month January
A2: DO NAME | B2: STOCK ISSUANCE | O2: PAYMENT RECEIVED | U2: ACCOUNT BALANCE
A3: Date | B3: 280 | C3: 350 | D3: 1000 | E3: 500 | F3: 5000 | G3: 7400 | H3: 5350 | I3: 2100 | J3: 7000 | K3: 280 | L3: 390 | M3: Total Qty | N3: Total Amount | O3: Date | P3: PAYMENT RECEIVED | T3: Total Received | U3: Carry Forward | W3: 58240
B4: RETAILER | C4: FRANCHISE | D4: LOAD SIM | E4: MBB SIM | F4: E SIM | G4: Shine Mobile | H4: MOBILE | I4: WINGLE | J4: DONGLE | K4: RETAIL IMZI | L4: CS IMZI | P4: SIM | Q4: IMZI | R4: DEVICES | S4: MOBILE | U4: Total Amount | V4: Payment | W4: Due Balance
A5: 46266 | B5: 100 | M5: =SUM(B5:L5) -> 100 | N5: =L5*L3+K5*K3+J5*J3+I5*I3+H5*H3+G5*G3+F5*F3+E5*E3+D5*D3+C5*C3+B5*B3 -> 28000 | T5: =P5+Q5+R5+S5 -> 0 | U5: =N5 -> 28000 | V5: =T5 -> 0 | W5: =U5-V5 -> 28000
M6: =SUM(B6:L6) -> 0 | N6: =L6*L3+K6*K3+J6*J3+I6*I3+H6*H3+G6*G3+F6*F3+E6*E3+D6*D3+C6*C3+B6*B3 -> 0 | T6: =P6+Q6+R6+S6 -> 0 | U6: =N6 -> 0 | V6: =T6 -> 0 | W6: =U6-V6 -> 0
M7: =SUM(B7:L7) -> 0 | N7: =L7*L3+K7*K3+J7*J3+I7*I3+H7*H3+G7*G3+F7*F3+E7*E3+D7*D3+C7*C3+B7*B3 -> 0 | T7: =P7+Q7+R7+S7 -> 0 | U7: =N7 -> 0 | V7: =T7 -> 0 | W7: =U7-V7 -> 0
M8: =SUM(B8:L8) -> 0 | N8: =L8*L3+K8*K3+J8*J3+I8*I3+H8*H3+G8*G3+F8*F3+E8*E3+D8*D3+C8*C3+B8*B3 -> 0 | T8: =P8+Q8+R8+S8 -> 0 | U8: =N8 -> 0 | V8: =T8 -> 0 | W8: =U8-V8 -> 0
M9: =SUM(B9:L9) -> 0 | N9: =L9*L3+K9*K3+J9*J3+I9*I3+H9*H3+G9*G3+F9*F3+E9*E3+D9*D3+C9*C3+B9*B3 -> 0 | T9: =P9+Q9+R9+S9 -> 0 | U9: =N9 -> 0 | V9: =T9 -> 0 | W9: =U9-V9 -> 0
M10: =SUM(B10:L10) -> 0 | N10: =L10*L3+K10*K3+J10*J3+I10*I3+H10*H3+G10*G3+F10*F3+E10*E3+D10*D3+C10*C3+B10*B3 -> 0 | T10: =P10+Q10+R10+S10 -> 0 | U10: =N10 -> 0 | V10: =T10 -> 0 | W10: =U10-V10 -> 0
M11: =SUM(B11:L11) -> 0 | N11: =L11*L3+K11*K3+J11*J3+I11*I3+H11*H3+G11*G3+F11*F3+E11*E3+D11*D3+C11*C3+B11*B3 -> 0 | T11: =P11+Q11+R11+S11 -> 0 | U11: =N11 -> 0 | V11: =T11 -> 0 | W11: =U11-V11 -> 0
M12: =SUM(B12:L12) -> 0 | N12: =L12*L3+K12*K3+J12*J3+I12*I3+H12*H3+G12*G3+F12*F3+E12*E3+D12*D3+C12*C3+B12*B3 -> 0 | T12: =P12+Q12+R12+S12 -> 0 | U12: =N12 -> 0 | V12: =T12 -> 0 | W12: =U12-V12 -> 0
M13: =SUM(B13:L13) -> 0 | N13: =L13*L3+K13*K3+J13*J3+I13*I3+H13*H3+G13*G3+F13*F3+E13*E3+D13*D3+C13*C3+B13*B3 -> 0 | T13: =P13+Q13+R13+S13 -> 0 | U13: =N13 -> 0 | V13: =T13 -> 0 | W13: =U13-V13 -> 0
M14: =SUM(B14:L14) -> 0 | N14: =L14*L3+K14*K3+J14*J3+I14*I3+H14*H3+G14*G3+F14*F3+E14*E3+D14*D3+C14*C3+B14*B3 -> 0 | T14: =P14+Q14+R14+S14 -> 0 | U14: =N14 -> 0 | V14: =T14 -> 0 | W14: =U14-V14 -> 0
M15: =SUM(B15:L15) -> 0 | N15: =L15*L3+K15*K3+J15*J3+I15*I3+H15*H3+G15*G3+F15*F3+E15*E3+D15*D3+C15*C3+B15*B3 -> 0 | T15: =P15+Q15+R15+S15 -> 0 | U15: =N15 -> 0 | V15: =T15 -> 0 | W15: =U15-V15 -> 0
M16: =SUM(B16:L16) -> 0 | N16: =L16*L3+K16*K3+J16*J3+I16*I3+H16*H3+G16*G3+F16*F3+E16*E3+D16*D3+C16*C3+B16*B3 -> 0 | T16: =P16+Q16+R16+S16 -> 0 | U16: =N16 -> 0 | V16: =T16 -> 0 | W16: =U16-V16 -> 0
M17: =SUM(B17:L17) -> 0 | N17: =L17*L3+K17*K3+J17*J3+I17*I3+H17*H3+G17*G3+F17*F3+E17*E3+D17*D3+C17*C3+B17*B3 -> 0 | T17: =P17+Q17+R17+S17 -> 0 | U17: =N17 -> 0 | V17: =T17 -> 0 | W17: =U17-V17 -> 0
M18: =SUM(B18:L18) -> 0 | N18: =L18*L3+K18*K3+J18*J3+I18*I3+H18*H3+G18*G3+F18*F3+E18*E3+D18*D3+C18*C3+B18*B3 -> 0 | T18: =P18+Q18+R18+S18 -> 0 | U18: =N18 -> 0 | V18: =T18 -> 0 | W18: =U18-V18 -> 0
M19: =SUM(B19:L19) -> 0 | N19: =L19*L3+K19*K3+J19*J3+I19*I3+H19*H3+G19*G3+F19*F3+E19*E3+D19*D3+C19*C3+B19*B3 -> 0 | T19: =P19+Q19+R19+S19 -> 0 | U19: =N19 -> 0 | V19: =T19 -> 0 | W19: =U19-V19 -> 0
M20: =SUM(B20:L20) -> 0 | N20: =L20*L3+K20*K3+J20*J3+I20*I3+H20*H3+G20*G3+F20*F3+E20*E3+D20*D3+C20*C3+B20*B3 -> 0 | T20: =P20+Q20+R20+S20 -> 0 | U20: =N20 -> 0 | V20: =T20 -> 0 | W20: =U20-V20 -> 0
M21: =SUM(B21:L21) -> 0 | N21: =L21*L3+K21*K3+J21*J3+I21*I3+H21*H3+G21*G3+F21*F3+E21*E3+D21*D3+C21*C3+B21*B3 -> 0 | T21: =P21+Q21+R21+S21 -> 0 | U21: =N21 -> 0 | V21: =T21 -> 0 | W21: =U21-V21 -> 0
M22: =SUM(B22:L22) -> 0 | N22: =L22*L3+K22*K3+J22*J3+I22*I3+H22*H3+G22*G3+F22*F3+E22*E3+D22*D3+C22*C3+B22*B3 -> 0 | T22: =P22+Q22+R22+S22 -> 0 | U22: =N22 -> 0 | V22: =T22 -> 0 | W22: =U22-V22 -> 0
M23: =SUM(B23:L23) -> 0 | N23: =L23*L3+K23*K3+J23*J3+I23*I3+H23*H3+G23*G3+F23*F3+E23*E3+D23*D3+C23*C3+B23*B3 -> 0 | T23: =P23+Q23+R23+S23 -> 0 | U23: =N23 -> 0 | V23: =T23 -> 0 | W23: =U23-V23 -> 0
M24: =SUM(B24:L24) -> 0 | N24: =L24*L3+K24*K3+J24*J3+I24*I3+H24*H3+G24*G3+F24*F3+E24*E3+D24*D3+C24*C3+B24*B3 -> 0 | T24: =P24+Q24+R24+S24 -> 0 | U24: =N24 -> 0 | V24: =T24 -> 0 | W24: =U24-V24 -> 0
A25: G TOTAL | B25: =SUM(B5:B24) -> 100 | C25: =SUM(C5:C24) -> 0 | D25: =SUM(D5:D24) -> 0 | E25: =SUM(E5:E24) -> 0 | F25: =SUM(F5:F24) -> 0 | G25: =SUM(G5:G24) -> 0 | H25: =SUM(H5:H24) -> 0 | I25: =SUM(I5:I24) -> 0 | ... N25: =SUM(N5:N24) -> 28000 | P25: =SUM(P5:P24) -> 0 | Q25: =SUM(Q5:Q24) -> 0 | R25: =SUM(R5:R24) -> 0 | S25: =SUM(S5:S24) -> 0 | T25: =SUM(T5:T24) -> 0 | U25: =SUM(U5:U24) -> 28000 | V25: =SUM(V5:V24) -> 0 | W25: =SUM(W3:W24) -> 86240

Sheet NEW IRFAN 
A1: Month January
A2: DO NAME | B2: STOCK ISSUANCE | O2: PAYMENT RECEIVED | U2: ACCOUNT BALANCE
A3: Date | B3: 280 | C3: 350 | D3: 1000 | E3: 500 | F3: 5000 | G3: 7400 | H3: 5350 | I3: 2100 | J3: 7000 | K3: 280 | L3: 390 | M3: Total Qty | N3: Total Amount | O3: Date | P3: PAYMENT RECEIVED | T3: Total Received | U3: Carry Forward | W3: 36960
B4: RETAILER | C4: FRANCHISE | D4: LOAD SIM | E4: MBB SIM | F4: E SIM | G4: Shine Mobile | H4: MOBILE | I4: WINGLE | J4: DONGLE | K4: RETAIL IMZI | L4: CS IMZI | P4: SIM | Q4: IMZI | R4: DEVICES | S4: MOBILE | U4: Total Amount | V4: Payment | W4: Due Balance
A5: 46266 | B5: 40 | K5: 20 | M5: =SUM(B5:L5) -> 60 | N5: =L5*L3+K5*K3+J5*J3+I5*I3+H5*H3+G5*G3+F5*F3+E5*E3+D5*D3+C5*C3+B5*B3 -> 16800 | T5: =P5+Q5+R5+S5 -> 0 | U5: =N5 -> 16800 | V5: =T5 -> 0 | W5: =U5-V5 -> 16800
M6: =SUM(B6:L6) -> 0 | N6: =L6*L3+K6*K3+J6*J3+I6*I3+H6*H3+G6*G3+F6*F3+E6*E3+D6*D3+C6*C3+B6*B3 -> 0 | T6: =P6+Q6+R6+S6 -> 0 | U6: =N6 -> 0 | V6: =T6 -> 0 | W6: =U6-V6 -> 0
M7: =SUM(B7:L7) -> 0 | N7: =L7*L3+K7*K3+J7*J3+I7*I3+H7*H3+G7*G3+F7*F3+E7*E3+D7*D3+C7*C3+B7*B3 -> 0 | T7: =P7+Q7+R7+S7 -> 0 | U7: =N7 -> 0 | V7: =T7 -> 0 | W7: =U7-V7 -> 0
M8: =SUM(B8:L8) -> 0 | N8: =L8*L3+K8*K3+J8*J3+I8*I3+H8*H3+G8*G3+F8*F3+E8*E3+D8*D3+C8*C3+B8*B3 -> 0 | T8: =P8+Q8+R8+S8 -> 0 | U8: =N8 -> 0 | V8: =T8 -> 0 | W8: =U8-V8 -> 0
M9: =SUM(B9:L9) -> 0 | N9: =L9*L3+K9*K3+J9*J3+I9*I3+H9*H3+G9*G3+F9*F3+E9*E3+D9*D3+C9*C3+B9*B3 -> 0 | T9: =P9+Q9+R9+S9 -> 0 | U9: =N9 -> 0 | V9: =T9 -> 0 | W9: =U9-V9 -> 0
M10: =SUM(B10:L10) -> 0 | N10: =L10*L3+K10*K3+J10*J3+I10*I3+H10*H3+G10*G3+F10*F3+E10*E3+D10*D3+C10*C3+B10*B3 -> 0 | T10: =P10+Q10+R10+S10 -> 0 | U10: =N10 -> 0 | V10: =T10 -> 0 | W10: =U10-V10 -> 0
M11: =SUM(B11:L11) -> 0 | N11: =L11*L3+K11*K3+J11*J3+I11*I3+H11*H3+G11*G3+F11*F3+E11*E3+D11*D3+C11*C3+B11*B3 -> 0 | T11: =P11+Q11+R11+S11 -> 0 | U11: =N11 -> 0 | V11: =T11 -> 0 | W11: =U11-V11 -> 0
M12: =SUM(B12:L12) -> 0 | N12: =L12*L3+K12*K3+J12*J3+I12*I3+H12*H3+G12*G3+F12*F3+E12*E3+D12*D3+C12*C3+B12*B3 -> 0 | T12: =P12+Q12+R12+S12 -> 0 | U12: =N12 -> 0 | V12: =T12 -> 0 | W12: =U12-V12 -> 0
M13: =SUM(B13:L13) -> 0 | N13: =L13*L3+K13*K3+J13*J3+I13*I3+H13*H3+G13*G3+F13*F3+E13*E3+D13*D3+C13*C3+B13*B3 -> 0 | T13: =P13+Q13+R13+S13 -> 0 | U13: =N13 -> 0 | V13: =T13 -> 0 | W13: =U13-V13 -> 0
M14: =SUM(B14:L14) -> 0 | N14: =L14*L3+K14*K3+J14*J3+I14*I3+H14*H3+G14*G3+F14*F3+E14*E3+D14*D3+C14*C3+B14*B3 -> 0 | T14: =P14+Q14+R14+S14 -> 0 | U14: =N14 -> 0 | V14: =T14 -> 0 | W14: =U14-V14 -> 0
M15: =SUM(B15:L15) -> 0 | N15: =L15*L3+K15*K3+J15*J3+I15*I3+H15*H3+G15*G3+F15*F3+E15*E3+D15*D3+C15*C3+B15*B3 -> 0 | T15: =P15+Q15+R15+S15 -> 0 | U15: =N15 -> 0 | V15: =T15 -> 0 | W15: =U15-V15 -> 0
M16: =SUM(B16:L16) -> 0 | N16: =L16*L3+K16*K3+J16*J3+I16*I3+H16*H3+G16*G3+F16*F3+E16*E3+D16*D3+C16*C3+B16*B3 -> 0 | T16: =P16+Q16+R16+S16 -> 0 | U16: =N16 -> 0 | V16: =T16 -> 0 | W16: =U16-V16 -> 0
M17: =SUM(B17:L17) -> 0 | N17: =L17*L3+K17*K3+J17*J3+I17*I3+H17*H3+G17*G3+F17*F3+E17*E3+D17*D3+C17*C3+B17*B3 -> 0 | T17: =P17+Q17+R17+S17 -> 0 | U17: =N17 -> 0 | V17: =T17 -> 0 | W17: =U17-V17 -> 0
M18: =SUM(B18:L18) -> 0 | N18: =L18*L3+K18*K3+J18*J3+I18*I3+H18*H3+G18*G3+F18*F3+E18*E3+D18*D3+C18*C3+B18*B3 -> 0 | T18: =P18+Q18+R18+S18 -> 0 | U18: =N18 -> 0 | V18: =T18 -> 0 | W18: =U18-V18 -> 0
M19: =SUM(B19:L19) -> 0 | N19: =L19*L3+K19*K3+J19*J3+I19*I3+H19*H3+G19*G3+F19*F3+E19*E3+D19*D3+C19*C3+B19*B3 -> 0 | T19: =P19+Q19+R19+S19 -> 0 | U19: =N19 -> 0 | V19: =T19 -> 0 | W19: =U19-V19 -> 0
M20: =SUM(B20:L20) -> 0 | N20: =L20*L3+K20*K3+J20*J3+I20*I3+H20*H3+G20*G3+F20*F3+E20*E3+D20*D3+C20*C3+B20*B3 -> 0 | T20: =P20+Q20+R20+S20 -> 0 | U20: =N20 -> 0 | V20: =T20 -> 0 | W20: =U20-V20 -> 0
M21: =SUM(B21:L21) -> 0 | N21: =L21*L3+K21*K3+J21*J3+I21*I3+H21*H3+G21*G3+F21*F3+E21*E3+D21*D3+C21*C3+B21*B3 -> 0 | T21: =P21+Q21+R21+S21 -> 0 | U21: =N21 -> 0 | V21: =T21 -> 0 | W21: =U21-V21 -> 0
M22: =SUM(B22:L22) -> 0 | N22: =L22*L3+K22*K3+J22*J3+I22*I3+H22*H3+G22*G3+F22*F3+E22*E3+D22*D3+C22*C3+B22*B3 -> 0 | T22: =P22+Q22+R22+S22 -> 0 | U22: =N22 -> 0 | V22: =T22 -> 0 | W22: =U22-V22 -> 0
M23: =SUM(B23:L23) -> 0 | N23: =L23*L3+K23*K3+J23*J3+I23*I3+H23*H3+G23*G3+F23*F3+E23*E3+D23*D3+C23*C3+B23*B3 -> 0 | T23: =P23+Q23+R23+S23 -> 0 | U23: =N23 -> 0 | V23: =T23 -> 0 | W23: =U23-V23 -> 0
M24: =SUM(B24:L24) -> 0 | N24: =L24*L3+K24*K3+J24*J3+I24*I3+H24*H3+G24*G3+F24*F3+E24*E3+D24*D3+C24*C3+B24*B3 -> 0 | T24: =P24+Q24+R24+S24 -> 0 | U24: =N24 -> 0 | V24: =T24 -> 0 | W24: =U24-V24 -> 0
A25: G TOTAL | B25: =SUM(B5:B24) -> 40 | C25: =SUM(C5:C24) -> 0 | D25: =SUM(D5:D24) -> 0 | E25: =SUM(E5:E24) -> 0 | F25: =SUM(F5:F24) -> 0 | G25: =SUM(G5:G24) -> 0 | H25: =SUM(H5:H24) -> 0 | I25: =SUM(I5:I24) -> 0 | ... N25: =SUM(N5:N24) -> 16800 | P25: =SUM(P5:P24) -> 0 | Q25: =SUM(Q5:Q24) -> 0 | R25: =SUM(R5:R24) -> 0 | S25: =SUM(S5:S24) -> 0 | T25: =SUM(T5:T24) -> 0 | U25: =SUM(U5:U24) -> 16800 | V25: =SUM(V5:V24) -> 0 | W25: =SUM(W3:W24) -> 53760

Sheet HASSAN
A1: Month January
A2: DO NAME | B2: STOCK ISSUANCE | O2: PAYMENT RECEIVED | U2: ACCOUNT BALANCE
A3: Date | B3: 280 | C3: 350 | D3: 1000 | E3: 500 | F3: 5000 | G3: 7400 | H3: 5350 | I3: 2100 | J3: 7000 | K3: 280 | L3: 390 | M3: Total Qty | N3: Total Amount | O3: Date | P3: PAYMENT RECEIVED | T3: Total Received | U3: Carry Forward | W3: 21000
B4: RETAILER | C4: FRANCHISE | D4: LOAD SIM | E4: MBB SIM | F4: E SIM | G4: Shine Mobile | H4: MOBILE | I4: WINGLE | J4: DONGLE | K4: RETAIL IMZI | L4: CS IMZI | P4: SIM | Q4: IMZI | R4: DEVICES | S4: MOBILE | U4: Total Amount | V4: Payment | W4: Due Balance
M5: =SUM(B5:L5) -> 0 | N5: =L5*L3+K5*K3+J5*J3+I5*I3+H5*H3+G5*G3+F5*F3+E5*E3+D5*D3+C5*C3+B5*B3 -> 0 | T5: =P5+Q5+R5+S5 -> 0 | U5: =N5 -> 0 | V5: =T5 -> 0 | W5: =U5-V5 -> 0
M6: =SUM(B6:L6) -> 0 | N6: =L6*L3+K6*K3+J6*J3+I6*I3+H6*H3+G6*G3+F6*F3+E6*E3+D6*D3+C6*C3+B6*B3 -> 0 | T6: =P6+Q6+R6+S6 -> 0 | U6: =N6 -> 0 | V6: =T6 -> 0 | W6: =U6-V6 -> 0
M7: =SUM(B7:L7) -> 0 | N7: =L7*L3+K7*K3+J7*J3+I7*I3+H7*H3+G7*G3+F7*F3+E7*E3+D7*D3+C7*C3+B7*B3 -> 0 | T7: =P7+Q7+R7+S7 -> 0 | U7: =N7 -> 0 | V7: =T7 -> 0 | W7: =U7-V7 -> 0
M8: =SUM(B8:L8) -> 0 | N8: =L8*L3+K8*K3+J8*J3+I8*I3+H8*H3+G8*G3+F8*F3+E8*E3+D8*D3+C8*C3+B8*B3 -> 0 | T8: =P8+Q8+R8+S8 -> 0 | U8: =N8 -> 0 | V8: =T8 -> 0 | W8: =U8-V8 -> 0
M9: =SUM(B9:L9) -> 0 | N9: =L9*L3+K9*K3+J9*J3+I9*I3+H9*H3+G9*G3+F9*F3+E9*E3+D9*D3+C9*C3+B9*B3 -> 0 | T9: =P9+Q9+R9+S9 -> 0 | U9: =N9 -> 0 | V9: =T9 -> 0 | W9: =U9-V9 -> 0
M10: =SUM(B10:L10) -> 0 | N10: =L10*L3+K10*K3+J10*J3+I10*I3+H10*H3+G10*G3+F10*F3+E10*E3+D10*D3+C10*C3+B10*B3 -> 0 | T10: =P10+Q10+R10+S10 -> 0 | U10: =N10 -> 0 | V10: =T10 -> 0 | W10: =U10-V10 -> 0
M11: =SUM(B11:L11) -> 0 | N11: =L11*L3+K11*K3+J11*J3+I11*I3+H11*H3+G11*G3+F11*F3+E11*E3+D11*D3+C11*C3+B11*B3 -> 0 | T11: =P11+Q11+R11+S11 -> 0 | U11: =N11 -> 0 | V11: =T11 -> 0 | W11: =U11-V11 -> 0
M12: =SUM(B12:L12) -> 0 | N12: =L12*L3+K12*K3+J12*J3+I12*I3+H12*H3+G12*G3+F12*F3+E12*E3+D12*D3+C12*C3+B12*B3 -> 0 | T12: =P12+Q12+R12+S12 -> 0 | U12: =N12 -> 0 | V12: =T12 -> 0 | W12: =U12-V12 -> 0
M13: =SUM(B13:L13) -> 0 | N13: =L13*L3+K13*K3+J13*J3+I13*I3+H13*H3+G13*G3+F13*F3+E13*E3+D13*D3+C13*C3+B13*B3 -> 0 | T13: =P13+Q13+R13+S13 -> 0 | U13: =N13 -> 0 | V13: =T13 -> 0 | W13: =U13-V13 -> 0
M14: =SUM(B14:L14) -> 0 | N14: =L14*L3+K14*K3+J14*J3+I14*I3+H14*H3+G14*G3+F14*F3+E14*E3+D14*D3+C14*C3+B14*B3 -> 0 | T14: =P14+Q14+R14+S14 -> 0 | U14: =N14 -> 0 | V14: =T14 -> 0 | W14: =U14-V14 -> 0
M15: =SUM(B15:L15) -> 0 | N15: =L15*L3+K15*K3+J15*J3+I15*I3+H15*H3+G15*G3+F15*F3+E15*E3+D15*D3+C15*C3+B15*B3 -> 0 | T15: =P15+Q15+R15+S15 -> 0 | U15: =N15 -> 0 | V15: =T15 -> 0 | W15: =U15-V15 -> 0
M16: =SUM(B16:L16) -> 0 | N16: =L16*L3+K16*K3+J16*J3+I16*I3+H16*H3+G16*G3+F16*F3+E16*E3+D16*D3+C16*C3+B16*B3 -> 0 | T16: =P16+Q16+R16+S16 -> 0 | U16: =N16 -> 0 | V16: =T16 -> 0 | W16: =U16-V16 -> 0
M17: =SUM(B17:L17) -> 0 | N17: =L17*L3+K17*K3+J17*J3+I17*I3+H17*H3+G17*G3+F17*F3+E17*E3+D17*D3+C17*C3+B17*B3 -> 0 | T17: =P17+Q17+R17+S17 -> 0 | U17: =N17 -> 0 | V17: =T17 -> 0 | W17: =U17-V17 -> 0
M18: =SUM(B18:L18) -> 0 | N18: =L18*L3+K18*K3+J18*J3+I18*I3+H18*H3+G18*G3+F18*F3+E18*E3+D18*D3+C18*C3+B18*B3 -> 0 | T18: =P18+Q18+R18+S18 -> 0 | U18: =N18 -> 0 | V18: =T18 -> 0 | W18: =U18-V18 -> 0
M19: =SUM(B19:L19) -> 0 | N19: =L19*L3+K19*K3+J19*J3+I19*I3+H19*H3+G19*G3+F19*F3+E19*E3+D19*D3+C19*C3+B19*B3 -> 0 | T19: =P19+Q19+R19+S19 -> 0 | U19: =N19 -> 0 | V19: =T19 -> 0 | W19: =U19-V19 -> 0
M20: =SUM(B20:L20) -> 0 | N20: =L20*L3+K20*K3+J20*J3+I20*I3+H20*H3+G20*G3+F20*F3+E20*E3+D20*D3+C20*C3+B20*B3 -> 0 | T20: =P20+Q20+R20+S20 -> 0 | U20: =N20 -> 0 | V20: =T20 -> 0 | W20: =U20-V20 -> 0
M21: =SUM(B21:L21) -> 0 | N21: =L21*L3+K21*K3+J21*J3+I21*I3+H21*H3+G21*G3+F21*F3+E21*E3+D21*D3+C21*C3+B21*B3 -> 0 | T21: =P21+Q21+R21+S21 -> 0 | U21: =N21 -> 0 | V21: =T21 -> 0 | W21: =U21-V21 -> 0
M22: =SUM(B22:L22) -> 0 | N22: =L22*L3+K22*K3+J22*J3+I22*I3+H22*H3+G22*G3+F22*F3+E22*E3+D22*D3+C22*C3+B22*B3 -> 0 | T22: =P22+Q22+R22+S22 -> 0 | U22: =N22 -> 0 | V22: =T22 -> 0 | W22: =U22-V22 -> 0
M23: =SUM(B23:L23) -> 0 | N23: =L23*L3+K23*K3+J23*J3+I23*I3+H23*H3+G23*G3+F23*F3+E23*E3+D23*D3+C23*C3+B23*B3 -> 0 | T23: =P23+Q23+R23+S23 -> 0 | U23: =N23 -> 0 | V23: =T23 -> 0 | W23: =U23-V23 -> 0
M24: =SUM(B24:L24) -> 0 | N24: =L24*L3+K24*K3+J24*J3+I24*I3+H24*H3+G24*G3+F24*F3+E24*E3+D24*D3+C24*C3+B24*B3 -> 0 | T24: =P24+Q24+R24+S24 -> 0 | U24: =N24 -> 0 | V24: =T24 -> 0 | W24: =U24-V24 -> 0
A25: G TOTAL | B25: =SUM(B5:B24) -> 0 | C25: =SUM(C5:C24) -> 0 | D25: =SUM(D5:D24) -> 0 | E25: =SUM(E5:E24) -> 0 | F25: =SUM(F5:F24) -> 0 | G25: =SUM(G5:G24) -> 0 | H25: =SUM(H5:H24) -> 0 | I25: =SUM(I5:I24) -> 0 | ... N25: =SUM(N5:N24) -> 0 | P25: =SUM(P5:P24) -> 0 | Q25: =SUM(Q5:Q24) -> 0 | R25: =SUM(R5:R24) -> 0 | S25: =SUM(S5:S24) -> 0 | T25: =SUM(T5:T24) -> 0 | U25: =SUM(U5:U24) -> 0 | V25: =SUM(V5:V24) -> 0 | W25: =SUM(W3:W24) -> 21000

Sheet NAVEED
A1: Month January
A2: DO NAME | B2: STOCK ISSUANCE | O2: PAYMENT RECEIVED | U2: ACCOUNT BALANCE
A3: Date | B3: 280 | C3: 350 | D3: 1000 | E3: 500 | F3: 5000 | G3: 7400 | H3: 5350 | I3: 2100 | J3: 7000 | K3: 280 | L3: 390 | M3: Total Qty | N3: Total Amount | O3: Date | P3: PAYMENT RECEIVED | T3: Total Received | U3: Carry Forward | W3: 115670
B4: RETAILER | C4: FRANCHISE | D4: LOAD SIM | E4: MBB SIM | F4: E SIM | G4: Shine Mobile | H4: MOBILE | I4: WINGLE | J4: DONGLE | K4: RETAIL IMZI | L4: CS IMZI | P4: SIM | Q4: IMZI | R4: DEVICES | S4: MOBILE | U4: Total Amount | V4: Payment | W4: Due Balance
A5: 46266 | B5: 100 | K5: 100 | M5: =SUM(B5:L5) -> 200 | N5: =L5*L3+K5*K3+J5*J3+I5*I3+H5*H3+G5*G3+F5*F3+E5*E3+D5*D3+C5*C3+B5*B3 -> 56000 | T5: =P5+Q5+R5+S5 -> 0 | U5: =N5 -> 56000 | V5: =T5 -> 0 | W5: =U5-V5 -> 56000
M6: =SUM(B6:L6) -> 0 | N6: =L6*L3+K6*K3+J6*J3+I6*I3+H6*H3+G6*G3+F6*F3+E6*E3+D6*D3+C6*C3+B6*B3 -> 0 | T6: =P6+Q6+R6+S6 -> 0 | U6: =N6 -> 0 | V6: =T6 -> 0 | W6: =U6-V6 -> 0
M7: =SUM(B7:L7) -> 0 | N7: =L7*L3+K7*K3+J7*J3+I7*I3+H7*H3+G7*G3+F7*F3+E7*E3+D7*D3+C7*C3+B7*B3 -> 0 | T7: =P7+Q7+R7+S7 -> 0 | U7: =N7 -> 0 | V7: =T7 -> 0 | W7: =U7-V7 -> 0
M8: =SUM(B8:L8) -> 0 | N8: =L8*L3+K8*K3+J8*J3+I8*I3+H8*H3+G8*G3+F8*F3+E8*E3+D8*D3+C8*C3+B8*B3 -> 0 | T8: =P8+Q8+R8+S8 -> 0 | U8: =N8 -> 0 | V8: =T8 -> 0 | W8: =U8-V8 -> 0
M9: =SUM(B9:L9) -> 0 | N9: =L9*L3+K9*K3+J9*J3+I9*I3+H9*H3+G9*G3+F9*F3+E9*E3+D9*D3+C9*C3+B9*B3 -> 0 | T9: =P9+Q9+R9+S9 -> 0 | U9: =N9 -> 0 | V9: =T9 -> 0 | W9: =U9-V9 -> 0
M10: =SUM(B10:L10) -> 0 | N10: =L10*L3+K10*K3+J10*J3+I10*I3+H10*H3+G10*G3+F10*F3+E10*E3+D10*D3+C10*C3+B10*B3 -> 0 | T10: =P10+Q10+R10+S10 -> 0 | U10: =N10 -> 0 | V10: =T10 -> 0 | W10: =U10-V10 -> 0
M11: =SUM(B11:L11) -> 0 | N11: =L11*L3+K11*K3+J11*J3+I11*I3+H11*H3+G11*G3+F11*F3+E11*E3+D11*D3+C11*C3+B11*B3 -> 0 | T11: =P11+Q11+R11+S11 -> 0 | U11: =N11 -> 0 | V11: =T11 -> 0 | W11: =U11-V11 -> 0
M12: =SUM(B12:L12) -> 0 | N12: =L12*L3+K12*K3+J12*J3+I12*I3+H12*H3+G12*G3+F12*F3+E12*E3+D12*D3+C12*C3+B12*B3 -> 0 | T12: =P12+Q12+R12+S12 -> 0 | U12: =N12 -> 0 | V12: =T12 -> 0 | W12: =U12-V12 -> 0
M13: =SUM(B13:L13) -> 0 | N13: =L13*L3+K13*K3+J13*J3+I13*I3+H13*H3+G13*G3+F13*F3+E13*E3+D13*D3+C13*C3+B13*B3 -> 0 | T13: =P13+Q13+R13+S13 -> 0 | U13: =N13 -> 0 | V13: =T13 -> 0 | W13: =U13-V13 -> 0
M14: =SUM(B14:L14) -> 0 | N14: =L14*L3+K14*K3+J14*J3+I14*I3+H14*H3+G14*G3+F14*F3+E14*E3+D14*D3+C14*C3+B14*B3 -> 0 | T14: =P14+Q14+R14+S14 -> 0 | U14: =N14 -> 0 | V14: =T14 -> 0 | W14: =U14-V14 -> 0
M15: =SUM(B15:L15) -> 0 | N15: =L15*L3+K15*K3+J15*J3+I15*I3+H15*H3+G15*G3+F15*F3+E15*E3+D15*D3+C15*C3+B15*B3 -> 0 | T15: =P15+Q15+R15+S15 -> 0 | U15: =N15 -> 0 | V15: =T15 -> 0 | W15: =U15-V15 -> 0
M16: =SUM(B16:L16) -> 0 | N16: =L16*L3+K16*K3+J16*J3+I16*I3+H16*H3+G16*G3+F16*F3+E16*E3+D16*D3+C16*C3+B16*B3 -> 0 | T16: =P16+Q16+R16+S16 -> 0 | U16: =N16 -> 0 | V16: =T16 -> 0 | W16: =U16-V16 -> 0
M17: =SUM(B17:L17) -> 0 | N17: =L17*L3+K17*K3+J17*J3+I17*I3+H17*H3+G17*G3+F17*F3+E17*E3+D17*D3+C17*C3+B17*B3 -> 0 | T17: =P17+Q17+R17+S17 -> 0 | U17: =N17 -> 0 | V17: =T17 -> 0 | W17: =U17-V17 -> 0
M18: =SUM(B18:L18) -> 0 | N18: =L18*L3+K18*K3+J18*J3+I18*I3+H18*H3+G18*G3+F18*F3+E18*E3+D18*D3+C18*C3+B18*B3 -> 0 | T18: =P18+Q18+R18+S18 -> 0 | U18: =N18 -> 0 | V18: =T18 -> 0 | W18: =U18-V18 -> 0
M19: =SUM(B19:L19) -> 0 | N19: =L19*L3+K19*K3+J19*J3+I19*I3+H19*H3+G19*G3+F19*F3+E19*E3+D19*D3+C19*C3+B19*B3 -> 0 | T19: =P19+Q19+R19+S19 -> 0 | U19: =N19 -> 0 | V19: =T19 -> 0 | W19: =U19-V19 -> 0
M20: =SUM(B20:L20) -> 0 | N20: =L20*L3+K20*K3+J20*J3+I20*I3+H20*H3+G20*G3+F20*F3+E20*E3+D20*D3+C20*C3+B20*B3 -> 0 | T20: =P20+Q20+R20+S20 -> 0 | U20: =N20 -> 0 | V20: =T20 -> 0 | W20: =U20-V20 -> 0
M21: =SUM(B21:L21) -> 0 | N21: =L21*L3+K21*K3+J21*J3+I21*I3+H21*H3+G21*G3+F21*F3+E21*E3+D21*D3+C21*C3+B21*B3 -> 0 | T21: =P21+Q21+R21+S21 -> 0 | U21: =N21 -> 0 | V21: =T21 -> 0 | W21: =U21-V21 -> 0
M22: =SUM(B22:L22) -> 0 | N22: =L22*L3+K22*K3+J22*J3+I22*I3+H22*H3+G22*G3+F22*F3+E22*E3+D22*D3+C22*C3+B22*B3 -> 0 | T22: =P22+Q22+R22+S22 -> 0 | U22: =N22 -> 0 | V22: =T22 -> 0 | W22: =U22-V22 -> 0
M23: =SUM(B23:L23) -> 0 | N23: =L23*L3+K23*K3+J23*J3+I23*I3+H23*H3+G23*G3+F23*F3+E23*E3+D23*D3+C23*C3+B23*B3 -> 0 | T23: =P23+Q23+R23+S23 -> 0 | U23: =N23 -> 0 | V23: =T23 -> 0 | W23: =U23-V23 -> 0
M24: =SUM(B24:L24) -> 0 | N24: =L24*L3+K24*K3+J24*J3+I24*I3+H24*H3+G24*G3+F24*F3+E24*E3+D24*D3+C24*C3+B24*B3 -> 0 | T24: =P24+Q24+R24+S24 -> 0 | U24: =N24 -> 0 | V24: =T24 -> 0 | W24: =U24-V24 -> 0
A25: G TOTAL | B25: =SUM(B5:B24) -> 100 | C25: =SUM(C5:C24) -> 0 | D25: =SUM(D5:D24) -> 0 | E25: =SUM(E5:E24) -> 0 | F25: =SUM(F5:F24) -> 0 | G25: =SUM(G5:G24) -> 0 | H25: =SUM(H5:H24) -> 0 | I25: =SUM(I5:I24) -> 0 | ... N25: =SUM(N5:N24) -> 56000 | P25: =SUM(P5:P24) -> 0 | Q25: =SUM(Q5:Q24) -> 0 | R25: =SUM(R5:R24) -> 0 | S25: =SUM(S5:S24) -> 0 | T25: =SUM(T5:T24) -> 0 | U25: =SUM(U5:U24) -> 56000 | V25: =SUM(V5:V24) -> 0 | W25: =SUM(W3:W24) -> 171670

Sheet IRFAN
A1: Month January
A2: DO NAME | B2: STOCK ISSUANCE | O2: PAYMENT RECEIVED | U2: ACCOUNT BALANCE
A3: Date | B3: 280 | C3: 350 | D3: 1000 | E3: 500 | F3: 5000 | G3: 7400 | H3: 5350 | I3: 2100 | J3: 7000 | K3: 280 | L3: 390 | M3: Total Qty | N3: Total Amount | O3: Date | P3: PAYMENT RECEIVED | T3: Total Received | U3: Carry Forward | W3: 40560
B4: RETAILER | C4: FRANCHISE | D4: LOAD SIM | E4: MBB SIM | F4: E SIM | G4: Shine Mobile | H4: MOBILE | I4: WINGLE | J4: DONGLE | K4: RETAIL IMZI | L4: CS IMZI | P4: SIM | Q4: IMZI | R4: DEVICES | S4: MOBILE | U4: Total Amount | V4: Payment | W4: Due Balance
M5: =SUM(B5:L5) -> 0 | N5: =L5*L3+K5*K3+J5*J3+I5*I3+H5*H3+G5*G3+F5*F3+E5*E3+D5*D3+C5*C3+B5*B3 -> 0 | T5: =P5+Q5+R5+S5 -> 0 | U5: =N5 -> 0 | V5: =T5 -> 0 | W5: =U5-V5 -> 0
M6: =SUM(B6:L6) -> 0 | N6: =L6*L3+K6*K3+J6*J3+I6*I3+H6*H3+G6*G3+F6*F3+E6*E3+D6*D3+C6*C3+B6*B3 -> 0 | T6: =P6+Q6+R6+S6 -> 0 | U6: =N6 -> 0 | V6: =T6 -> 0 | W6: =U6-V6 -> 0
M7: =SUM(B7:L7) -> 0 | N7: =L7*L3+K7*K3+J7*J3+I7*I3+H7*H3+G7*G3+F7*F3+E7*E3+D7*D3+C7*C3+B7*B3 -> 0 | T7: =P7+Q7+R7+S7 -> 0 | U7: =N7 -> 0 | V7: =T7 -> 0 | W7: =U7-V7 -> 0
M8: =SUM(B8:L8) -> 0 | N8: =L8*L3+K8*K3+J8*J3+I8*I3+H8*H3+G8*G3+F8*F3+E8*E3+D8*D3+C8*C3+B8*B3 -> 0 | T8: =P8+Q8+R8+S8 -> 0 | U8: =N8 -> 0 | V8: =T8 -> 0 | W8: =U8-V8 -> 0
M9: =SUM(B9:L9) -> 0 | N9: =L9*L3+K9*K3+J9*J3+I9*I3+H9*H3+G9*G3+F9*F3+E9*E3+D9*D3+C9*C3+B9*B3 -> 0 | T9: =P9+Q9+R9+S9 -> 0 | U9: =N9 -> 0 | V9: =T9 -> 0 | W9: =U9-V9 -> 0
M10: =SUM(B10:L10) -> 0 | N10: =L10*L3+K10*K3+J10*J3+I10*I3+H10*H3+G10*G3+F10*F3+E10*E3+D10*D3+C10*C3+B10*B3 -> 0 | T10: =P10+Q10+R10+S10 -> 0 | U10: =N10 -> 0 | V10: =T10 -> 0 | W10: =U10-V10 -> 0
M11: =SUM(B11:L11) -> 0 | N11: =L11*L3+K11*K3+J11*J3+I11*I3+H11*H3+G11*G3+F11*F3+E11*E3+D11*D3+C11*C3+B11*B3 -> 0 | T11: =P11+Q11+R11+S11 -> 0 | U11: =N11 -> 0 | V11: =T11 -> 0 | W11: =U11-V11 -> 0
M12: =SUM(B12:L12) -> 0 | N12: =L12*L3+K12*K3+J12*J3+I12*I3+H12*H3+G12*G3+F12*F3+E12*E3+D12*D3+C12*C3+B12*B3 -> 0 | T12: =P12+Q12+R12+S12 -> 0 | U12: =N12 -> 0 | V12: =T12 -> 0 | W12: =U12-V12 -> 0
M13: =SUM(B13:L13) -> 0 | N13: =L13*L3+K13*K3+J13*J3+I13*I3+H13*H3+G13*G3+F13*F3+E13*E3+D13*D3+C13*C3+B13*B3 -> 0 | T13: =P13+Q13+R13+S13 -> 0 | U13: =N13 -> 0 | V13: =T13 -> 0 | W13: =U13-V13 -> 0
M14: =SUM(B14:L14) -> 0 | N14: =L14*L3+K14*K3+J14*J3+I14*I3+H14*H3+G14*G3+F14*F3+E14*E3+D14*D3+C14*C3+B14*B3 -> 0 | T14: =P14+Q14+R14+S14 -> 0 | U14: =N14 -> 0 | V14: =T14 -> 0 | W14: =U14-V14 -> 0
M15: =SUM(B15:L15) -> 0 | N15: =L15*L3+K15*K3+J15*J3+I15*I3+H15*H3+G15*G3+F15*F3+E15*E3+D15*D3+C15*C3+B15*B3 -> 0 | T15: =P15+Q15+R15+S15 -> 0 | U15: =N15 -> 0 | V15: =T15 -> 0 | W15: =U15-V15 -> 0
M16: =SUM(B16:L16) -> 0 | N16: =L16*L3+K16*K3+J16*J3+I16*I3+H16*H3+G16*G3+F16*F3+E16*E3+D16*D3+C16*C3+B16*B3 -> 0 | T16: =P16+Q16+R16+S16 -> 0 | U16: =N16 -> 0 | V16: =T16 -> 0 | W16: =U16-V16 -> 0
M17: =SUM(B17:L17) -> 0 | N17: =L17*L3+K17*K3+J17*J3+I17*I3+H17*H3+G17*G3+F17*F3+E17*E3+D17*D3+C17*C3+B17*B3 -> 0 | T17: =P17+Q17+R17+S17 -> 0 | U17: =N17 -> 0 | V17: =T17 -> 0 | W17: =U17-V17 -> 0
M18: =SUM(B18:L18) -> 0 | N18: =L18*L3+K18*K3+J18*J3+I18*I3+H18*H3+G18*G3+F18*F3+E18*E3+D18*D3+C18*C3+B18*B3 -> 0 | T18: =P18+Q18+R18+S18 -> 0 | U18: =N18 -> 0 | V18: =T18 -> 0 | W18: =U18-V18 -> 0
M19: =SUM(B19:L19) -> 0 | N19: =L19*L3+K19*K3+J19*J3+I19*I3+H19*H3+G19*G3+F19*F3+E19*E3+D19*D3+C19*C3+B19*B3 -> 0 | T19: =P19+Q19+R19+S19 -> 0 | U19: =N19 -> 0 | V19: =T19 -> 0 | W19: =U19-V19 -> 0
M20: =SUM(B20:L20) -> 0 | N20: =L20*L3+K20*K3+J20*J3+I20*I3+H20*H3+G20*G3+F20*F3+E20*E3+D20*D3+C20*C3+B20*B3 -> 0 | T20: =P20+Q20+R20+S20 -> 0 | U20: =N20 -> 0 | V20: =T20 -> 0 | W20: =U20-V20 -> 0
M21: =SUM(B21:L21) -> 0 | N21: =L21*L3+K21*K3+J21*J3+I21*I3+H21*H3+G21*G3+F21*F3+E21*E3+D21*D3+C21*C3+B21*B3 -> 0 | T21: =P21+Q21+R21+S21 -> 0 | U21: =N21 -> 0 | V21: =T21 -> 0 | W21: =U21-V21 -> 0
M22: =SUM(B22:L22) -> 0 | N22: =L22*L3+K22*K3+J22*J3+I22*I3+H22*H3+G22*G3+F22*F3+E22*E3+D22*D3+C22*C3+B22*B3 -> 0 | T22: =P22+Q22+R22+S22 -> 0 | U22: =N22 -> 0 | V22: =T22 -> 0 | W22: =U22-V22 -> 0
M23: =SUM(B23:L23) -> 0 | N23: =L23*L3+K23*K3+J23*J3+I23*I3+H23*H3+G23*G3+F23*F3+E23*E3+D23*D3+C23*C3+B23*B3 -> 0 | T23: =P23+Q23+R23+S23 -> 0 | U23: =N23 -> 0 | V23: =T23 -> 0 | W23: =U23-V23 -> 0
M24: =SUM(B24:L24) -> 0 | N24: =L24*L3+K24*K3+J24*J3+I24*I3+H24*H3+G24*G3+F24*F3+E24*E3+D24*D3+C24*C3+B24*B3 -> 0 | T24: =P24+Q24+R24+S24 -> 0 | U24: =N24 -> 0 | V24: =T24 -> 0 | W24: =U24-V24 -> 0
A25: G TOTAL | B25: =SUM(B5:B24) -> 0 | C25: =SUM(C5:C24) -> 0 | D25: =SUM(D5:D24) -> 0 | E25: =SUM(E5:E24) -> 0 | F25: =SUM(F5:F24) -> 0 | G25: =SUM(G5:G24) -> 0 | H25: =SUM(H5:H24) -> 0 | I25: =SUM(I5:I24) -> 0 | ... N25: =SUM(N5:N24) -> 0 | P25: =SUM(P5:P24) -> 0 | Q25: =SUM(Q5:Q24) -> 0 | R25: =SUM(R5:R24) -> 0 | S25: =SUM(S5:S24) -> 0 | T25: =SUM(T5:T24) -> 0 | U25: =SUM(U5:U24) -> 0 | V25: =SUM(V5:V24) -> 0 | W25: =SUM(W3:W24) -> 40560

Sheet DSO NADEEM 
A1: Month January
A2: DO NAME | B2: STOCK ISSUANCE | O2: PAYMENT RECEIVED | U2: ACCOUNT BALANCE
A3: Date | B3: 280 | C3: 350 | D3: 1000 | E3: 500 | F3: 5000 | G3: 7400 | H3: 5350 | I3: 2100 | J3: 7000 | K3: 280 | L3: 390 | M3: Total Qty | N3: Total Amount | O3: Date | P3: PAYMENT RECEIVED | T3: Total Received | U3: Carry Forward
B4: RETAILER | C4: FRANCHISE | D4: LOAD SIM | E4: MBB SIM | F4: E SIM | G4: Shine Mobile | H4: MOBILE | I4: WINGLE | J4: DONGLE | K4: RETAIL IMZI | L4: CS IMZI | P4: SIM | Q4: IMZI | R4: DEVICES | S4: MOBILE | U4: Total Amount | V4: Payment | W4: Due Balance
M5: =SUM(B5:L5) -> 0 | N5: =L5*L3+K5*K3+J5*J3+I5*I3+H5*H3+G5*G3+F5*F3+E5*E3+D5*D3+C5*C3+B5*B3 -> 0 | T5: =P5+Q5+R5+S5 -> 0 | U5: =N5 -> 0 | V5: =T5 -> 0 | W5: =U5-V5 -> 0
M6: =SUM(B6:L6) -> 0 | N6: =L6*L3+K6*K3+J6*J3+I6*I3+H6*H3+G6*G3+F6*F3+E6*E3+D6*D3+C6*C3+B6*B3 -> 0 | T6: =P6+Q6+R6+S6 -> 0 | U6: =N6 -> 0 | V6: =T6 -> 0 | W6: =U6-V6 -> 0
M7: =SUM(B7:L7) -> 0 | N7: =L7*L3+K7*K3+J7*J3+I7*I3+H7*H3+G7*G3+F7*F3+E7*E3+D7*D3+C7*C3+B7*B3 -> 0 | T7: =P7+Q7+R7+S7 -> 0 | U7: =N7 -> 0 | V7: =T7 -> 0 | W7: =U7-V7 -> 0
M8: =SUM(B8:L8) -> 0 | N8: =L8*L3+K8*K3+J8*J3+I8*I3+H8*H3+G8*G3+F8*F3+E8*E3+D8*D3+C8*C3+B8*B3 -> 0 | T8: =P8+Q8+R8+S8 -> 0 | U8: =N8 -> 0 | V8: =T8 -> 0 | W8: =U8-V8 -> 0
M9: =SUM(B9:L9) -> 0 | N9: =L9*L3+K9*K3+J9*J3+I9*I3+H9*H3+G9*G3+F9*F3+E9*E3+D9*D3+C9*C3+B9*B3 -> 0 | T9: =P9+Q9+R9+S9 -> 0 | U9: =N9 -> 0 | V9: =T9 -> 0 | W9: =U9-V9 -> 0
M10: =SUM(B10:L10) -> 0 | N10: =L10*L3+K10*K3+J10*J3+I10*I3+H10*H3+G10*G3+F10*F3+E10*E3+D10*D3+C10*C3+B10*B3 -> 0 | T10: =P10+Q10+R10+S10 -> 0 | U10: =N10 -> 0 | V10: =T10 -> 0 | W10: =U10-V10 -> 0
M11: =SUM(B11:L11) -> 0 | N11: =L11*L3+K11*K3+J11*J3+I11*I3+H11*H3+G11*G3+F11*F3+E11*E3+D11*D3+C11*C3+B11*B3 -> 0 | T11: =P11+Q11+R11+S11 -> 0 | U11: =N11 -> 0 | V11: =T11 -> 0 | W11: =U11-V11 -> 0
M12: =SUM(B12:L12) -> 0 | N12: =L12*L3+K12*K3+J12*J3+I12*I3+H12*H3+G12*G3+F12*F3+E12*E3+D12*D3+C12*C3+B12*B3 -> 0 | T12: =P12+Q12+R12+S12 -> 0 | U12: =N12 -> 0 | V12: =T12 -> 0 | W12: =U12-V12 -> 0
M13: =SUM(B13:L13) -> 0 | N13: =L13*L3+K13*K3+J13*J3+I13*I3+H13*H3+G13*G3+F13*F3+E13*E3+D13*D3+C13*C3+B13*B3 -> 0 | T13: =P13+Q13+R13+S13 -> 0 | U13: =N13 -> 0 | V13: =T13 -> 0 | W13: =U13-V13 -> 0
M14: =SUM(B14:L14) -> 0 | N14: =L14*L3+K14*K3+J14*J3+I14*I3+H14*H3+G14*G3+F14*F3+E14*E3+D14*D3+C14*C3+B14*B3 -> 0 | T14: =P14+Q14+R14+S14 -> 0 | U14: =N14 -> 0 | V14: =T14 -> 0 | W14: =U14-V14 -> 0
M15: =SUM(B15:L15) -> 0 | N15: =L15*L3+K15*K3+J15*J3+I15*I3+H15*H3+G15*G3+F15*F3+E15*E3+D15*D3+C15*C3+B15*B3 -> 0 | T15: =P15+Q15+R15+S15 -> 0 | U15: =N15 -> 0 | V15: =T15 -> 0 | W15: =U15-V15 -> 0
M16: =SUM(B16:L16) -> 0 | N16: =L16*L3+K16*K3+J16*J3+I16*I3+H16*H3+G16*G3+F16*F3+E16*E3+D16*D3+C16*C3+B16*B3 -> 0 | T16: =P16+Q16+R16+S16 -> 0 | U16: =N16 -> 0 | V16: =T16 -> 0 | W16: =U16-V16 -> 0
M17: =SUM(B17:L17) -> 0 | N17: =L17*L3+K17*K3+J17*J3+I17*I3+H17*H3+G17*G3+F17*F3+E17*E3+D17*D3+C17*C3+B17*B3 -> 0 | T17: =P17+Q17+R17+S17 -> 0 | U17: =N17 -> 0 | V17: =T17 -> 0 | W17: =U17-V17 -> 0
M18: =SUM(B18:L18) -> 0 | N18: =L18*L3+K18*K3+J18*J3+I18*I3+H18*H3+G18*G3+F18*F3+E18*E3+D18*D3+C18*C3+B18*B3 -> 0 | T18: =P18+Q18+R18+S18 -> 0 | U18: =N18 -> 0 | V18: =T18 -> 0 | W18: =U18-V18 -> 0
M19: =SUM(B19:L19) -> 0 | N19: =L19*L3+K19*K3+J19*J3+I19*I3+H19*H3+G19*G3+F19*F3+E19*E3+D19*D3+C19*C3+B19*B3 -> 0 | T19: =P19+Q19+R19+S19 -> 0 | U19: =N19 -> 0 | V19: =T19 -> 0 | W19: =U19-V19 -> 0 | AA19: 0
M20: =SUM(B20:L20) -> 0 | N20: =L20*L3+K20*K3+J20*J3+I20*I3+H20*H3+G20*G3+F20*F3+E20*E3+D20*D3+C20*C3+B20*B3 -> 0 | T20: =P20+Q20+R20+S20 -> 0 | U20: =N20 -> 0 | V20: =T20 -> 0 | W20: =U20-V20 -> 0
M21: =SUM(B21:L21) -> 0 | N21: =L21*L3+K21*K3+J21*J3+I21*I3+H21*H3+G21*G3+F21*F3+E21*E3+D21*D3+C21*C3+B21*B3 -> 0 | T21: =P21+Q21+R21+S21 -> 0 | U21: =N21 -> 0 | V21: =T21 -> 0 | W21: =U21-V21 -> 0
M22: =SUM(B22:L22) -> 0 | N22: =L22*L3+K22*K3+J22*J3+I22*I3+H22*H3+G22*G3+F22*F3+E22*E3+D22*D3+C22*C3+B22*B3 -> 0 | T22: =P22+Q22+R22+S22 -> 0 | U22: =N22 -> 0 | V22: =T22 -> 0 | W22: =U22-V22 -> 0
M23: =SUM(B23:L23) -> 0 | N23: =L23*L3+K23*K3+J23*J3+I23*I3+H23*H3+G23*G3+F23*F3+E23*E3+D23*D3+C23*C3+B23*B3 -> 0 | T23: =P23+Q23+R23+S23 -> 0 | U23: =N23 -> 0 | V23: =T23 -> 0 | W23: =U23-V23 -> 0
